Workbook

Sheet Recent state
A1: Date | B1: IC Number | C1: Channel | D1: Difference from theoretical potential measured at different resistances [%] | J1: Note
D2: 1 | E2: 1.5 | F2: 2 | G2: 3.3 | H2: 4 | I2: 5
A3: 46171 | B3: x | C3: 1-1 | D3: 0.15217391 | E3: -0.34057971 | F3: -0.88043478 | G3: -0.36890646 | H3: -0.75271739 | I3: -0.7 | J3: copper clips
A4: 46188 | B4: IC1827 | C4: 1-2 | D4: 0.17391304 | E4: -0.3115942 | F4: -0.89130435 | G4: -0.36561265 | H4: -0.73369565 | I4: -0.68043478
A5: 46164 | B5: x | C5: 1-3 | D5: 0.19565217 | E5: -0.32608696 | F5: -0.89130435 | G5: -0.3886693 | H5: -0.77717391 | I5: -0.70434783 | J5: copper clips
A6: 46171 | B6: x | C6: 1-5 | D6: 0.17391304 | E6: -0.51359954 | F6: -1.0633681 | G6: -0.52872475 | H6: -0.9250217 | I6: -0.87239583 | J6: out of order
A7: 46178 | B7: x | C7: 1-6 | D7: 0.18478261 | E7: -0.31884058 | F7: -0.89673913 | G7: -0.35902503 | H7: -0.72554348 | I7: -0.69347826 | J7: copper clips
A8: 46189 | B8: x | C8: 1-7 | D8: 0.17391304 | E8: -0.2826087 | F8: -0.85869565 | G8: -0.34255599 | H8: -0.67663043 | I8: -0.66521739
A9: 46178 | B9: x | C9: 1-8 | D9: 0.16304348 | E9: -0.34057971 | F9: -0.88586957 | G9: -0.36231884 | H9: -0.7201087 | I9: -0.67608696 | J9: copper clips
A10: 46045 | B10: x | C10: 2-1 | D10: 0.19565217 | E10: -0.28985507 | F10: -0.85326087 | G10: -0.3458498 | H10: -0.70652174 | I10: -0.66956522
A11: 46178 | B11: x | C11: 2-2 | D11: 0.17391304 | E11: -0.32608696 | F11: -0.88043478 | G11: -0.35902503 | H11: -0.73097826 | I11: -0.69565217
A12: 46171 | B12: x | C12: 2-3 | D12: 0.18478261 | E12: -0.27536232 | F12: -0.89673913 | G12: -0.37220026 | H12: -0.70108696 | I12: -0.68043478 | J12: copper clips
A13: 46045 | B13: IC0649 | C13: 2-4 | D13: 0.16304348 | E13: -0.30434783 | F13: -0.89130435 | G13: -0.35902503 | H13: -0.74456522 | I13: -0.69565217 | J13: copper clips
A14: 46185 | B14: IC0679 | C14: 2-5 | D14: 0.14130435 | E14: -0.31884058 | F14: -0.89673913 | G14: -0.35902503 | H14: -0.6875 | I14: -0.66956522 | J14: copper clips
A15: 46188 | B15: IC1829 | C15: 2-6 | D15: 0.16304348 | E15: -0.34057971 | F15: -0.91304348 | G15: -0.3886693 | H15: -0.76902174 | I15: -0.70434783 | J15: copper clips
A16: 46163 | B16: IC0787 | C16: 2-7 | D16: 0.054347826 | E16: -0.43478261 | F16: -1.0163043 | G16: -0.4743083 | H16: -0.80706522 | I16: -0.80217391 | J16: out of order
A17: 46168 | B17: IC1789 | C17: 2-8 | D17: 0.15217391 | E17: -0.34782609 | F17: -0.90217391 | G17: -0.37220026 | H17: -0.72282609 | I17: -0.69782609
A18: 46069 | B18: IC0621 | C18: 3-1 | D18: 0.31521739 | E18: -0.26811594 | F18: -0.88043478 | G18: -0.34255599 | H18: -0.68206522 | I18: -0.67391304
A19: 46078 | B19: x | C19: 3-2 | D19: 0.22826087 | E19: -0.26086957 | F19: -0.86413043 | G19: -0.34914361 | H19: -0.73369565 | I19: -0.70217391
A20: 46034 | B20: x | C20: 3-3 | D20: 0.15217391 | E20: -0.31884058 | F20: -0.91847826 | G20: -0.40513834 | H20: -0.73913043 | I20: -0.7326087
A21: 46069 | B21: x | C21: 3-4 | D21: 0.11956522 | E21: -0.32608696 | F21: -0.92391304 | G21: -0.39855072 | H21: -0.72554348 | I21: -0.72173913
A22: 46035 | B22: x | C22: 3-5 | D22: 0.11956522 | E22: -0.37681159 | F22: -0.9673913 | G22: -0.44466403 | H22: -0.79619565 | I22: -0.76956522 | J22: copper clips
A23: 46168 | B23: IC1767 | C23: 3-6 | D23: 0.11956522 | E23: -0.39855072 | F23: -0.95108696 | G23: -0.41831357 | H23: -0.76902174 | I23: -0.7673913
A24: 46185 | B24: IC0782 | C24: 3-7 | D24: 0.054347826 | E24: -0.41304348 | F24: -1.0054348 | G24: -0.47101449 | H24: -0.80163043 | I24: -0.7826087 | J24: out of order
A25: 46185 | B25: x | C25: 3-8 | D25: 0.010869565 | E25: -0.46376812 | F25: -1.048913 | G25: -0.50724638 | H25: -0.89402174 | I25: -0.83478261 | J25: out of order
A26: 46170 | C26: 4-1 | D26: 0.26086957 | E26: -0.29710145 | F26: -0.875 | G26: -0.35243742 | H26: -0.69836957 | I26: -0.6673913
A27: 46170 | C27: 4-2 | D27: 0.17391304 | E27: -0.3115942 | F27: -0.89673913 | G27: -0.36561265 | H27: -0.7201087 | I27: -0.68478261
A28: 46205 | C28: 4-3 | D28: 0.18478261 | E28: -0.30434783 | F28: -0.89673913 | G28: -0.36231884 | H28: -0.71195652 | I28: -0.68478261
A29: 46205 | C29: 4-4 | D29: 0.18478261 | E29: -0.33333333 | F29: -0.89130435 | G29: -0.37220026 | H29: -0.73097826 | I29: -0.72826087
A30: 46205 | B30: x | C30: 4-5 | D30: 0.17391304 | E30: -0.34782609 | F30: -0.88586957 | G30: -0.36561265 | H30: -0.72826087 | I30: -0.6826087
A31: 46205 | B31: x | C31: 4-6 | D31: 0.16304348 | E31: -0.34057971 | F31: -0.89673913 | G31: -0.35902503 | H31: -0.73369565 | I31: -0.68913043
A32: 46170 | B32: x | C32: 5-1 | D32: 0.19565217 | E32: -0.26811594 | F32: -0.88043478 | G32: -0.35573123 | H32: -0.69836957 | I32: -0.65
A33: 46170 | B33: x | C33: 5-3 | D33: -0.31521739 | E33: -0.3115942 | F33: -0.89130435 | G33: -0.35243742 | H33: -0.70108696 | I33: -0.6673913
A34: 46171 | B34: IC1008 | C34: 5-4 | D34: 0.25 | E34: -0.21014493 | F34: -0.81521739 | G34: -0.27997365 | H34: -0.66576087 | I34: -0.65
A35: 46042 | B35: x | C35: 5-5 | D35: 0.18478261 | E35: -0.29710145 | F35: -0.88586957 | G35: -0.3458498 | H35: -0.66576087 | I35: -0.65652174
A36: 46042 | B36: x | C36: 5-7 | D36: 0.18478261 | E36: -0.25362319 | F36: -0.86956522 | G36: -0.3458498 | H36: -0.71195652 | I36: -0.67391304
A37: 46042 | B37: x | C37: 5-8 | D37: 0.18478261 | E37: -0.31884058 | F37: -0.86956522 | G37: -0.3458498 | H37: -0.67934783 | I37: -0.69347826
A38: 46177 | B38: x | C38: 6-1 | D38: 0.20652174 | E38: -0.2826087 | F38: -0.86413043 | G38: -0.33596838 | H38: -0.6548913 | I38: -0.65
A39: 46177 | B39: x | C39: 6-2 | D39: 0.18478261 | E39: -0.25362319 | F39: -0.875 | G39: -0.35573123 | H39: -0.68206522 | I39: -0.65434783
A40: 46103 | B40: x | C40: 6-3 | D40: 0.2173913 | E40: -0.25362319 | F40: -0.8423913 | G40: -0.31949934 | H40: -0.66032609 | I40: -0.65217391
...

Sheet 1-1
A1: Date | B1: IC number | C1: Measured by | D1: Applied current [A] | E1: Measured potential by the nominal value of resistance [ohm] | K1: Difference from theoretical value [mV] | Q1: Approved? | R1: Note
E2: 1 | F2: 1.5 | G2: 2 | H2: 3.3 | I2: 4 | J2: 5 | K2: ΔV [%] 1.0 | L2: ΔV [%] 1.5 | M2: ΔV [%] 2.0 | N2: ΔV [%] 3.3 | O2: ΔV [%] 4.0 | P2: ΔV [%] 5.0
A3: 45800 | B3: old clips | C3: Aleksandra | D3: 0.92 | E3: 0.9278 | F3: 1.3823 | G3: 1.8313 | H3: 3.0315 | I3: 3.6666 | J3: 4.5746 | K3: =IF(D3=0, 0, 100*(E3 - D3*1)/(D3*1)) -> 0.84782609 | L3: =IF(D3=0, 0, 100*(F3 - D3*1.5)/(D3*1.5)) -> 0.16666667 | M3: =IF(D3=0, 0, 100*(G3 - D3*2)/(D3*2)) -> -0.47282609 | N3: =IF(D3=0, 0, 100*(H3 - D3*3.3)/(D3*3.3)) -> -0.14822134 | O3: =IF(D3=0, 0, 100*(I3 - D3*4)/(D3*4)) -> -0.36413043 | P3: =IF(D3=0, 0, 100*(J3 - D3*5)/(D3*5)) -> -0.55217391 | Q3: =IF(AND(K3>=0.11,K3<=0.27,L3>=-0.36,L3<=-0.22,M3>=-0.92,M3<=-0.82,N3>=-0.4,N3<=-0.3,O3>=-0.79,O3<=-0.64,P3>=-0.76,P3<=-0.61), "Yes", IF(AND(K3=0,L3=0,M3=0,N3=0,O3=0,P3=0), "Ready to test", "No")) -> No | R3: Old clips
A4: 45807 | B4: x | C4: Akos | D4: 0.92 | E4: 0.9217 | F4: 1.3757 | G4: 1.8239 | H4: 3.0248 | I4: 3.653 | J4: 4.5687 | K4: =IF(D4=0, 0, 100*(E4 - D4*1)/(D4*1)) -> 0.18478261 | L4: =IF(D4=0, 0, 100*(F4 - D4*1.5)/(D4*1.5)) -> -0.3115942 | M4: =IF(D4=0, 0, 100*(G4 - D4*2)/(D4*2)) -> -0.875 | N4: =IF(D4=0, 0, 100*(H4 - D4*3.3)/(D4*3.3)) -> -0.36890646 | O4: =IF(D4=0, 0, 100*(I4 - D4*4)/(D4*4)) -> -0.73369565 | P4: =IF(D4=0, 0, 100*(J4 - D4*5)/(D4*5)) -> -0.68043478 | Q4: =IF(AND(K4>=0.11,K4<=0.27,L4>=-0.36,L4<=-0.22,M4>=-0.92,M4<=-0.82,N4>=-0.4,N4<=-0.3,O4>=-0.79,O4<=-0.64,P4>=-0.76,P4<=-0.61), "Yes", IF(AND(K4=0,L4=0,M4=0,N4=0,O4=0,P4=0), "Ready to test", "No")) -> Yes | R4: copper clips
A5: 45888 | C5: Carmine/Daniel | D5: 0.92 | E5: 0.9214 | F5: 1.3753 | G5: 1.8229 | H5: 3.0241 | I5: 3.6526 | J5: 4.5676 | K5: =IF(D5=0, 0, 100*(E5 - D5*1)/(D5*1)) -> 0.15217391 | L5: =IF(D5=0, 0, 100*(F5 - D5*1.5)/(D5*1.5)) -> -0.34057971 | M5: =IF(D5=0, 0, 100*(G5 - D5*2)/(D5*2)) -> -0.92934783 | N5: =IF(D5=0, 0, 100*(H5 - D5*3.3)/(D5*3.3)) -> -0.39196311 | O5: =IF(D5=0, 0, 100*(I5 - D5*4)/(D5*4)) -> -0.74456522 | P5: =IF(D5=0, 0, 100*(J5 - D5*5)/(D5*5)) -> -0.70434783 | Q5: =IF(AND(K5>=0.11,K5<=0.27,L5>=-0.36,L5<=-0.22,M5>=-0.94,M5<=-0.82,N5>=-0.4,N5<=-0.3,O5>=-0.79,O5<=-0.64,P5>=-0.76,P5<=-0.61), "Yes", IF(AND(K5=0,L5=0,M5=0,N5=0,O5=0,P5=0), "Ready to test", "No")) -> Yes
A6: 45916 | B6: x | C6: Aleksandra/Carmine | D6: 0.92 | E6: 0.9217 | F6: 1.376 | G6: 1.8237 | H6: 3.0254 | I6: 3.6544 | J6: 4.5693 | K6: =IF(D6=0, 0, 100*(E6 - D6*1)/(D6*1)) -> 0.18478261 | L6: =IF(D6=0, 0, 100*(F6 - D6*1.5)/(D6*1.5)) -> -0.28985507 | M6: =IF(D6=0, 0, 100*(G6 - D6*2)/(D6*2)) -> -0.88586957 | N6: =IF(D6=0, 0, 100*(H6 - D6*3.3)/(D6*3.3)) -> -0.34914361 | O6: =IF(D6=0, 0, 100*(I6 - D6*4)/(D6*4)) -> -0.69565217 | P6: =IF(D6=0, 0, 100*(J6 - D6*5)/(D6*5)) -> -0.6673913 | Q6: =IF(AND(K6>=0.11,K6<=0.27,L6>=-0.36,L6<=-0.22,M6>=-0.92,M6<=-0.82,N6>=-0.4,N6<=-0.3,O6>=-0.79,O6<=-0.64,P6>=-0.76,P6<=-0.61), "Yes", IF(AND(K6=0,L6=0,M6=0,N6=0,O6=0,P6=0), "Ready to test", "No")) -> Yes
A7: 46041 | C7: Carmine | D7: 0.92 | E7: 0.9218 | F7: 1.3761 | G7: 1.8242 | H7: 3.0256 | I7: 3.6547 | J7: 4.5689 | K7: =IF(D7=0, 0, 100*(E7 - D7*1)/(D7*1)) -> 0.19565217 | L7: =IF(D7=0, 0, 100*(F7 - D7*1.5)/(D7*1.5)) -> -0.2826087 | M7: =IF(D7=0, 0, 100*(G7 - D7*2)/(D7*2)) -> -0.85869565 | N7: =IF(D7=0, 0, 100*(H7 - D7*3.3)/(D7*3.3)) -> -0.34255599 | O7: =IF(D7=0, 0, 100*(I7 - D7*4)/(D7*4)) -> -0.6875 | P7: =IF(D7=0, 0, 100*(J7 - D7*5)/(D7*5)) -> -0.67608696 | Q7: =IF(AND(K7>=0.11,K7<=0.27,L7>=-0.36,L7<=-0.22,M7>=-0.92,M7<=-0.82,N7>=-0.4,N7<=-0.3,O7>=-0.79,O7<=-0.64,P7>=-0.76,P7<=-0.61), "Yes", IF(AND(K7=0,L7=0,M7=0,N7=0,O7=0,P7=0), "Ready to test", "No")) -> Yes
A8: 46164 | C8: Marcus/Daniel | D8: 0.92 | E8: 0.9215 | F8: 1.3751 | G8: 1.8234 | H8: 3.0243 | I8: 3.6534 | J8: 4.5682 | K8: =IF(D8=0, 0, 100*(E8 - D8*1)/(D8*1)) -> 0.16304348 | L8: =IF(D8=0, 0, 100*(F8 - D8*1.5)/(D8*1.5)) -> -0.35507246 | M8: =IF(D8=0, 0, 100*(G8 - D8*2)/(D8*2)) -> -0.90217391 | N8: =IF(D8=0, 0, 100*(H8 - D8*3.3)/(D8*3.3)) -> -0.38537549 | O8: =IF(D8=0, 0, 100*(I8 - D8*4)/(D8*4)) -> -0.72282609 | P8: =IF(D8=0, 0, 100*(J8 - D8*5)/(D8*5)) -> -0.69130435 | Q8: =IF(AND(K8>=0.11,K8<=0.27,L8>=-0.36,L8<=-0.22,M8>=-0.92,M8<=-0.82,N8>=-0.4,N8<=-0.3,O8>=-0.79,O8<=-0.64,P8>=-0.76,P8<=-0.61), "Yes", IF(AND(K8=0,L8=0,M8=0,N8=0,O8=0,P8=0), "Ready to test", "No")) -> Yes
A9: 29/05/2026 | C9: Marcus/Tamas | D9: 0.92 | E9: 0.9214 | F9: 1.3753 | G9: 1.8238 | H9: 3.0248 | I9: 3.6523 | J9: 4.5678 | K9: =IF(D9=0, 0, 100*(E9 - D9*1)/(D9*1)) -> 0.15217391 | L9: =IF(D9=0, 0, 100*(F9 - D9*1.5)/(D9*1.5)) -> -0.34057971 | M9: =IF(D9=0, 0, 100*(G9 - D9*2)/(D9*2)) -> -0.88043478 | N9: =IF(D9=0, 0, 100*(H9 - D9*3.3)/(D9*3.3)) -> -0.36890646 | O9: =IF(D9=0, 0, 100*(I9 - D9*4)/(D9*4)) -> -0.75271739 | P9: =IF(D9=0, 0, 100*(J9 - D9*5)/(D9*5)) -> -0.7 | Q9: =IF(AND(K9>=0.11,K9<=0.27,L9>=-0.36,L9<=-0.22,M9>=-0.92,M9<=-0.82,N9>=-0.4,N9<=-0.3,O9>=-0.79,O9<=-0.64,P9>=-0.76,P9<=-0.61), "Yes", IF(AND(K9=0,L9=0,M9=0,N9=0,O9=0,P9=0), "Ready to test", "No")) -> Yes
K10: =IF(D10=0, 0, 100*(E10 - D10*1)/(D10*1)) -> 0 | L10: =IF(D10=0, 0, 100*(F10 - D10*1.5)/(D10*1.5)) -> 0 | M10: =IF(D10=0, 0, 100*(G10 - D10*2)/(D10*2)) -> 0 | N10: =IF(D10=0, 0, 100*(H10 - D10*3.3)/(D10*3.3)) -> 0 | O10: =IF(D10=0, 0, 100*(I10 - D10*4)/(D10*4)) -> 0 | P10: =IF(D10=0, 0, 100*(J10 - D10*5)/(D10*5)) -> 0 | Q10: =IF(AND(K10>=0.11,K10<=0.27,L10>=-0.36,L10<=-0.22,M10>=-0.92,M10<=-0.82,N10>=-0.4,N10<=-0.3,O10>=-0.79,O10<=-0.64,P10>=-0.76,P10<=-0.61), "Yes", IF(AND(K10=0,L10=0,M10=0,N10=0,O10=0,P10=0), "Ready to test", "No")) -> Ready to test
K11: =IF(D11=0, 0, 100*(E11 - D11*1)/(D11*1)) -> 0 | L11: =IF(D11=0, 0, 100*(F11 - D11*1.5)/(D11*1.5)) -> 0 | M11: =IF(D11=0, 0, 100*(G11 - D11*2)/(D11*2)) -> 0 | N11: =IF(D11=0, 0, 100*(H11 - D11*3.3)/(D11*3.3)) -> 0 | O11: =IF(D11=0, 0, 100*(I11 - D11*4)/(D11*4)) -> 0 | P11: =IF(D11=0, 0, 100*(J11 - D11*5)/(D11*5)) -> 0 | Q11: =IF(AND(K11>=0.11,K11<=0.27,L11>=-0.36,L11<=-0.22,M11>=-0.92,M11<=-0.82,N11>=-0.4,N11<=-0.3,O11>=-0.79,O11<=-0.64,P11>=-0.76,P11<=-0.61), "Yes", IF(AND(K11=0,L11=0,M11=0,N11=0,O11=0,P11=0), "Ready to test", "No")) -> Ready to test
K12: =IF(D12=0, 0, 100*(E12 - D12*1)/(D12*1)) -> 0 | L12: =IF(D12=0, 0, 100*(F12 - D12*1.5)/(D12*1.5)) -> 0 | M12: =IF(D12=0, 0, 100*(G12 - D12*2)/(D12*2)) -> 0 | N12: =IF(D12=0, 0, 100*(H12 - D12*3.3)/(D12*3.3)) -> 0 | O12: =IF(D12=0, 0, 100*(I12 - D12*4)/(D12*4)) -> 0 | P12: =IF(D12=0, 0, 100*(J12 - D12*5)/(D12*5)) -> 0 | Q12: =IF(AND(K12>=0.11,K12<=0.27,L12>=-0.36,L12<=-0.22,M12>=-0.92,M12<=-0.82,N12>=-0.4,N12<=-0.3,O12>=-0.79,O12<=-0.64,P12>=-0.76,P12<=-0.61), "Yes", IF(AND(K12=0,L12=0,M12=0,N12=0,O12=0,P12=0), "Ready to test", "No")) -> Ready to test
K13: =IF(D13=0, 0, 100*(E13 - D13*1)/(D13*1)) -> 0 | L13: =IF(D13=0, 0, 100*(F13 - D13*1.5)/(D13*1.5)) -> 0 | M13: =IF(D13=0, 0, 100*(G13 - D13*2)/(D13*2)) -> 0 | N13: =IF(D13=0, 0, 100*(H13 - D13*3.3)/(D13*3.3)) -> 0 | O13: =IF(D13=0, 0, 100*(I13 - D13*4)/(D13*4)) -> 0 | P13: =IF(D13=0, 0, 100*(J13 - D13*5)/(D13*5)) -> 0 | Q13: =IF(AND(K13>=0.11,K13<=0.27,L13>=-0.36,L13<=-0.22,M13>=-0.92,M13<=-0.82,N13>=-0.4,N13<=-0.3,O13>=-0.79,O13<=-0.64,P13>=-0.76,P13<=-0.61), "Yes", IF(AND(K13=0,L13=0,M13=0,N13=0,O13=0,P13=0), "Ready to test", "No")) -> Ready to test
K14: =IF(D14=0, 0, 100*(E14 - D14*1)/(D14*1)) -> 0 | L14: =IF(D14=0, 0, 100*(F14 - D14*1.5)/(D14*1.5)) -> 0 | M14: =IF(D14=0, 0, 100*(G14 - D14*2)/(D14*2)) -> 0 | N14: =IF(D14=0, 0, 100*(H14 - D14*3.3)/(D14*3.3)) -> 0 | O14: =IF(D14=0, 0, 100*(I14 - D14*4)/(D14*4)) -> 0 | P14: =IF(D14=0, 0, 100*(J14 - D14*5)/(D14*5)) -> 0 | Q14: =IF(AND(K14>=0.11,K14<=0.27,L14>=-0.36,L14<=-0.22,M14>=-0.92,M14<=-0.82,N14>=-0.4,N14<=-0.3,O14>=-0.79,O14<=-0.64,P14>=-0.76,P14<=-0.61), "Yes", IF(AND(K14=0,L14=0,M14=0,N14=0,O14=0,P14=0), "Ready to test", "No")) -> Ready to test
K15: =IF(D15=0, 0, 100*(E15 - D15*1)/(D15*1)) -> 0 | L15: =IF(D15=0, 0, 100*(F15 - D15*1.5)/(D15*1.5)) -> 0 | M15: =IF(D15=0, 0, 100*(G15 - D15*2)/(D15*2)) -> 0 | N15: =IF(D15=0, 0, 100*(H15 - D15*3.3)/(D15*3.3)) -> 0 | O15: =IF(D15=0, 0, 100*(I15 - D15*4)/(D15*4)) -> 0 | P15: =IF(D15=0, 0, 100*(J15 - D15*5)/(D15*5)) -> 0 | Q15: =IF(AND(K15>=0.11,K15<=0.27,L15>=-0.36,L15<=-0.22,M15>=-0.92,M15<=-0.82,N15>=-0.4,N15<=-0.3,O15>=-0.79,O15<=-0.64,P15>=-0.76,P15<=-0.61), "Yes", IF(AND(K15=0,L15=0,M15=0,N15=0,O15=0,P15=0), "Ready to test", "No")) -> Ready to test
K16: =IF(D16=0, 0, 100*(E16 - D16*1)/(D16*1)) -> 0 | L16: =IF(D16=0, 0, 100*(F16 - D16*1.5)/(D16*1.5)) -> 0 | M16: =IF(D16=0, 0, 100*(G16 - D16*2)/(D16*2)) -> 0 | N16: =IF(D16=0, 0, 100*(H16 - D16*3.3)/(D16*3.3)) -> 0 | O16: =IF(D16=0, 0, 100*(I16 - D16*4)/(D16*4)) -> 0 | P16: =IF(D16=0, 0, 100*(J16 - D16*5)/(D16*5)) -> 0 | Q16: =IF(AND(K16>=0.11,K16<=0.27,L16>=-0.36,L16<=-0.22,M16>=-0.92,M16<=-0.82,N16>=-0.4,N16<=-0.3,O16>=-0.79,O16<=-0.64,P16>=-0.76,P16<=-0.61), "Yes", IF(AND(K16=0,L16=0,M16=0,N16=0,O16=0,P16=0), "Ready to test", "No")) -> Ready to test

Sheet 1-2
A1: Date | B1: IC number | C1: Measured by | D1: Applied current [A] | E1: Measured potential by the nominal value of resistance [ohm] | K1: Difference from theoretical value [mV] | Q1: Approved? | R1: Note
E2: 1 | F2: 1.5 | G2: 2 | H2: 3.3 | I2: 4 | J2: 5 | K2: ΔV [%] 1.0 | L2: ΔV [%] 1.5 | M2: ΔV [%] 2.0 | N2: ΔV [%] 3.3 | O2: ΔV [%] 4.0 | P2: ΔV [%] 5.0
A3: 45797 | B3: Old clips | C3: Balázs | D3: 0.92 | E3: 0.9366 | F3: 1.394 | G3: 1.839 | H3: 3.0401 | I3: 3.672 | J3: 4.5816 | K3: =IF(D3=0, 0, 100*(E3 - D3*1)/(D3*1)) -> 1.8043478 | L3: =IF(D3=0, 0, 100*(F3 - D3*1.5)/(D3*1.5)) -> 1.0144928 | M3: =IF(D3=0, 0, 100*(G3 - D3*2)/(D3*2)) -> -0.054347826 | N3: =IF(D3=0, 0, 100*(H3 - D3*3.3)/(D3*3.3)) -> 0.13504611 | O3: =IF(D3=0, 0, 100*(I3 - D3*4)/(D3*4)) -> -0.2173913 | P3: =IF(D3=0, 0, 100*(J3 - D3*5)/(D3*5)) -> -0.4 | Q3: =IF(AND(K3>=0.11,K3<=0.27,L3>=-0.36,L3<=-0.22,M3>=-0.92,M3<=-0.82,N3>=-0.4,N3<=-0.3,O3>=-0.79,O3<=-0.64,P3>=-0.76,P3<=-0.61), "Yes", IF(AND(K3=0,L3=0,M3=0,N3=0,O3=0,P3=0), "Ready to test", "No")) -> No | R3: Old clips
A4: 45800 | B4: old clips | C4: Aleksandra | D4: 0.92 | E4: 0.93 | F4: 1.38 | G4: 1.8325 | H4: 3.0287 | I4: 3.6626 | J4: 4.5778 | K4: =IF(D4=0, 0, 100*(E4 - D4*1)/(D4*1)) -> 1.0869565 | L4: =IF(D4=0, 0, 100*(F4 - D4*1.5)/(D4*1.5)) -> -1.6090189e-14 | M4: =IF(D4=0, 0, 100*(G4 - D4*2)/(D4*2)) -> -0.4076087 | N4: =IF(D4=0, 0, 100*(H4 - D4*3.3)/(D4*3.3)) -> -0.24044796 | O4: =IF(D4=0, 0, 100*(I4 - D4*4)/(D4*4)) -> -0.47282609 | P4: =IF(D4=0, 0, 100*(J4 - D4*5)/(D4*5)) -> -0.4826087 | Q4: =IF(AND(K4>=0.11,K4<=0.27,L4>=-0.36,L4<=-0.22,M4>=-0.92,M4<=-0.82,N4>=-0.4,N4<=-0.3,O4>=-0.79,O4<=-0.64,P4>=-0.76,P4<=-0.61), "Yes", IF(AND(K4=0,L4=0,M4=0,N4=0,O4=0,P4=0), "Ready to test", "No")) -> No | R4: Old clips
A5: 45803 | B5: new clips copper | C5: carmine | D5: 0.92 | E5: 0.9218 | F5: 1.3763 | G5: 1.824 | H5: 3.0256 | I5: 3.6545 | J5: 4.5694 | K5: =IF(D5=0, 0, 100*(E5 - D5*1)/(D5*1)) -> 0.19565217 | L5: =IF(D5=0, 0, 100*(F5 - D5*1.5)/(D5*1.5)) -> -0.26811594 | M5: =IF(D5=0, 0, 100*(G5 - D5*2)/(D5*2)) -> -0.86956522 | N5: =IF(D5=0, 0, 100*(H5 - D5*3.3)/(D5*3.3)) -> -0.34255599 | O5: =IF(D5=0, 0, 100*(I5 - D5*4)/(D5*4)) -> -0.69293478 | P5: =IF(D5=0, 0, 100*(J5 - D5*5)/(D5*5)) -> -0.66521739 | Q5: =IF(AND(K5>=0.11,K5<=0.27,L5>=-0.36,L5<=-0.22,M5>=-0.92,M5<=-0.82,N5>=-0.4,N5<=-0.3,O5>=-0.79,O5<=-0.64,P5>=-0.76,P5<=-0.61), "Yes", IF(AND(K5=0,L5=0,M5=0,N5=0,O5=0,P5=0), "Ready to test", "No")) -> Yes | R5: New 4 wire clips
A6: 45888 | C6: Carmine/Daniel | D6: 0.92 | E6: 0.9218 | F6: 1.3757 | G6: 1.8235 | H6: 3.0246 | I6: 3.6516 | J6: 4.5682 | K6: =IF(D6=0, 0, 100*(E6 - D6*1)/(D6*1)) -> 0.19565217 | L6: =IF(D6=0, 0, 100*(F6 - D6*1.5)/(D6*1.5)) -> -0.3115942 | M6: =IF(D6=0, 0, 100*(G6 - D6*2)/(D6*2)) -> -0.89673913 | N6: =IF(D6=0, 0, 100*(H6 - D6*3.3)/(D6*3.3)) -> -0.37549407 | O6: =IF(D6=0, 0, 100*(I6 - D6*4)/(D6*4)) -> -0.77173913 | P6: =IF(D6=0, 0, 100*(J6 - D6*5)/(D6*5)) -> -0.69130435 | Q6: =IF(AND(K6>=0.11,K6<=0.27,L6>=-0.36,L6<=-0.22,M6>=-0.92,M6<=-0.82,N6>=-0.4,N6<=-0.3,O6>=-0.79,O6<=-0.64,P6>=-0.76,P6<=-0.61), "Yes", IF(AND(K6=0,L6=0,M6=0,N6=0,O6=0,P6=0), "Ready to test", "No")) -> Yes
A7: 45916 | B7: x | C7: Aleksandra/Carmine | D7: 0.92 | E7: 0.9219 | F7: 1.3762 | G7: 1.8237 | H7: 3.0248 | I7: 3.6536 | J7: 4.5684 | K7: =IF(D7=0, 0, 100*(E7 - D7*1)/(D7*1)) -> 0.20652174 | L7: =IF(D7=0, 0, 100*(F7 - D7*1.5)/(D7*1.5)) -> -0.27536232 | M7: =IF(D7=0, 0, 100*(G7 - D7*2)/(D7*2)) -> -0.88586957 | N7: =IF(D7=0, 0, 100*(H7 - D7*3.3)/(D7*3.3)) -> -0.36890646 | O7: =IF(D7=0, 0, 100*(I7 - D7*4)/(D7*4)) -> -0.7173913 | P7: =IF(D7=0, 0, 100*(J7 - D7*5)/(D7*5)) -> -0.68695652 | Q7: =IF(AND(K7>=0.11,K7<=0.27,L7>=-0.36,L7<=-0.22,M7>=-0.92,M7<=-0.82,N7>=-0.4,N7<=-0.3,O7>=-0.79,O7<=-0.64,P7>=-0.76,P7<=-0.61), "Yes", IF(AND(K7=0,L7=0,M7=0,N7=0,O7=0,P7=0), "Ready to test", "No")) -> Yes
A8: 46041 | C8: Carmine | D8: 0.92 | E8: 0.9218 | F8: 1.3759 | G8: 1.8239 | H8: 3.0257 | I8: 3.6537 | J8: 4.5696 | K8: =IF(D8=0, 0, 100*(E8 - D8*1)/(D8*1)) -> 0.19565217 | L8: =IF(D8=0, 0, 100*(F8 - D8*1.5)/(D8*1.5)) -> -0.29710145 | M8: =IF(D8=0, 0, 100*(G8 - D8*2)/(D8*2)) -> -0.875 | N8: =IF(D8=0, 0, 100*(H8 - D8*3.3)/(D8*3.3)) -> -0.33926219 | O8: =IF(D8=0, 0, 100*(I8 - D8*4)/(D8*4)) -> -0.71467391 | P8: =IF(D8=0, 0, 100*(J8 - D8*5)/(D8*5)) -> -0.66086957 | Q8: =IF(AND(K8>=0.11,K8<=0.27,L8>=-0.36,L8<=-0.22,M8>=-0.92,M8<=-0.82,N8>=-0.4,N8<=-0.3,O8>=-0.79,O8<=-0.64,P8>=-0.76,P8<=-0.61), "Yes", IF(AND(K8=0,L8=0,M8=0,N8=0,O8=0,P8=0), "Ready to test", "No")) -> Yes
A9: 46164 | C9: Marcus/Daniel | D9: 0.92 | E9: 0.9218 | F9: 1.3759 | G9: 1.8237 | H9: 3.0247 | I9: 3.6526 | J9: 4.5676 | K9: =IF(D9=0, 0, 100*(E9 - D9*1)/(D9*1)) -> 0.19565217 | L9: =IF(D9=0, 0, 100*(F9 - D9*1.5)/(D9*1.5)) -> -0.29710145 | M9: =IF(D9=0, 0, 100*(G9 - D9*2)/(D9*2)) -> -0.88586957 | N9: =IF(D9=0, 0, 100*(H9 - D9*3.3)/(D9*3.3)) -> -0.37220026 | O9: =IF(D9=0, 0, 100*(I9 - D9*4)/(D9*4)) -> -0.74456522 | P9: =IF(D9=0, 0, 100*(J9 - D9*5)/(D9*5)) -> -0.70434783 | Q9: =IF(AND(K9>=0.11,K9<=0.27,L9>=-0.36,L9<=-0.22,M9>=-0.92,M9<=-0.82,N9>=-0.4,N9<=-0.3,O9>=-0.79,O9<=-0.64,P9>=-0.76,P9<=-0.61), "Yes", IF(AND(K9=0,L9=0,M9=0,N9=0,O9=0,P9=0), "Ready to test", "No")) -> Yes
A10: 46188 | B10: IC1823 | C10: Ola/Frederik | D10: 0.92 | E10: 0.9216 | F10: 1.3757 | G10: 1.8236 | H10: 3.0249 | I10: 3.653 | J10: 4.5687 | K10: =IF(D10=0, 0, 100*(E10 - D10*1)/(D10*1)) -> 0.17391304 | L10: =IF(D10=0, 0, 100*(F10 - D10*1.5)/(D10*1.5)) -> -0.3115942 | M10: =IF(D10=0, 0, 100*(G10 - D10*2)/(D10*2)) -> -0.89130435 | N10: =IF(D10=0, 0, 100*(H10 - D10*3.3)/(D10*3.3)) -> -0.36561265 | O10: =IF(D10=0, 0, 100*(I10 - D10*4)/(D10*4)) -> -0.73369565 | P10: =IF(D10=0, 0, 100*(J10 - D10*5)/(D10*5)) -> -0.68043478 | Q10: =IF(AND(K10>=0.11,K10<=0.27,L10>=-0.36,L10<=-0.22,M10>=-0.92,M10<=-0.82,N10>=-0.4,N10<=-0.3,O10>=-0.79,O10<=-0.64,P10>=-0.76,P10<=-0.61), "Yes", IF(AND(K10=0,L10=0,M10=0,N10=0,O10=0,P10=0), "Ready to test", "No")) -> Yes
K11: =IF(D11=0, 0, 100*(E11 - D11*1)/(D11*1)) -> 0 | L11: =IF(D11=0, 0, 100*(F11 - D11*1.5)/(D11*1.5)) -> 0 | M11: =IF(D11=0, 0, 100*(G11 - D11*2)/(D11*2)) -> 0 | N11: =IF(D11=0, 0, 100*(H11 - D11*3.3)/(D11*3.3)) -> 0 | O11: =IF(D11=0, 0, 100*(I11 - D11*4)/(D11*4)) -> 0 | P11: =IF(D11=0, 0, 100*(J11 - D11*5)/(D11*5)) -> 0 | Q11: =IF(AND(K11>=0.11,K11<=0.27,L11>=-0.36,L11<=-0.22,M11>=-0.92,M11<=-0.82,N11>=-0.4,N11<=-0.3,O11>=-0.79,O11<=-0.64,P11>=-0.76,P11<=-0.61), "Yes", IF(AND(K11=0,L11=0,M11=0,N11=0,O11=0,P11=0), "Ready to test", "No")) -> Ready to test
K12: =IF(D12=0, 0, 100*(E12 - D12*1)/(D12*1)) -> 0 | L12: =IF(D12=0, 0, 100*(F12 - D12*1.5)/(D12*1.5)) -> 0 | M12: =IF(D12=0, 0, 100*(G12 - D12*2)/(D12*2)) -> 0 | N12: =IF(D12=0, 0, 100*(H12 - D12*3.3)/(D12*3.3)) -> 0 | O12: =IF(D12=0, 0, 100*(I12 - D12*4)/(D12*4)) -> 0 | P12: =IF(D12=0, 0, 100*(J12 - D12*5)/(D12*5)) -> 0 | Q12: =IF(AND(K12>=0.11,K12<=0.27,L12>=-0.36,L12<=-0.22,M12>=-0.92,M12<=-0.82,N12>=-0.4,N12<=-0.3,O12>=-0.79,O12<=-0.64,P12>=-0.76,P12<=-0.61), "Yes", IF(AND(K12=0,L12=0,M12=0,N12=0,O12=0,P12=0), "Ready to test", "No")) -> Ready to test
K13: =IF(D13=0, 0, 100*(E13 - D13*1)/(D13*1)) -> 0 | L13: =IF(D13=0, 0, 100*(F13 - D13*1.5)/(D13*1.5)) -> 0 | M13: =IF(D13=0, 0, 100*(G13 - D13*2)/(D13*2)) -> 0 | N13: =IF(D13=0, 0, 100*(H13 - D13*3.3)/(D13*3.3)) -> 0 | O13: =IF(D13=0, 0, 100*(I13 - D13*4)/(D13*4)) -> 0 | P13: =IF(D13=0, 0, 100*(J13 - D13*5)/(D13*5)) -> 0 | Q13: =IF(AND(K13>=0.11,K13<=0.27,L13>=-0.36,L13<=-0.22,M13>=-0.92,M13<=-0.82,N13>=-0.4,N13<=-0.3,O13>=-0.79,O13<=-0.64,P13>=-0.76,P13<=-0.61), "Yes", IF(AND(K13=0,L13=0,M13=0,N13=0,O13=0,P13=0), "Ready to test", "No")) -> Ready to test
K14: =IF(D14=0, 0, 100*(E14 - D14*1)/(D14*1)) -> 0 | L14: =IF(D14=0, 0, 100*(F14 - D14*1.5)/(D14*1.5)) -> 0 | M14: =IF(D14=0, 0, 100*(G14 - D14*2)/(D14*2)) -> 0 | N14: =IF(D14=0, 0, 100*(H14 - D14*3.3)/(D14*3.3)) -> 0 | O14: =IF(D14=0, 0, 100*(I14 - D14*4)/(D14*4)) -> 0 | P14: =IF(D14=0, 0, 100*(J14 - D14*5)/(D14*5)) -> 0 | Q14: =IF(AND(K14>=0.11,K14<=0.27,L14>=-0.36,L14<=-0.22,M14>=-0.92,M14<=-0.82,N14>=-0.4,N14<=-0.3,O14>=-0.79,O14<=-0.64,P14>=-0.76,P14<=-0.61), "Yes", IF(AND(K14=0,L14=0,M14=0,N14=0,O14=0,P14=0), "Ready to test", "No")) -> Ready to test
K15: =IF(D15=0, 0, 100*(E15 - D15*1)/(D15*1)) -> 0 | L15: =IF(D15=0, 0, 100*(F15 - D15*1.5)/(D15*1.5)) -> 0 | M15: =IF(D15=0, 0, 100*(G15 - D15*2)/(D15*2)) -> 0 | N15: =IF(D15=0, 0, 100*(H15 - D15*3.3)/(D15*3.3)) -> 0 | O15: =IF(D15=0, 0, 100*(I15 - D15*4)/(D15*4)) -> 0 | P15: =IF(D15=0, 0, 100*(J15 - D15*5)/(D15*5)) -> 0 | Q15: =IF(AND(K15>=0.11,K15<=0.27,L15>=-0.36,L15<=-0.22,M15>=-0.92,M15<=-0.82,N15>=-0.4,N15<=-0.3,O15>=-0.79,O15<=-0.64,P15>=-0.76,P15<=-0.61), "Yes", IF(AND(K15=0,L15=0,M15=0,N15=0,O15=0,P15=0), "Ready to test", "No")) -> Ready to test
K16: =IF(D16=0, 0, 100*(E16 - D16*1)/(D16*1)) -> 0 | L16: =IF(D16=0, 0, 100*(F16 - D16*1.5)/(D16*1.5)) -> 0 | M16: =IF(D16=0, 0, 100*(G16 - D16*2)/(D16*2)) -> 0 | N16: =IF(D16=0, 0, 100*(H16 - D16*3.3)/(D16*3.3)) -> 0 | O16: =IF(D16=0, 0, 100*(I16 - D16*4)/(D16*4)) -> 0 | P16: =IF(D16=0, 0, 100*(J16 - D16*5)/(D16*5)) -> 0 | Q16: =IF(AND(K16>=0.11,K16<=0.27,L16>=-0.36,L16<=-0.22,M16>=-0.92,M16<=-0.82,N16>=-0.4,N16<=-0.3,O16>=-0.79,O16<=-0.64,P16>=-0.76,P16<=-0.61), "Yes", IF(AND(K16=0,L16=0,M16=0,N16=0,O16=0,P16=0), "Ready to test", "No")) -> Ready to test

Sheet 1-3
A1: Date | B1: IC number | C1: Measured by | D1: Applied current [A] | E1: Measured potential by the nominal value of resistance [ohm] | K1: Difference from theoretical value [mV] | Q1: Approved? | R1: Note
E2: 1 | F2: 1.5 | G2: 2 | H2: 3.3 | I2: 4 | J2: 5 | K2: ΔV [%] 1.0 | L2: ΔV [%] 1.5 | M2: ΔV [%] 2.0 | N2: ΔV [%] 3.3 | O2: ΔV [%] 4.0 | P2: ΔV [%] 5.0
A3: 45803 | B3: x | C3: Balázs | D3: 0.92 | E3: 0.9219 | F3: 1.3769 | G3: 1.8244 | H3: 3.026 | I3: 3.6516 | J3: 4.5703 | K3: =IF(D3=0, 0, 100*(E3 - D3*1)/(D3*1)) -> 0.20652174 | L3: =IF(D3=0, 0, 100*(F3 - D3*1.5)/(D3*1.5)) -> -0.22463768 | M3: =IF(D3=0, 0, 100*(G3 - D3*2)/(D3*2)) -> -0.84782609 | N3: =IF(D3=0, 0, 100*(H3 - D3*3.3)/(D3*3.3)) -> -0.32938076 | O3: =IF(D3=0, 0, 100*(I3 - D3*4)/(D3*4)) -> -0.77173913 | P3: =IF(D3=0, 0, 100*(J3 - D3*5)/(D3*5)) -> -0.64565217 | Q3: =IF(AND(K3>=0.11,K3<=0.27,L3>=-0.36,L3<=-0.22,M3>=-0.92,M3<=-0.82,N3>=-0.4,N3<=-0.3,O3>=-0.79,O3<=-0.64,P3>=-0.76,P3<=-0.61), "Yes", IF(AND(K3=0,L3=0,M3=0,N3=0,O3=0,P3=0), "Ready to test", "No")) -> Yes | R3: Neware gold clips
A4: 45807 | B4: x | C4: Akos | D4: 0.92 | E4: 0.9217 | F4: 1.3761 | G4: 1.8238 | H4: 3.025 | I4: 3.6538 | J4: 4.5689 | K4: =IF(D4=0, 0, 100*(E4 - D4*1)/(D4*1)) -> 0.18478261 | L4: =IF(D4=0, 0, 100*(F4 - D4*1.5)/(D4*1.5)) -> -0.2826087 | M4: =IF(D4=0, 0, 100*(G4 - D4*2)/(D4*2)) -> -0.88043478 | N4: =IF(D4=0, 0, 100*(H4 - D4*3.3)/(D4*3.3)) -> -0.36231884 | O4: =IF(D4=0, 0, 100*(I4 - D4*4)/(D4*4)) -> -0.71195652 | P4: =IF(D4=0, 0, 100*(J4 - D4*5)/(D4*5)) -> -0.67608696 | Q4: =IF(AND(K4>=0.11,K4<=0.27,L4>=-0.36,L4<=-0.22,M4>=-0.92,M4<=-0.82,N4>=-0.4,N4<=-0.3,O4>=-0.79,O4<=-0.64,P4>=-0.76,P4<=-0.61), "Yes", IF(AND(K4=0,L4=0,M4=0,N4=0,O4=0,P4=0), "Ready to test", "No")) -> Yes | R4: copper clips
A5: 45824 | B5: x | C5: Aleksandra + Carmine | D5: 0.92 | E5: 0.9218 | F5: 1.3757 | G5: 1.8237 | H5: 3.025 | I5: 3.6522 | J5: 4.5682 | K5: =IF(D5=0, 0, 100*(E5 - D5*1)/(D5*1)) -> 0.19565217 | L5: =IF(D5=0, 0, 100*(F5 - D5*1.5)/(D5*1.5)) -> -0.3115942 | M5: =IF(D5=0, 0, 100*(G5 - D5*2)/(D5*2)) -> -0.88586957 | N5: =IF(D5=0, 0, 100*(H5 - D5*3.3)/(D5*3.3)) -> -0.36231884 | O5: =IF(D5=0, 0, 100*(I5 - D5*4)/(D5*4)) -> -0.75543478 | P5: =IF(D5=0, 0, 100*('1-5'!J5 - D5*5)/(D5*5)) -> -0.69782609 | Q5: =IF(AND(K5>=0.11,K5<=0.27,L5>=-0.36,L5<=-0.22,M5>=-0.92,M5<=-0.82,N5>=-0.4,N5<=-0.3,O5>=-0.79,O5<=-0.64,P5>=-0.76,P5<=-0.61), "Yes", IF(AND(K5=0,L5=0,M5=0,N5=0,O5=0,P5=0), "Ready to test", "No")) -> Yes
A6: 45888 | C6: Carmine/Daniel | D6: 0.92 | E6: 0.9215 | F6: 1.3752 | G6: 1.8233 | H6: 3.0245 | I6: 3.6518 | J6: 4.5681 | K6: =IF(D6=0, 0, 100*(E6 - D6*1)/(D6*1)) -> 0.16304348 | L6: =IF(D6=0, 0, 100*(F6 - D6*1.5)/(D6*1.5)) -> -0.34782609 | M6: =IF(D6=0, 0, 100*(G6 - D6*2)/(D6*2)) -> -0.9076087 | N6: =IF(D6=0, 0, 100*(H6 - D6*3.3)/(D6*3.3)) -> -0.37878788 | O6: =IF(D6=0, 0, 100*(I6 - D6*4)/(D6*4)) -> -0.76630435 | P6: =IF(D6=0, 0, 100*(J6 - D6*5)/(D6*5)) -> -0.69347826 | Q6: =IF(AND(K6>=0.11,K6<=0.27,L6>=-0.36,L6<=-0.22,M6>=-0.92,M6<=-0.82,N6>=-0.4,N6<=-0.3,O6>=-0.79,O6<=-0.64,P6>=-0.76,P6<=-0.61), "Yes", IF(AND(K6=0,L6=0,M6=0,N6=0,O6=0,P6=0), "Ready to test", "No")) -> Yes
A7: 45916 | B7: x | C7: Aleksandra/Carmine | D7: 0.92 | E7: 0.9217 | F7: 1.376 | G7: 1.824 | H7: 3.0249 | I7: 3.6526 | J7: 4.5688 | K7: =IF(D7=0, 0, 100*(E7 - D7*1)/(D7*1)) -> 0.18478261 | L7: =IF(D7=0, 0, 100*(F7 - D7*1.5)/(D7*1.5)) -> -0.28985507 | M7: =IF(D7=0, 0, 100*(G7 - D7*2)/(D7*2)) -> -0.86956522 | N7: =IF(D7=0, 0, 100*(H7 - D7*3.3)/(D7*3.3)) -> -0.36561265 | O7: =IF(D7=0, 0, 100*(I7 - D7*4)/(D7*4)) -> -0.74456522 | P7: =IF(D7=0, 0, 100*(J7 - D7*5)/(D7*5)) -> -0.67826087 | Q7: =IF(AND(K7>=0.11,K7<=0.27,L7>=-0.36,L7<=-0.22,M7>=-0.92,M7<=-0.82,N7>=-0.4,N7<=-0.3,O7>=-0.79,O7<=-0.64,P7>=-0.76,P7<=-0.61), "Yes", IF(AND(K7=0,L7=0,M7=0,N7=0,O7=0,P7=0), "Ready to test", "No")) -> Yes
A8: 46034 | B8: x | C8: Carmine/Oniel | D8: 0.92 | E8: 0.922 | F8: 1.3767 | G8: 1.8243 | H8: 3.0261 | I8: 3.6564 | J8: 4.5699 | K8: =IF(D8=0, 0, 100*(E8 - D8*1)/(D8*1)) -> 0.2173913 | L8: =IF(D8=0, 0, 100*(F8 - D8*1.5)/(D8*1.5)) -> -0.23913043 | M8: =IF(D8=0, 0, 100*(G8 - D8*2)/(D8*2)) -> -0.85326087 | N8: =IF(D8=0, 0, 100*(H8 - D8*3.3)/(D8*3.3)) -> -0.32608696 | O8: =IF(D8=0, 0, 100*(I8 - D8*4)/(D8*4)) -> -0.64130435 | P8: =IF(D8=0, 0, 100*(J8 - D8*5)/(D8*5)) -> -0.65434783 | Q8: =IF(AND(K8>=0.11,K8<=0.27,L8>=-0.36,L8<=-0.22,M8>=-0.92,M8<=-0.82,N8>=-0.4,N8<=-0.3,O8>=-0.79,O8<=-0.64,P8>=-0.76,P8<=-0.61), "Yes", IF(AND(K8=0,L8=0,M8=0,N8=0,O8=0,P8=0), "Ready to test", "No")) -> Yes
A9: 46164 | C9: Marcus/Daniel | D9: 0.92 | E9: 0.9215 | F9: 1.3755 | G9: 1.8236 | H9: 3.0242 | I9: 3.6514 | J9: 4.5676 | K9: =IF(D9=0, 0, 100*('1-5'!E7 - D9*1)/(D9*1)) -> 0.19565217 | L9: =IF(D9=0, 0, 100*(F9 - D9*1.5)/(D9*1.5)) -> -0.32608696 | M9: =IF(D9=0, 0, 100*(G9 - D9*2)/(D9*2)) -> -0.89130435 | N9: =IF(D9=0, 0, 100*(H9 - D9*3.3)/(D9*3.3)) -> -0.3886693 | O9: =IF(D9=0, 0, 100*(I9 - D9*4)/(D9*4)) -> -0.77717391 | P9: =IF(D9=0, 0, 100*(J9 - D9*5)/(D9*5)) -> -0.70434783 | Q9: =IF(AND(K9>=0.11,K9<=0.27,L9>=-0.36,L9<=-0.22,M9>=-0.92,M9<=-0.82,N9>=-0.4,N9<=-0.3,O9>=-0.79,O9<=-0.64,P9>=-0.76,P9<=-0.61), "Yes", IF(AND(K9=0,L9=0,M9=0,N9=0,O9=0,P9=0), "Ready to test", "No")) -> Yes
A10: 29/05/2026 | C10: Marcus/Tamas | D10: 0.92 | E10: 0.9216 | F10: 1.3759 | G10: 1.8237 | H10: 3.025 | I10: 3.6519 | J10: 4.5689 | K10: =IF(D10=0, 0, 100*(E10 - D10*1)/(D10*1)) -> 0.17391304 | L10: =IF(D10=0, 0, 100*(F10 - D10*1.5)/(D10*1.5)) -> -0.29710145 | M10: =IF(D10=0, 0, 100*(G10 - D10*2)/(D10*2)) -> -0.88586957 | N10: =IF(D10=0, 0, 100*(H10 - D10*3.3)/(D10*3.3)) -> -0.36231884 | O10: =IF(D10=0, 0, 100*(I10 - D10*4)/(D10*4)) -> -0.76358696 | P10: =IF(D10=0, 0, 100*(J10 - D10*5)/(D10*5)) -> -0.67608696 | Q10: =IF(AND(K10>=0.11,K10<=0.27,L10>=-0.36,L10<=-0.22,M10>=-0.92,M10<=-0.82,N10>=-0.4,N10<=-0.3,O10>=-0.79,O10<=-0.64,P10>=-0.76,P10<=-0.61), "Yes", IF(AND(K10=0,L10=0,M10=0,N10=0,O10=0,P10=0), "Ready to test", "No")) -> Yes
K11: =IF(D11=0, 0, 100*(E11 - D11*1)/(D11*1)) -> 0 | L11: =IF(D11=0, 0, 100*(F11 - D11*1.5)/(D11*1.5)) -> 0 | M11: =IF(D11=0, 0, 100*(G11 - D11*2)/(D11*2)) -> 0 | N11: =IF(D11=0, 0, 100*(H11 - D11*3.3)/(D11*3.3)) -> 0 | O11: =IF(D11=0, 0, 100*(I11 - D11*4)/(D11*4)) -> 0 | P11: =IF(D11=0, 0, 100*(J11 - D11*5)/(D11*5)) -> 0 | Q11: =IF(AND(K11>=0.11,K11<=0.27,L11>=-0.36,L11<=-0.22,M11>=-0.92,M11<=-0.82,N11>=-0.4,N11<=-0.3,O11>=-0.79,O11<=-0.64,P11>=-0.76,P11<=-0.61), "Yes", IF(AND(K11=0,L11=0,M11=0,N11=0,O11=0,P11=0), "Ready to test", "No")) -> Ready to test
K12: =IF(D12=0, 0, 100*(E12 - D12*1)/(D12*1)) -> 0 | L12: =IF(D12=0, 0, 100*(F12 - D12*1.5)/(D12*1.5)) -> 0 | M12: =IF(D12=0, 0, 100*(G12 - D12*2)/(D12*2)) -> 0 | N12: =IF(D12=0, 0, 100*(H12 - D12*3.3)/(D12*3.3)) -> 0 | O12: =IF(D12=0, 0, 100*(I12 - D12*4)/(D12*4)) -> 0 | P12: =IF(D12=0, 0, 100*(J12 - D12*5)/(D12*5)) -> 0 | Q12: =IF(AND(K12>=0.11,K12<=0.27,L12>=-0.36,L12<=-0.22,M12>=-0.92,M12<=-0.82,N12>=-0.4,N12<=-0.3,O12>=-0.79,O12<=-0.64,P12>=-0.76,P12<=-0.61), "Yes", IF(AND(K12=0,L12=0,M12=0,N12=0,O12=0,P12=0), "Ready to test", "No")) -> Ready to test
K13: =IF(D13=0, 0, 100*(E13 - D13*1)/(D13*1)) -> 0 | L13: =IF(D13=0, 0, 100*(F13 - D13*1.5)/(D13*1.5)) -> 0 | M13: =IF(D13=0, 0, 100*(G13 - D13*2)/(D13*2)) -> 0 | N13: =IF(D13=0, 0, 100*(H13 - D13*3.3)/(D13*3.3)) -> 0 | O13: =IF(D13=0, 0, 100*(I13 - D13*4)/(D13*4)) -> 0 | P13: =IF(D13=0, 0, 100*(J13 - D13*5)/(D13*5)) -> 0 | Q13: =IF(AND(K13>=0.11,K13<=0.27,L13>=-0.36,L13<=-0.22,M13>=-0.92,M13<=-0.82,N13>=-0.4,N13<=-0.3,O13>=-0.79,O13<=-0.64,P13>=-0.76,P13<=-0.61), "Yes", IF(AND(K13=0,L13=0,M13=0,N13=0,O13=0,P13=0), "Ready to test", "No")) -> Ready to test
K14: =IF(D14=0, 0, 100*(E14 - D14*1)/(D14*1)) -> 0 | L14: =IF(D14=0, 0, 100*(F14 - D14*1.5)/(D14*1.5)) -> 0 | M14: =IF(D14=0, 0, 100*(G14 - D14*2)/(D14*2)) -> 0 | N14: =IF(D14=0, 0, 100*(H14 - D14*3.3)/(D14*3.3)) -> 0 | O14: =IF(D14=0, 0, 100*(I14 - D14*4)/(D14*4)) -> 0 | P14: =IF(D14=0, 0, 100*(J14 - D14*5)/(D14*5)) -> 0 | Q14: =IF(AND(K14>=0.11,K14<=0.27,L14>=-0.36,L14<=-0.22,M14>=-0.92,M14<=-0.82,N14>=-0.4,N14<=-0.3,O14>=-0.79,O14<=-0.64,P14>=-0.76,P14<=-0.61), "Yes", IF(AND(K14=0,L14=0,M14=0,N14=0,O14=0,P14=0), "Ready to test", "No")) -> Ready to test
K15: =IF(D15=0, 0, 100*(E15 - D15*1)/(D15*1)) -> 0 | L15: =IF(D15=0, 0, 100*(F15 - D15*1.5)/(D15*1.5)) -> 0 | M15: =IF(D15=0, 0, 100*(G15 - D15*2)/(D15*2)) -> 0 | N15: =IF(D15=0, 0, 100*(H15 - D15*3.3)/(D15*3.3)) -> 0 | O15: =IF(D15=0, 0, 100*(I15 - D15*4)/(D15*4)) -> 0 | P15: =IF(D15=0, 0, 100*(J15 - D15*5)/(D15*5)) -> 0 | Q15: =IF(AND(K15>=0.11,K15<=0.27,L15>=-0.36,L15<=-0.22,M15>=-0.92,M15<=-0.82,N15>=-0.4,N15<=-0.3,O15>=-0.79,O15<=-0.64,P15>=-0.76,P15<=-0.61), "Yes", IF(AND(K15=0,L15=0,M15=0,N15=0,O15=0,P15=0), "Ready to test", "No")) -> Ready to test
K16: =IF(D16=0, 0, 100*(E16 - D16*1)/(D16*1)) -> 0 | L16: =IF(D16=0, 0, 100*(F16 - D16*1.5)/(D16*1.5)) -> 0 | M16: =IF(D16=0, 0, 100*(G16 - D16*2)/(D16*2)) -> 0 | N16: =IF(D16=0, 0, 100*(H16 - D16*3.3)/(D16*3.3)) -> 0 | O16: =IF(D16=0, 0, 100*(I16 - D16*4)/(D16*4)) -> 0 | P16: =IF(D16=0, 0, 100*(J16 - D16*5)/(D16*5)) -> 0 | Q16: =IF(AND(K16>=0.11,K16<=0.27,L16>=-0.36,L16<=-0.22,M16>=-0.92,M16<=-0.82,N16>=-0.4,N16<=-0.3,O16>=-0.79,O16<=-0.64,P16>=-0.76,P16<=-0.61), "Yes", IF(AND(K16=0,L16=0,M16=0,N16=0,O16=0,P16=0), "Ready to test", "No")) -> Ready to test

Sheet 1-6
A1: Date | B1: IC number | C1: Measured by | D1: Applied current [A] | E1: Measured potential by the nominal value of resistance [ohm] | K1: Difference from theoretical value | Q1: Approved?
E2: 1 | F2: 1.5 | G2: 2 | H2: 3.3 | I2: 4 | J2: 5 | K2: ΔV [%] 1.0 | L2: ΔV [%] 1.5 | M2: ΔV [%] 2.0 | N2: ΔV [%] 3.3 | O2: ΔV [%] 4.0 | P2: ΔV [%] 5.0
A3: 45800 | B3: 4 clips (not copper) | C3: Aleksandra | D3: 0.92 | E3: 0.9217 | F3: 1.3765 | G3: 1.824 | H3: 3.0251 | I3: 3.6537 | J3: 4.5692 | K3: =IF(D3=0, 0, 100*(E3 - D3*1)/(D3*1)) -> 0.18478261 | L3: =IF(D3=0, 0, 100*(F3 - D3*1.5)/(D3*1.5)) -> -0.25362319 | M3: =IF(D3=0, 0, 100*(G3 - D3*2)/(D3*2)) -> -0.86956522 | N3: =IF(D3=0, 0, 100*(H3 - D3*3.3)/(D3*3.3)) -> -0.35902503 | O3: =IF(D3=0, 0, 100*(I3 - D3*4)/(D3*4)) -> -0.71467391 | P3: =IF(D3=0, 0, 100*(J3 - D3*5)/(D3*5)) -> -0.66956522 | Q3: =IF(AND(K3>=0.11,K3<=0.27,L3>=-0.36,L3<=-0.22,M3>=-0.92,M3<=-0.82,N3>=-0.4,N3<=-0.3,O3>=-0.79,O3<=-0.64,P3>=-0.76,P3<=-0.61), "Yes", IF(AND(K3=0,L3=0,M3=0,N3=0,O3=0,P3=0), "Ready to test", "No")) -> Yes
A4: 45811 | B4: copper clips | C4: Aleksandra | D4: 0.92 | E4: 0.9219 | F4: 1.3761 | G4: 1.8241 | H4: 3.0255 | I4: 3.6538 | J4: 4.5693 | K4: =IF(D4=0, 0, 100*(E4 - D4*1)/(D4*1)) -> 0.20652174 | L4: =IF(D4=0, 0, 100*(F4 - D4*1.5)/(D4*1.5)) -> -0.2826087 | M4: =IF(D4=0, 0, 100*(G4 - D4*2)/(D4*2)) -> -0.86413043 | N4: =IF(D4=0, 0, 100*(H4 - D4*3.3)/(D4*3.3)) -> -0.3458498 | O4: =IF(D4=0, 0, 100*(I4 - D4*4)/(D4*4)) -> -0.71195652 | P4: =IF(D4=0, 0, 100*(J4 - D4*5)/(D4*5)) -> -0.6673913 | Q4: =IF(AND(K4>=0.11,K4<=0.27,L4>=-0.36,L4<=-0.22,M4>=-0.92,M4<=-0.82,N4>=-0.4,N4<=-0.3,O4>=-0.79,O4<=-0.64,P4>=-0.76,P4<=-0.61), "Yes", IF(AND(K4=0,L4=0,M4=0,N4=0,O4=0,P4=0), "Ready to test", "No")) -> Yes
A5: 45824 | B5: x | C5: Aleksandra + Carmine | D5: 0.92 | E5: 0.9217 | F5: 1.3758 | G5: 1.8238 | H5: 3.0252 | I5: 3.6533 | J5: 4.5681 | K5: =IF(D5=0, 0, 100*(E5 - D5*1)/(D5*1)) -> 0.18478261 | L5: =IF(D5=0, 0, 100*(F5 - D5*1.5)/(D5*1.5)) -> -0.30434783 | M5: =IF(D5=0, 0, 100*(G5 - D5*2)/(D5*2)) -> -0.88043478 | N5: =IF(D5=0, 0, 100*(H5 - D5*3.3)/(D5*3.3)) -> -0.35573123 | O5: =IF(D5=0, 0, 100*(I5 - D5*4)/(D5*4)) -> -0.72554348 | P5: =IF(D5=0, 0, 100*(J5 - D5*5)/(D5*5)) -> -0.69347826 | Q5: =IF(AND(K5>=0.11,K5<=0.27,L5>=-0.36,L5<=-0.22,M5>=-0.92,M5<=-0.82,N5>=-0.4,N5<=-0.3,O5>=-0.79,O5<=-0.64,P5>=-0.76,P5<=-0.61), "Yes", IF(AND(K5=0,L5=0,M5=0,N5=0,O5=0,P5=0), "Ready to test", "No")) -> Yes
A6: 45895 | B6: 885 | C6: Carmine | D6: 0.92 | E6: 0.9218 | F6: 1.3755 | G6: 1.8236 | H6: 3.0251 | I6: 3.6522 | J6: 4.5684 | K6: =IF(D6=0, 0, 100*(E6 - D6*1)/(D6*1)) -> 0.19565217 | L6: =IF(D6=0, 0, 100*(F6 - D6*1.5)/(D6*1.5)) -> -0.32608696 | M6: =IF(D6=0, 0, 100*(G6 - D6*2)/(D6*2)) -> -0.89130435 | N6: =IF(D6=0, 0, 100*(H6 - D6*3.3)/(D6*3.3)) -> -0.35902503 | O6: =IF(D6=0, 0, 100*(I6 - D6*4)/(D6*4)) -> -0.75543478 | P6: =IF(D6=0, 0, 100*(J6 - D6*5)/(D6*5)) -> -0.68695652 | Q6: =IF(AND(K6>=0.11,K6<=0.27,L6>=-0.36,L6<=-0.22,M6>=-0.92,M6<=-0.82,N6>=-0.4,N6<=-0.3,O6>=-0.79,O6<=-0.64,P6>=-0.76,P6<=-0.61), "Yes", IF(AND(K6=0,L6=0,M6=0,N6=0,O6=0,P6=0), "Ready to test", "No")) -> Yes
A7: 45952 | B7: x | C7: Ola + Tamas | D7: 0.92 | E7: 0.922 | F7: 1.376 | G7: 1.824 | H7: 3.0255 | I7: 3.6547 | J7: 4.5699 | K7: =IF(D7=0, 0, 100*(E7 - D7*1)/(D7*1)) -> 0.2173913 | L7: =IF(D7=0, 0, 100*(F7 - D7*1.5)/(D7*1.5)) -> -0.28985507 | M7: =IF(D7=0, 0, 100*(G7 - D7*2)/(D7*2)) -> -0.86956522 | N7: =IF(D7=0, 0, 100*(H7 - D7*3.3)/(D7*3.3)) -> -0.3458498 | O7: =IF(D7=0, 0, 100*(I7 - D7*4)/(D7*4)) -> -0.6875 | P7: =IF(D7=0, 0, 100*(J7 - D7*5)/(D7*5)) -> -0.65434783 | Q7: =IF(AND(K7>=0.11,K7<=0.27,L7>=-0.36,L7<=-0.22,M7>=-0.92,M7<=-0.82,N7>=-0.4,N7<=-0.3,O7>=-0.79,O7<=-0.64,P7>=-0.76,P7<=-0.61), "Yes", IF(AND(K7=0,L7=0,M7=0,N7=0,O7=0,P7=0), "Ready to test", "No")) -> Yes
A8: 46178 | B8: X | C8: Tamás/Emil | D8: 0.92 | E8: 0.9217 | F8: 1.3756 | G8: 1.8235 | H8: 3.0251 | I8: 3.6533 | J8: 4.5681 | K8: =IF(D8=0, 0, 100*(E8 - D8*1)/(D8*1)) -> 0.18478261 | L8: =IF(D8=0, 0, 100*(F8 - D8*1.5)/(D8*1.5)) -> -0.31884058 | M8: =IF(D8=0, 0, 100*(G8 - D8*2)/(D8*2)) -> -0.89673913 | N8: =IF(D8=0, 0, 100*(H8 - D8*3.3)/(D8*3.3)) -> -0.35902503 | O8: =IF(D8=0, 0, 100*(I8 - D8*4)/(D8*4)) -> -0.72554348 | P8: =IF(D8=0, 0, 100*(J8 - D8*5)/(D8*5)) -> -0.69347826 | Q8: =IF(AND(K8>=0.11,K8<=0.27,L8>=-0.36,L8<=-0.22,M8>=-0.92,M8<=-0.82,N8>=-0.4,N8<=-0.3,O8>=-0.79,O8<=-0.64,P8>=-0.76,P8<=-0.61), "Yes", IF(AND(K8=0,L8=0,M8=0,N8=0,O8=0,P8=0), "Ready to test", "No")) -> Yes
K9: =IF(D9=0, 0, 100*(E9 - D9*1)/(D9*1)) -> 0 | L9: =IF(D9=0, 0, 100*(F9 - D9*1.5)/(D9*1.5)) -> 0 | M9: =IF(D9=0, 0, 100*(G9 - D9*2)/(D9*2)) -> 0 | N9: =IF(D9=0, 0, 100*(H9 - D9*3.3)/(D9*3.3)) -> 0 | O9: =IF(D9=0, 0, 100*(I9 - D9*4)/(D9*4)) -> 0 | P9: =IF(D9=0, 0, 100*(J9 - D9*5)/(D9*5)) -> 0 | Q9: =IF(AND(K9>=0.11,K9<=0.27,L9>=-0.36,L9<=-0.22,M9>=-0.92,M9<=-0.82,N9>=-0.4,N9<=-0.3,O9>=-0.79,O9<=-0.64,P9>=-0.76,P9<=-0.61), "Yes", IF(AND(K9=0,L9=0,M9=0,N9=0,O9=0,P9=0), "Ready to test", "No")) -> Ready to test
K10: =IF(D10=0, 0, 100*(E10 - D10*1)/(D10*1)) -> 0 | L10: =IF(D10=0, 0, 100*(F10 - D10*1.5)/(D10*1.5)) -> 0 | M10: =IF(D10=0, 0, 100*(G10 - D10*2)/(D10*2)) -> 0 | N10: =IF(D10=0, 0, 100*(H10 - D10*3.3)/(D10*3.3)) -> 0 | O10: =IF(D10=0, 0, 100*(I10 - D10*4)/(D10*4)) -> 0 | P10: =IF(D10=0, 0, 100*(J10 - D10*5)/(D10*5)) -> 0 | Q10: =IF(AND(K10>=0.11,K10<=0.27,L10>=-0.36,L10<=-0.22,M10>=-0.92,M10<=-0.82,N10>=-0.4,N10<=-0.3,O10>=-0.79,O10<=-0.64,P10>=-0.76,P10<=-0.61), "Yes", IF(AND(K10=0,L10=0,M10=0,N10=0,O10=0,P10=0), "Ready to test", "No")) -> Ready to test
K11: =IF(D11=0, 0, 100*(E11 - D11*1)/(D11*1)) -> 0 | L11: =IF(D11=0, 0, 100*(F11 - D11*1.5)/(D11*1.5)) -> 0 | M11: =IF(D11=0, 0, 100*(G11 - D11*2)/(D11*2)) -> 0 | N11: =IF(D11=0, 0, 100*(H11 - D11*3.3)/(D11*3.3)) -> 0 | O11: =IF(D11=0, 0, 100*(I11 - D11*4)/(D11*4)) -> 0 | P11: =IF(D11=0, 0, 100*(J11 - D11*5)/(D11*5)) -> 0 | Q11: =IF(AND(K11>=0.11,K11<=0.27,L11>=-0.36,L11<=-0.22,M11>=-0.92,M11<=-0.82,N11>=-0.4,N11<=-0.3,O11>=-0.79,O11<=-0.64,P11>=-0.76,P11<=-0.61), "Yes", IF(AND(K11=0,L11=0,M11=0,N11=0,O11=0,P11=0), "Ready to test", "No")) -> Ready to test
K12: =IF(D12=0, 0, 100*(E12 - D12*1)/(D12*1)) -> 0 | L12: =IF(D12=0, 0, 100*(F12 - D12*1.5)/(D12*1.5)) -> 0 | M12: =IF(D12=0, 0, 100*(G12 - D12*2)/(D12*2)) -> 0 | N12: =IF(D12=0, 0, 100*(H12 - D12*3.3)/(D12*3.3)) -> 0 | O12: =IF(D12=0, 0, 100*(I12 - D12*4)/(D12*4)) -> 0 | P12: =IF(D12=0, 0, 100*(J12 - D12*5)/(D12*5)) -> 0 | Q12: =IF(AND(K12>=0.11,K12<=0.27,L12>=-0.36,L12<=-0.22,M12>=-0.92,M12<=-0.82,N12>=-0.4,N12<=-0.3,O12>=-0.79,O12<=-0.64,P12>=-0.76,P12<=-0.61), "Yes", IF(AND(K12=0,L12=0,M12=0,N12=0,O12=0,P12=0), "Ready to test", "No")) -> Ready to test
K13: =IF(D13=0, 0, 100*(E13 - D13*1)/(D13*1)) -> 0 | L13: =IF(D13=0, 0, 100*(F13 - D13*1.5)/(D13*1.5)) -> 0 | M13: =IF(D13=0, 0, 100*(G13 - D13*2)/(D13*2)) -> 0 | N13: =IF(D13=0, 0, 100*(H13 - D13*3.3)/(D13*3.3)) -> 0 | O13: =IF(D13=0, 0, 100*(I13 - D13*4)/(D13*4)) -> 0 | P13: =IF(D13=0, 0, 100*(J13 - D13*5)/(D13*5)) -> 0 | Q13: =IF(AND(K13>=0.11,K13<=0.27,L13>=-0.36,L13<=-0.22,M13>=-0.92,M13<=-0.82,N13>=-0.4,N13<=-0.3,O13>=-0.79,O13<=-0.64,P13>=-0.76,P13<=-0.61), "Yes", IF(AND(K13=0,L13=0,M13=0,N13=0,O13=0,P13=0), "Ready to test", "No")) -> Ready to test
K14: =IF(D14=0, 0, 100*(E14 - D14*1)/(D14*1)) -> 0 | L14: =IF(D14=0, 0, 100*(F14 - D14*1.5)/(D14*1.5)) -> 0 | M14: =IF(D14=0, 0, 100*(G14 - D14*2)/(D14*2)) -> 0 | N14: =IF(D14=0, 0, 100*(H14 - D14*3.3)/(D14*3.3)) -> 0 | O14: =IF(D14=0, 0, 100*(I14 - D14*4)/(D14*4)) -> 0 | P14: =IF(D14=0, 0, 100*(J14 - D14*5)/(D14*5)) -> 0 | Q14: =IF(AND(K14>=0.11,K14<=0.27,L14>=-0.36,L14<=-0.22,M14>=-0.92,M14<=-0.82,N14>=-0.4,N14<=-0.3,O14>=-0.79,O14<=-0.64,P14>=-0.76,P14<=-0.61), "Yes", IF(AND(K14=0,L14=0,M14=0,N14=0,O14=0,P14=0), "Ready to test", "No")) -> Ready to test
K15: =IF(D15=0, 0, 100*(E15 - D15*1)/(D15*1)) -> 0 | L15: =IF(D15=0, 0, 100*(F15 - D15*1.5)/(D15*1.5)) -> 0 | M15: =IF(D15=0, 0, 100*(G15 - D15*2)/(D15*2)) -> 0 | N15: =IF(D15=0, 0, 100*(H15 - D15*3.3)/(D15*3.3)) -> 0 | O15: =IF(D15=0, 0, 100*(I15 - D15*4)/(D15*4)) -> 0 | P15: =IF(D15=0, 0, 100*(J15 - D15*5)/(D15*5)) -> 0 | Q15: =IF(AND(K15>=0.11,K15<=0.27,L15>=-0.36,L15<=-0.22,M15>=-0.92,M15<=-0.82,N15>=-0.4,N15<=-0.3,O15>=-0.79,O15<=-0.64,P15>=-0.76,P15<=-0.61), "Yes", IF(AND(K15=0,L15=0,M15=0,N15=0,O15=0,P15=0), "Ready to test", "No")) -> Ready to test
K16: =IF(D16=0, 0, 100*(E16 - D16*1)/(D16*1)) -> 0 | L16: =IF(D16=0, 0, 100*(F16 - D16*1.5)/(D16*1.5)) -> 0 | M16: =IF(D16=0, 0, 100*(G16 - D16*2)/(D16*2)) -> 0 | N16: =IF(D16=0, 0, 100*(H16 - D16*3.3)/(D16*3.3)) -> 0 | O16: =IF(D16=0, 0, 100*(I16 - D16*4)/(D16*4)) -> 0 | P16: =IF(D16=0, 0, 100*(J16 - D16*5)/(D16*5)) -> 0 | Q16: =IF(AND(K16>=0.11,K16<=0.27,L16>=-0.36,L16<=-0.22,M16>=-0.92,M16<=-0.82,N16>=-0.4,N16<=-0.3,O16>=-0.79,O16<=-0.64,P16>=-0.76,P16<=-0.61), "Yes", IF(AND(K16=0,L16=0,M16=0,N16=0,O16=0,P16=0), "Ready to test", "No")) -> Ready to test

Sheet 1-5
A1: Date | B1: IC number | C1: Measured by | D1: Applied current [A] | E1: Measured potential by the nominal value of resistance [ohm] | K1: Difference from theoretical value [mV] | Q1: Approved? | R1: Note
E2: 1 | F2: 1.5 | G2: 2 | H2: 3.3 | I2: 4 | J2: 5 | K2: ΔV [%] 1.0 | L2: ΔV [%] 1.5 | M2: ΔV [%] 2.0 | N2: ΔV [%] 3.3 | O2: ΔV [%] 4.0 | P2: ΔV [%] 5.0
A3: 45800 | B3: old clips | C3: Aleksandra | D3: 0.92 | E3: 0.9389 | F3: 1.393 | G3: 1.8347 | H3: 3.0366 | I3: 3.6647 | J3: 4.5786 | K3: =IF(D3=0, 0, 100*(E3 - D3*1)/(D3*1)) -> 2.0543478 | L3: =IF(D3=0, 0, 100*(F3 - D3*1.5)/(D3*1.5)) -> 0.94202899 | M3: =IF(D3=0, 0, 100*(G3 - D3*2)/(D3*2)) -> -0.28804348 | N3: =IF(D3=0, 0, 100*(H3 - D3*3.3)/(D3*3.3)) -> 0.019762846 | O3: =IF(D3=0, 0, 100*(I3 - D3*4)/(D3*4)) -> -0.41576087 | P3: =IF(D3=0, 0, 100*(J3 - D3*5)/(D3*5)) -> -0.46521739 | Q3: =IF(AND(K3>=0.11,K3<=0.27,L3>=-0.36,L3<=-0.22,M3>=-0.92,M3<=-0.82,N3>=-0.4,N3<=-0.3,O3>=-0.79,O3<=-0.64,P3>=-0.76,P3<=-0.61), "Yes", IF(AND(K3=0,L3=0,M3=0,N3=0,O3=0,P3=0), "Ready to test", "No")) -> No | R3: Old clips
A4: 45803 | B4: new clips copper | C4: carmine | D4: 0.92 | E4: 0.9218 | F4: 1.376 | G4: 1.8242 | H4: 3.0257 | I4: 3.6528 | J4: 4.5697 | K4: =IF(D4=0, 0, 100*(E4 - D4*1)/(D4*1)) -> 0.19565217 | L4: =IF(D4=0, 0, 100*(F4 - D4*1.5)/(D4*1.5)) -> -0.28985507 | M4: =IF(D4=0, 0, 100*(G4 - D4*2)/(D4*2)) -> -0.85869565 | N4: =IF(D4=0, 0, 100*(H4 - D4*3.3)/(D4*3.3)) -> -0.33926219 | O4: =IF(D4=0, 0, 100*(I4 - D4*4)/(D4*4)) -> -0.73913043 | P4: =IF(D4=0, 0, 100*(J4 - D4*5)/(D4*5)) -> -0.65869565 | Q4: =IF(AND(K4>=0.11,K4<=0.27,L4>=-0.36,L4<=-0.22,M4>=-0.92,M4<=-0.82,N4>=-0.4,N4<=-0.3,O4>=-0.79,O4<=-0.64,P4>=-0.76,P4<=-0.61), "Yes", IF(AND(K4=0,L4=0,M4=0,N4=0,O4=0,P4=0), "Ready to test", "No")) -> Yes
A5: 45824 | B5: x | C5: Aleksandra + Carmine | D5: 0.92 | E5: 0.9217 | F5: 1.3758 | G5: 1.8238 | H5: 3.0251 | I5: 3.653 | J5: 4.5679 | K5: =IF(D5=0, 0, 100*(E5 - D5*1)/(D5*1)) -> 0.18478261 | L5: =IF(D5=0, 0, 100*(F5 - D5*1.5)/(D5*1.5)) -> -0.30434783 | M5: =IF(D5=0, 0, 100*(G5 - D5*2)/(D5*2)) -> -0.88043478 | N5: =IF(D5=0, 0, 100*(H5 - D5*3.3)/(D5*3.3)) -> -0.35902503 | O5: =IF(D5=0, 0, 100*(I5 - D5*4)/(D5*4)) -> -0.73369565 | P5: =IF(D5=0, 0, 100*(J5 - D5*5)/(D5*5)) -> -0.69782609 | Q5: =IF(AND(K5>=0.11,K5<=0.27,L5>=-0.36,L5<=-0.22,M5>=-0.92,M5<=-0.82,N5>=-0.4,N5<=-0.3,O5>=-0.79,O5<=-0.64,P5>=-0.76,P5<=-0.61), "Yes", IF(AND(K5=0,L5=0,M5=0,N5=0,O5=0,P5=0), "Ready to test", "No")) -> Yes
A6: 45974 | B6: x | C6: Daniel + Bardia | D6: 0.92 | E6: 0.9217 | F6: 1.3761 | G6: 1.8237 | H6: 3.0255 | I6: 3.6546 | J6: 4.5688 | K6: =IF(D6=0, 0, 100*(E6 - D6*1)/(D6*1)) -> 0.18478261 | L6: =IF(D6=0, L70, 100*(F6 - D6*1.5)/(D6*1.5)) -> -0.2826087 | M6: =IF(D6=0, 0, 100*(G6 - D6*2)/(D6*2)) -> -0.88586957 | N6: =IF(D6=0, 0, 100*(H6 - D6*3.3)/(D6*3.3)) -> -0.3458498 | O6: =IF(D6=0, 0, 100*(I6 - D6*4)/(D6*4)) -> -0.69021739 | P6: =IF(D6=0, 0, 100*(J6 - D6*5)/(D6*5)) -> -0.67826087 | Q6: =IF(AND(K6>=0.11,K6<=0.27,L6>=-0.36,L6<=-0.22,M6>=-0.92,M6<=-0.82,N6>=-0.4,N6<=-0.3,O6>=-0.79,O6<=-0.64,P6>=-0.76,P6<=-0.61), "Yes", IF(AND(K6=0,L6=0,M6=0,N6=0,O6=0,P6=0), "Ready to test", "No")) -> Yes
A7: 46034 | B7: x | C7: Carmine/Oniel | D7: 0.92 | E7: 0.9218 | F7: 1.3765 | G7: 1.8239 | H7: 3.0256 | I7: 3.6554 | J7: 4.5697 | K7: =IF(D7=0, 0, 100*(E7 - D7*1)/(D7*1)) -> 0.19565217 | L7: =IF(D7=0, 0, 100*(F7 - D7*1.5)/(D7*1.5)) -> -0.25362319 | M7: =IF(D7=0, 0, 100*(G7 - D7*2)/(D7*2)) -> -0.875 | N7: =IF(D7=0, 0, 100*(H7 - D7*3.3)/(D7*3.3)) -> -0.34255599 | O7: =IF(D7=0, 0, 100*(I7 - D7*4)/(D7*4)) -> -0.66847826 | P7: =IF(D7=0, 0, 100*(J7 - D7*5)/(D7*5)) -> -0.65869565 | Q7: =IF(AND(K7>=0.11,K7<=0.27,L7>=-0.36,L7<=-0.22,M7>=-0.92,M7<=-0.82,N7>=-0.4,N7<=-0.3,O7>=-0.79,O7<=-0.64,P7>=-0.76,P7<=-0.61), "Yes", IF(AND(K7=0,L7=0,M7=0,N7=0,O7=0,P7=0), "Ready to test", "No")) -> Yes
A8: 46164 | C8: Marcus/Daniel | D8: 0.92 | E8: 0.9216 | F8: 1.3753 | G8: 1.8236 | H8: 3.0252 | I8: 3.6523 | J8: 4.5678 | K8: =IF(D8=0, 0, 100*(E8 - D8*1)/(D8*1)) -> 0.17391304 | L8: =IF(D8=0, 0, 100*(F8 - D8*1.5)/(D8*1.5)) -> -0.34057971 | M8: =IF(E8=0, 0, 100*(G8 - E8*2)/(E8*2)) -> -1.0633681 | N8: =IF(E8=0, 0, 100*(H8 - E8*3.3)/(E8*3.3)) -> -0.52872475 | O8: =IF(E8=0, 0, 100*(I8 - E8*4)/(E8*4)) -> -0.9250217 | P8: =IF(E8=0, 0, 100*(J8 - E8*5)/(E8*5)) -> -0.87239583 | Q8: =IF(AND(K8>=0.11,K8<=0.27,L8>=-0.36,L8<=-0.22,M8>=-0.92,M8<=-0.82,N8>=-0.4,N8<=-0.3,O8>=-0.79,O8<=-0.64,P8>=-0.76,P8<=-0.61), "Yes", IF(AND(K8=0,L8=0,M8=0,N8=0,O8=0,P8=0), "Ready to test", "No")) -> No
K9: =IF(D9=0, 0, 100*(E9 - D9*1)/(D9*1)) -> 0 | L9: =IF(D9=0, 0, 100*(F9 - D9*1.5)/(D9*1.5)) -> 0 | M9: =IF(D9=0, 0, 100*(G9 - D9*2)/(D9*2)) -> 0 | N9: =IF(D9=0, 0, 100*(H9 - D9*3.3)/(D9*3.3)) -> 0 | O9: =IF(D9=0, 0, 100*(I9 - D9*4)/(D9*4)) -> 0 | P9: =IF(D9=0, 0, 100*(J9 - D9*5)/(D9*5)) -> 0 | Q9: =IF(AND(K9>=0.11,K9<=0.27,L9>=-0.36,L9<=-0.22,M9>=-0.92,M9<=-0.82,N9>=-0.4,N9<=-0.3,O9>=-0.79,O9<=-0.64,P9>=-0.76,P9<=-0.61), "Yes", IF(AND(K9=0,L9=0,M9=0,N9=0,O9=0,P9=0), "Ready to test", "No")) -> Ready to test
K10: =IF(D10=0, 0, 100*(E10 - D10*1)/(D10*1)) -> 0 | L10: =IF(D10=0, 0, 100*(F10 - D10*1.5)/(D10*1.5)) -> 0 | M10: =IF(D10=0, 0, 100*(G10 - D10*2)/(D10*2)) -> 0 | N10: =IF(D10=0, 0, 100*(H10 - D10*3.3)/(D10*3.3)) -> 0 | O10: =IF(D10=0, 0, 100*(I10 - D10*4)/(D10*4)) -> 0 | P10: =IF(D10=0, 0, 100*(J10 - D10*5)/(D10*5)) -> 0 | Q10: =IF(AND(K10>=0.11,K10<=0.27,L10>=-0.36,L10<=-0.22,M10>=-0.92,M10<=-0.82,N10>=-0.4,N10<=-0.3,O10>=-0.79,O10<=-0.64,P10>=-0.76,P10<=-0.61), "Yes", IF(AND(K10=0,L10=0,M10=0,N10=0,O10=0,P10=0), "Ready to test", "No")) -> Ready to test
K11: =IF(D11=0, 0, 100*(E11 - D11*1)/(D11*1)) -> 0 | L11: =IF(D11=0, 0, 100*(F11 - D11*1.5)/(D11*1.5)) -> 0 | M11: =IF(D11=0, 0, 100*(G11 - D11*2)/(D11*2)) -> 0 | N11: =IF(D11=0, 0, 100*(H11 - D11*3.3)/(D11*3.3)) -> 0 | O11: =IF(D11=0, 0, 100*(I11 - D11*4)/(D11*4)) -> 0 | P11: =IF(D11=0, 0, 100*(J11 - D11*5)/(D11*5)) -> 0 | Q11: =IF(AND(K11>=0.11,K11<=0.27,L11>=-0.36,L11<=-0.22,M11>=-0.92,M11<=-0.82,N11>=-0.4,N11<=-0.3,O11>=-0.79,O11<=-0.64,P11>=-0.76,P11<=-0.61), "Yes", IF(AND(K11=0,L11=0,M11=0,N11=0,O11=0,P11=0), "Ready to test", "No")) -> Ready to test
K12: =IF(D12=0, 0, 100*(E12 - D12*1)/(D12*1)) -> 0 | L12: =IF(D12=0, 0, 100*(F12 - D12*1.5)/(D12*1.5)) -> 0 | M12: =IF(D12=0, 0, 100*(G12 - D12*2)/(D12*2)) -> 0 | N12: =IF(D12=0, 0, 100*(H12 - D12*3.3)/(D12*3.3)) -> 0 | O12: =IF(D12=0, 0, 100*(I12 - D12*4)/(D12*4)) -> 0 | P12: =IF(D12=0, 0, 100*(J12 - D12*5)/(D12*5)) -> 0 | Q12: =IF(AND(K12>=0.11,K12<=0.27,L12>=-0.36,L12<=-0.22,M12>=-0.92,M12<=-0.82,N12>=-0.4,N12<=-0.3,O12>=-0.79,O12<=-0.64,P12>=-0.76,P12<=-0.61), "Yes", IF(AND(K12=0,L12=0,M12=0,N12=0,O12=0,P12=0), "Ready to test", "No")) -> Ready to test
K13: =IF(D13=0, 0, 100*(E13 - D13*1)/(D13*1)) -> 0 | L13: =IF(D13=0, 0, 100*(F13 - D13*1.5)/(D13*1.5)) -> 0 | M13: =IF(D13=0, 0, 100*(G13 - D13*2)/(D13*2)) -> 0 | N13: =IF(D13=0, 0, 100*(H13 - D13*3.3)/(D13*3.3)) -> 0 | O13: =IF(D13=0, 0, 100*(I13 - D13*4)/(D13*4)) -> 0 | P13: =IF(D13=0, 0, 100*(J13 - D13*5)/(D13*5)) -> 0 | Q13: =IF(AND(K13>=0.11,K13<=0.27,L13>=-0.36,L13<=-0.22,M13>=-0.92,M13<=-0.82,N13>=-0.4,N13<=-0.3,O13>=-0.79,O13<=-0.64,P13>=-0.76,P13<=-0.61), "Yes", IF(AND(K13=0,L13=0,M13=0,N13=0,O13=0,P13=0), "Ready to test", "No")) -> Ready to test
K14: =IF(D14=0, 0, 100*(E14 - D14*1)/(D14*1)) -> 0 | L14: =IF(D14=0, 0, 100*(F14 - D14*1.5)/(D14*1.5)) -> 0 | M14: =IF(D14=0, 0, 100*(G14 - D14*2)/(D14*2)) -> 0 | N14: =IF(D14=0, 0, 100*(H14 - D14*3.3)/(D14*3.3)) -> 0 | O14: =IF(D14=0, 0, 100*(I14 - D14*4)/(D14*4)) -> 0 | P14: =IF(D14=0, 0, 100*(J14 - D14*5)/(D14*5)) -> 0 | Q14: =IF(AND(K14>=0.11,K14<=0.27,L14>=-0.36,L14<=-0.22,M14>=-0.92,M14<=-0.82,N14>=-0.4,N14<=-0.3,O14>=-0.79,O14<=-0.64,P14>=-0.76,P14<=-0.61), "Yes", IF(AND(K14=0,L14=0,M14=0,N14=0,O14=0,P14=0), "Ready to test", "No")) -> Ready to test
K15: =IF(D15=0, 0, 100*(E15 - D15*1)/(D15*1)) -> 0 | L15: =IF(D15=0, 0, 100*(F15 - D15*1.5)/(D15*1.5)) -> 0 | M15: =IF(D15=0, 0, 100*(G15 - D15*2)/(D15*2)) -> 0 | N15: =IF(D15=0, 0, 100*(H15 - D15*3.3)/(D15*3.3)) -> 0 | O15: =IF(D15=0, 0, 100*(I15 - D15*4)/(D15*4)) -> 0 | P15: =IF(D15=0, 0, 100*(J15 - D15*5)/(D15*5)) -> 0 | Q15: =IF(AND(K15>=0.11,K15<=0.27,L15>=-0.36,L15<=-0.22,M15>=-0.92,M15<=-0.82,N15>=-0.4,N15<=-0.3,O15>=-0.79,O15<=-0.64,P15>=-0.76,P15<=-0.61), "Yes", IF(AND(K15=0,L15=0,M15=0,N15=0,O15=0,P15=0), "Ready to test", "No")) -> Ready to test
K16: =IF(D16=0, 0, 100*(E16 - D16*1)/(D16*1)) -> 0 | L16: =IF(D16=0, 0, 100*(F16 - D16*1.5)/(D16*1.5)) -> 0 | M16: =IF(D16=0, 0, 100*(G16 - D16*2)/(D16*2)) -> 0 | N16: =IF(D16=0, 0, 100*(H16 - D16*3.3)/(D16*3.3)) -> 0 | O16: =IF(D16=0, 0, 100*(I16 - D16*4)/(D16*4)) -> 0 | P16: =IF(D16=0, 0, 100*(J16 - D16*5)/(D16*5)) -> 0 | Q16: =IF(AND(K16>=0.11,K16<=0.27,L16>=-0.36,L16<=-0.22,M16>=-0.92,M16<=-0.82,N16>=-0.4,N16<=-0.3,O16>=-0.79,O16<=-0.64,P16>=-0.76,P16<=-0.61), "Yes", IF(AND(K16=0,L16=0,M16=0,N16=0,O16=0,P16=0), "Ready to test", "No")) -> Ready to test

Sheet 1-7
A1: Date | B1: IC number | C1: Measured by | D1: Applied current [A] | E1: Measured potential by the nominal value of resistance [ohm] | K1: Difference from theoretical value [mV] | Q1: Approved?
E2: 1 | F2: 1.5 | G2: 2 | H2: 3.3 | I2: 4 | J2: 5 | K2: ΔV [%] 1.0 | L2: ΔV [%] 1.5 | M2: ΔV [%] 2.0 | N2: ΔV [%] 3.3 | O2: ΔV [%] 4.0 | P2: ΔV [%] 5.0
A3: 45811 | B3: copper clips | C3: Aleksandra | D3: 0.92 | E3: 0.9218 | F3: 1.3765 | G3: 1.8243 | H3: 3.0259 | I3: 3.6553 | J3: 4.5694 | K3: =IF(D3=0, 0, 100*('1-6'!E4 - D3*1)/(D3*1)) -> 0.20652174 | L3: =IF(D3=0, 0, 100*(F3 - D3*1.5)/(D3*1.5)) -> -0.25362319 | M3: =IF(D3=0, 0, 100*(G3 - D3*2)/(D3*2)) -> -0.85326087 | N3: =IF(D3=0, 0, 100*(H3 - D3*3.3)/(D3*3.3)) -> -0.33267457 | O3: =IF(D3=0, 0, 100*(I3 - D3*4)/(D3*4)) -> -0.67119565 | P3: =IF(D3=0, 0, 100*(J3 - D3*5)/(D3*5)) -> -0.66521739 | Q3: =IF(AND(K3>=0.11,K3<=0.27,L3>=-0.36,L3<=-0.22,M3>=-0.92,M3<=-0.82,N3>=-0.4,N3<=-0.3,O3>=-0.79,O3<=-0.64,P3>=-0.76,P3<=-0.61), "Yes", IF(AND(K3=0,L3=0,M3=0,N3=0,O3=0,P3=0), "Ready to test", "No")) -> Yes
A4: 45824 | B4: x | C4: Aleksandra + Carmine | D4: 0.92 | E4: 0.9218 | F4: 1.3759 | G4: 1.824 | H4: 3.0256 | I4: 3.6541 | J4: 4.5688 | K4: =IF(D4=0, 0, 100*(E4 - D4*1)/(D4*1)) -> 0.19565217 | L4: =IF(D4=0, 0, 100*(F4 - D4*1.5)/(D4*1.5)) -> -0.29710145 | M4: =IF(D4=0, 0, 100*(G4 - D4*2)/(D4*2)) -> -0.86956522 | N4: =IF(D4=0, 0, 100*(H4 - D4*3.3)/(D4*3.3)) -> -0.34255599 | O4: =IF(D4=0, 0, 100*(I4 - D4*4)/(D4*4)) -> -0.70380435 | P4: =IF(D4=0, 0, 100*(J3 - D4*5)/(D4*5)) -> -0.66521739 | Q4: =IF(AND(K4>=0.11,K4<=0.27,L4>=-0.36,L4<=-0.22,M4>=-0.92,M4<=-0.82,N4>=-0.4,N4<=-0.3,O4>=-0.79,O4<=-0.64,P4>=-0.76,P4<=-0.61), "Yes", IF(AND(K4=0,L4=0,M4=0,N4=0,O4=0,P4=0), "Ready to test", "No")) -> Yes
A5: 45895 | B5: 886 | C5: Carmine | D5: 0.92 | E5: 0.9218 | F5: 1.376 | G5: 1.824 | H5: 3.0254 | I5: 3.6538 | J5: 4.5696 | K5: =IF(D5=0, 0, 100*(E5 - D5*1)/(D5*1)) -> 0.19565217 | L5: =IF(D5=0, 0, 100*(F5 - D5*1.5)/(D5*1.5)) -> -0.28985507 | M5: =IF(D5=0, 0, 100*(G5 - D5*2)/(D5*2)) -> -0.86956522 | N5: =IF(D5=0, 0, 100*(H5 - D5*3.3)/(D5*3.3)) -> -0.34914361 | O5: =IF(D5=0, 0, 100*(I5 - D5*4)/(D5*4)) -> -0.71195652 | P5: =IF(D5=0, 0, 100*(J5 - D5*5)/(D5*5)) -> -0.66086957 | Q5: =IF(AND(K5>=0.11,K5<=0.27,L5>=-0.36,L5<=-0.22,M5>=-0.92,M5<=-0.82,N5>=-0.4,N5<=-0.3,O5>=-0.79,O5<=-0.64,P5>=-0.76,P5<=-0.61), "Yes", IF(AND(K5=0,L5=0,M5=0,N5=0,O5=0,P5=0), "Ready to test", "No")) -> Yes
A6: 45952 | B6: x | C6: Ola + Tamas | D6: 0.92 | E6: 0.9217 | F6: 1.3764 | G6: 1.8242 | H6: 3.0262 | I6: 3.6545 | J6: 4.5699 | K6: =IF(D6=0, 0, 100*(E6 - D6*1)/(D6*1)) -> 0.18478261 | L6: =IF(D6=0, 0, 100*(F6 - D6*1.5)/(D6*1.5)) -> -0.26086957 | M6: =IF(D6=0, 0, 100*(G6 - D6*2)/(D6*2)) -> -0.85869565 | N6: =IF(D6=0, 0, 100*(H6 - D6*3.3)/(D6*3.3)) -> -0.32279315 | O6: =IF(D6=0, 0, 100*(I6 - D6*4)/(D6*4)) -> -0.69293478 | P6: =IF(D6=0, 0, 100*(J6 - D6*5)/(D6*5)) -> -0.65434783 | Q6: =IF(AND(K6>=0.11,K6<=0.27,L6>=-0.36,L6<=-0.22,M6>=-0.92,M6<=-0.82,N6>=-0.4,N6<=-0.3,O6>=-0.79,O6<=-0.64,P6>=-0.76,P6<=-0.61), "Yes", IF(AND(K6=0,L6=0,M6=0,N6=0,O6=0,P6=0), "Ready to test", "No")) -> Yes
A7: 16/06/2026 | B7: x | C7: Oniel+Marcus | D7: 0.92 | E7: 0.9216 | F7: 1.3761 | G7: 1.8242 | H7: 3.0256 | I7: 3.6551 | J7: 4.5694 | K7: =IF(D7=0, 0, 100*(E7 - D7*1)/(D7*1)) -> 0.17391304 | L7: =IF(D7=0, 0, 100*(F7 - D7*1.5)/(D7*1.5)) -> -0.2826087 | M7: =IF(D7=0, 0, 100*(G7 - D7*2)/(D7*2)) -> -0.85869565 | N7: =IF(D7=0, 0, 100*(H7 - D7*3.3)/(D7*3.3)) -> -0.34255599 | O7: =IF(D7=0, 0, 100*(I7 - D7*4)/(D7*4)) -> -0.67663043 | P7: =IF(D7=0, 0, 100*(J7 - D7*5)/(D7*5)) -> -0.66521739 | Q7: =IF(AND(K7>=0.11,K7<=0.27,L7>=-0.36,L7<=-0.22,M7>=-0.92,M7<=-0.82,N7>=-0.4,N7<=-0.3,O7>=-0.79,O7<=-0.64,P7>=-0.76,P7<=-0.61), "Yes", IF(AND(K7=0,L7=0,M7=0,N7=0,O7=0,P7=0), "Ready to test", "No")) -> Yes
K8: =IF(D8=0, 0, 100*(E8 - D8*1)/(D8*1)) -> 0 | L8: =IF(D8=0, 0, 100*(F8 - D8*1.5)/(D8*1.5)) -> 0 | M8: =IF(D8=0, 0, 100*(G8 - D8*2)/(D8*2)) -> 0 | N8: =IF(D8=0, 0, 100*(H8 - D8*3.3)/(D8*3.3)) -> 0 | O8: =IF(D8=0, 0, 100*(I8 - D8*4)/(D8*4)) -> 0 | P8: =IF(D8=0, 0, 100*(J8 - D8*5)/(D8*5)) -> 0 | Q8: =IF(AND(K8>=0.11,K8<=0.27,L8>=-0.36,L8<=-0.22,M8>=-0.92,M8<=-0.82,N8>=-0.4,N8<=-0.3,O8>=-0.79,O8<=-0.64,P8>=-0.76,P8<=-0.61), "Yes", IF(AND(K8=0,L8=0,M8=0,N8=0,O8=0,P8=0), "Ready to test", "No")) -> Ready to test
K9: =IF(D9=0, 0, 100*(E9 - D9*1)/(D9*1)) -> 0 | L9: =IF(D9=0, 0, 100*(F9 - D9*1.5)/(D9*1.5)) -> 0 | M9: =IF(D9=0, 0, 100*(G9 - D9*2)/(D9*2)) -> 0 | N9: =IF(D9=0, 0, 100*(H9 - D9*3.3)/(D9*3.3)) -> 0 | O9: =IF(D9=0, 0, 100*(I9 - D9*4)/(D9*4)) -> 0 | P9: =IF(D9=0, 0, 100*(J9 - D9*5)/(D9*5)) -> 0 | Q9: =IF(AND(K9>=0.11,K9<=0.27,L9>=-0.36,L9<=-0.22,M9>=-0.92,M9<=-0.82,N9>=-0.4,N9<=-0.3,O9>=-0.79,O9<=-0.64,P9>=-0.76,P9<=-0.61), "Yes", IF(AND(K9=0,L9=0,M9=0,N9=0,O9=0,P9=0), "Ready to test", "No")) -> Ready to test
K10: =IF(D10=0, 0, 100*(E10 - D10*1)/(D10*1)) -> 0 | L10: =IF(D10=0, 0, 100*(F10 - D10*1.5)/(D10*1.5)) -> 0 | M10: =IF(D10=0, 0, 100*(G10 - D10*2)/(D10*2)) -> 0 | N10: =IF(D10=0, 0, 100*(H10 - D10*3.3)/(D10*3.3)) -> 0 | O10: =IF(D10=0, 0, 100*(I10 - D10*4)/(D10*4)) -> 0 | P10: =IF(D10=0, 0, 100*(J10 - D10*5)/(D10*5)) -> 0 | Q10: =IF(AND(K10>=0.11,K10<=0.27,L10>=-0.36,L10<=-0.22,M10>=-0.92,M10<=-0.82,N10>=-0.4,N10<=-0.3,O10>=-0.79,O10<=-0.64,P10>=-0.76,P10<=-0.61), "Yes", IF(AND(K10=0,L10=0,M10=0,N10=0,O10=0,P10=0), "Ready to test", "No")) -> Ready to test
K11: =IF(D11=0, 0, 100*(E11 - D11*1)/(D11*1)) -> 0 | L11: =IF(D11=0, 0, 100*(F11 - D11*1.5)/(D11*1.5)) -> 0 | M11: =IF(D11=0, 0, 100*(G11 - D11*2)/(D11*2)) -> 0 | N11: =IF(D11=0, 0, 100*(H11 - D11*3.3)/(D11*3.3)) -> 0 | O11: =IF(D11=0, 0, 100*(I11 - D11*4)/(D11*4)) -> 0 | P11: =IF(D11=0, 0, 100*(J11 - D11*5)/(D11*5)) -> 0 | Q11: =IF(AND(K11>=0.11,K11<=0.27,L11>=-0.36,L11<=-0.22,M11>=-0.92,M11<=-0.82,N11>=-0.4,N11<=-0.3,O11>=-0.79,O11<=-0.64,P11>=-0.76,P11<=-0.61), "Yes", IF(AND(K11=0,L11=0,M11=0,N11=0,O11=0,P11=0), "Ready to test", "No")) -> Ready to test
K12: =IF(D12=0, 0, 100*(E12 - D12*1)/(D12*1)) -> 0 | L12: =IF(D12=0, 0, 100*(F12 - D12*1.5)/(D12*1.5)) -> 0 | M12: =IF(D12=0, 0, 100*(G12 - D12*2)/(D12*2)) -> 0 | N12: =IF(D12=0, 0, 100*(H12 - D12*3.3)/(D12*3.3)) -> 0 | O12: =IF(D12=0, 0, 100*(I12 - D12*4)/(D12*4)) -> 0 | P12: =IF(D12=0, 0, 100*(J12 - D12*5)/(D12*5)) -> 0 | Q12: =IF(AND(K12>=0.11,K12<=0.27,L12>=-0.36,L12<=-0.22,M12>=-0.92,M12<=-0.82,N12>=-0.4,N12<=-0.3,O12>=-0.79,O12<=-0.64,P12>=-0.76,P12<=-0.61), "Yes", IF(AND(K12=0,L12=0,M12=0,N12=0,O12=0,P12=0), "Ready to test", "No")) -> Ready to test
K13: =IF(D13=0, 0, 100*(E13 - D13*1)/(D13*1)) -> 0 | L13: =IF(D13=0, 0, 100*(F13 - D13*1.5)/(D13*1.5)) -> 0 | M13: =IF(D13=0, 0, 100*(G13 - D13*2)/(D13*2)) -> 0 | N13: =IF(D13=0, 0, 100*(H13 - D13*3.3)/(D13*3.3)) -> 0 | O13: =IF(D13=0, 0, 100*(I13 - D13*4)/(D13*4)) -> 0 | P13: =IF(D13=0, 0, 100*(J13 - D13*5)/(D13*5)) -> 0 | Q13: =IF(AND(K13>=0.11,K13<=0.27,L13>=-0.36,L13<=-0.22,M13>=-0.92,M13<=-0.82,N13>=-0.4,N13<=-0.3,O13>=-0.79,O13<=-0.64,P13>=-0.76,P13<=-0.61), "Yes", IF(AND(K13=0,L13=0,M13=0,N13=0,O13=0,P13=0), "Ready to test", "No")) -> Ready to test
K14: =IF(D14=0, 0, 100*(E14 - D14*1)/(D14*1)) -> 0 | L14: =IF(D14=0, 0, 100*(F14 - D14*1.5)/(D14*1.5)) -> 0 | M14: =IF(D14=0, 0, 100*(G14 - D14*2)/(D14*2)) -> 0 | N14: =IF(D14=0, 0, 100*(H14 - D14*3.3)/(D14*3.3)) -> 0 | O14: =IF(D14=0, 0, 100*(I14 - D14*4)/(D14*4)) -> 0 | P14: =IF(D14=0, 0, 100*(J14 - D14*5)/(D14*5)) -> 0 | Q14: =IF(AND(K14>=0.11,K14<=0.27,L14>=-0.36,L14<=-0.22,M14>=-0.92,M14<=-0.82,N14>=-0.4,N14<=-0.3,O14>=-0.79,O14<=-0.64,P14>=-0.76,P14<=-0.61), "Yes", IF(AND(K14=0,L14=0,M14=0,N14=0,O14=0,P14=0), "Ready to test", "No")) -> Ready to test
K15: =IF(D15=0, 0, 100*(E15 - D15*1)/(D15*1)) -> 0 | L15: =IF(D15=0, 0, 100*(F15 - D15*1.5)/(D15*1.5)) -> 0 | M15: =IF(D15=0, 0, 100*(G15 - D15*2)/(D15*2)) -> 0 | N15: =IF(D15=0, 0, 100*(H15 - D15*3.3)/(D15*3.3)) -> 0 | O15: =IF(D15=0, 0, 100*(I15 - D15*4)/(D15*4)) -> 0 | P15: =IF(D15=0, 0, 100*(J15 - D15*5)/(D15*5)) -> 0 | Q15: =IF(AND(K15>=0.11,K15<=0.27,L15>=-0.36,L15<=-0.22,M15>=-0.92,M15<=-0.82,N15>=-0.4,N15<=-0.3,O15>=-0.79,O15<=-0.64,P15>=-0.76,P15<=-0.61), "Yes", IF(AND(K15=0,L15=0,M15=0,N15=0,O15=0,P15=0), "Ready to test", "No")) -> Ready to test
