Workbook

Sheet 1. Summary
B1: Gen3 I Gen3 | C1: Gen2 I Gen3 | D1: Gen3 I Gen2 | E1: Gen2 I Gen2 | F1: Accelerated | G1: H2-FOAM | H1: LC-H2 | I1: H2-Electrode | J1: MLF | K1: Sulfidized | L1: Substrate test | M1: H2-SAF | N1: Production R&D | O1: Long-term test | P1: H2-Giga | Q1: Other
A2: Overall testing time [h] | B2: =SUM('Gen3-Gen3 '!E2:E1048576) -> 34039.25 | C2: =SUM('Gen2-Gen3Ano'!E2:E1048576) -> 29073.64 | D2: =SUM('Gen3Cat-Gen2'!E2:E1048576) -> 27253.322 | E2: =SUM('Gen2-Gen2'!E2:E1048576) -> 29513.72 | F2: =SUM(Accelerated!E2:E1048576) -> 2367 | G2: =SUM('H2-FOAM'!E2:E1048576) -> 2338.5 | H2: =SUM('LC-H2'!E2:E1048576) -> 4960 | I2: =SUM('H2-Electrode'!E2:E1048576) -> 4765.5 | J2: =SUM(MLF!E2:E1048576) -> 1587 | K2: =SUM(Sulfidized!E2:E1048576) -> 36873 | L2: =SUM('Substrate tests'!E2:E1048576) -> 3872 | M2: =SUM('H2-SAF'!E2:E1048576) -> 9822 | N2: =SUM('Production R&D'!E2:E1048576) -> 61488.5 | O2: =SUM('Long term testing'!E2:E1048576)+O4 -> 85948 | P2: =SUM('H2-Giga'!E2:E131) -> 1680 | Q2: =SUM(Other!E2:E10000) -> 5784
A3: Number of IC's | B3: =COUNTA('Gen3-Gen3 '!A2:A1048576) -> 66 | C3: =COUNTA('Gen2-Gen3Ano'!A2:A1048576) -> 433 | D3: {=COUNTA('Gen3Cat-Gen2'!A2:A1048576)} -> 399 | E3: =COUNTA('Gen2-Gen2'!A2:A1048576) -> 153 | F3: =COUNTA(Accelerated!A2:A1048576) -> 11 | G3: =COUNTA('H2-FOAM'!A2:A1048576) -> 61 | H3: =COUNTA('LC-H2'!A2:A1048576) -> 57 | I3: =COUNTA('H2-Electrode'!A2:A1048576) -> 45 | J3: =COUNTA(MLF!A2:A1048576) -> 4 | K3: =COUNTA(Sulfidized!A2:A1048576) -> 108 | L3: =COUNTA('Substrate tests'!A2:A1048576) -> 22 | M3: =COUNTA('H2-SAF'!A2:A1048576) -> 62 | N3: =COUNTA('Production R&D'!A2:A1048576) -> 296 | O3: =COUNTA('Long term testing'!A2:A1048576) -> 48 | P3: =COUNTA('H2-Giga'!A2:A1048576) -> 10 | Q3: =COUNTA(Other!A2:A1048576) -> 21
A4: Still running tests cummulated length [h]
B6: Total testing time [h] | C6: Number of IC's
A7: Live counter | B7: =SUM(B2:Q2) -> 341365.43 | C7: =SUM(B3:Q3) -> 1796
A9: First registered IC_ID in the new system | B9: IC0058_CatPNF_AnoPNF_T90_rho1287_AUX1Cat_AUX2Ano_3-7
A10: Introduction date of the new IC_ID system | B10: 45539
A12: Scoreboard
A13: Date | B13: Days elapsed since ID introduction | C13: Total testing time [h] | D13: Number of IC's
A14: 45659 | B14: =A14-$B$10 -> 120 | C14: - | D14: =219-58 -> 161
A15: 45952 | B15: =A15-$B$10 -> 413 | C15: 203517 | D15: 979
A16: 45964 | B16: =A16-$B$10 -> 425 | C16: 207284.49 | D16: 1004
A17: 46029 | B17: =A17-$B$10 -> 490 | C17: 238051.49 | D17: 1175
A18: 46085 | B18: =A18-$B$10 -> 546 | C18: 291178.95 | D18: 1540
A19: 46163 | B19: =A19-$B$10 -> 624 | C19: 344716.93 | D19: 1723

Sheet Gen2-Gen2
A1: IC_ID | B1: Owner | C1: Assembled by | D1: Disassembled by | E1: Test length [h] | F1: Protocol | G1: Format | H1: Experiment finished on | I1: Notes | J1: Archived in | K1: Plot
A2: IC0132_CatNNF_AnoNNF_rho1287_AUX1Cat_AUX2Ano_3-3 | B2: Balázs | E2: 182 | F2: QC_IC_168h | H2: 31/10/2024 | J2: Production #2 | K2: IC0132_CatNNF_AnoNNF_rho1287_AUX1Cat_AUX2Ano_3-3.png
A3: IC0130_CatNNF_AnoNNF_rho1287_AUX1Cat_AUX2Ano_1-3 | B3: Balázs | E3: 172 | F3: QC_IC_168h | H3: 31/10/2024 | K3: IC0130_CatNNF_AnoNNF_rho1287_AUX1Cat_AUX2Ano_1-3.png
A4: IC0134_CatNNF_AnoNNF_rho1287_AUX1Cat_AUX2Ano_1-8 | B4: Balázs | E4: 171 | F4: QC_IC_168h_v1 | H4: 45393 | I4: It stopped alone while doing a polarization curve and the water level was too low when disassembling it - BUT fitting for baseline | K4: IC0134_CatNNF_AnoNNF_rho1287_AUX1Cat_AUX2Ano_1-8.png
A5: IC0146_CatNNF_AnoNNF_rho1287_AUX1Cat_AUX2Ano_1-3 | B5: Balázs | E5: 60 | F5: QC_IC_168h_v1 | G5: Both | H5: 45454 | I5: Missing data :( | J5: Production #2 | K5: IC0146_CatNNF_AnoNNF_rho1287_AUX1Cat_AUX2Ano_1-3.png
A6: IC0067_CatNF_AnoNF_oldprocedure_T90_rho1287_AUX1Cat_AUX2Ano_3-4 | B6: Balázs | E6: 1144 | F6: 0_ImmersionCellStandardProcedure_DN | G6: Both | H6: 45544 | I6: Too low potential - 1,8V: not fitting for baseline | J6: Production #1 | K6: IC0067_CatNF_AnoNF_oldprocedure_T90_rho1287_AUX1Cat_AUX2Ano_3-4.png
A7: IC0068_CatNF_AnoNF_oldprocedure_T90_rho1287_AUX1Cat_AUX2Ano_3-1 | B7: Balázs | E7: 1005 | F7: 0_ImmersionCellStandardProcedure_DN | G7: Both | H7: 45391 | I7: Dropping temperature: not fitting for baseline | K7: IC0068_CatNF_AnoNF_oldprocedure_T90_rho1287_AUX1Cat_AUX2Ano_3-1.png
A8: IC0070_CatNF_AnoNF_newQC_T90_rho1287_AUX1Ano_AUX2Cat_2-3 | B8: Balázs | E8: 1002 | F8: QC_IC_1000h | G8: Both | H8: 45544 | J8: Production #1 | K8: IC0070_CatNF_AnoNF_newQC_T90_rho1287_AUX1Ano_AUX2Cat_2-3.png
A9: IC0071_CatNF_AnoNF_newQC_T90_rho1287_AUX1Ano_AUX2Cat_2-4 | B9: Balázs | E9: 1002 | F9: QC_IC_1000h | G9: Both | H9: 45544 | J9: Production #1 | K9: IC0071_CatNF_AnoNF_newQC_T90_rho1287_AUX1Ano_AUX2Cat_2-4.png
A10: IC0072_CatNF_AnoNF_oldprocedure_T90_rho1287_AUX1Ano_AUX2Cat_2-1 | B10: Balázs | E10: 1009 | F10: 0_ImmersionCellStandardProcedure_DN | G10: Both | H10: 45605 | J10: Production #1 | K10: IC0072_CatNF_AnoNF_oldprocedure_T90_rho1287_AUX1Ano_AUX2Cat_2-1.png
A11: IC0073_CatNF_AnoNF_newQC_T90_rho1287_AUX1Ano_AUX2Cat_2-2 | B11: Balázs | E11: 1002 | F11: QC_IC_1000h | G11: Both | H11: 45574 | I11: Irregular temperature - do not use for baseline | J11: Production #1 | K11: IC0073_CatNF_AnoNF_newQC_T90_rho1287_AUX1Ano_AUX2Cat_2-2.png
A12: IC0075_CatNF_AnoNF_T90_rho1287_AUX1Ano_AUX2Cat_Mn_inpurity1_1-6 | B12: Anders | E12: 168 | F12: QC_IC_168h | G12: Regular | H12: 16/8/2024 | K12: IC0075_CatNF_AnoNF_T90_rho1287_AUX1Ano_AUX2Cat_Mn_inpurity1_1-6.png
A13: IC0076_CatNF_AnoNF_T90_rho1287_AUX1Ano_AUX2Cat_Mn_inpurity2_1-7 | B13: Anders | E13: 168 | F13: QC_IC_168h | G13: Regular | H13: 16/8/2024 | K13: IC0076_CatNF_AnoNF_T90_rho1287_AUX1Ano_AUX2Cat_Mn_inpurity2_1-7.png
A14: IC0077_CatNF_AnoNF_T90_rho1287_AUX1Ano_AUX2Cat_Mn_inpurity3_1-8 | B14: Anders | E14: 168 | F14: QC_IC_168h | G14: Regular | H14: 16/8/2024 | K14: IC0077_CatNF_AnoNF_T90_rho1287_AUX1Ano_AUX2Cat_Mn_inpurity3_1-8.png
A15: IC0025_CatNNFsesojab_AnoNNF_T90_rho1287_AUX1Cat_AUX2Ano | B15: Soffi | E15: missing | F15: 0_ImmersionCellStandardProcedure_DN | I15: super old measurement, with only anode type foam ONLY the first 90 hours were recorded! | K15: IC0025_CatNNFsesojab_AnoNNF_T90_rho1287_AUX1Cat_AUX2Ano.png
A16: IC0170_CatNNF_AnoNNF_rho1287_AUX1Cat_AUX2_Ano_3-3 | B16: Balázs | E16: 168 | F16: QC_IC_168h | G16: Both | H16: 28/11/2024 | I16: 1 of the 5 NNF samples from the same piece of anode and cathode | J16: Production #2 | K16: IC0170_CatNNF_AnoNNF_rho1287_AUX1Cat_AUX2_Ano_3-3.png
A17: IC0181_CatNNF_AnoNNF_rho1287_AUX1Cat_AUX2Ano_1-6 | B17: Balázs | E17: 168 | F17: QC_IC_168h | G17: Both | H17: 45394 | I17: 1 of the 5 NNF samples from the same piece of anode and cathode | K17: IC0181_CatNNF_AnoNNF_rho1287_AUX1Cat_AUX2Ano_1-6.png
A18: IC0182_CatNNF_AnoNNF_T90_rho1287_AUX1Cat_AUX2Ano_2-5 | B18: Balázs | E18: 168 | F18: QC_IC_168h | G18: Both | H18: 45424 | I18: 1 of the 5 NNF samples from the same piece of anode and cathode | J18: Production #2 | K18: IC0182_CatNNF_AnoNNF_T90_rho1287_AUX1Cat_AUX2Ano_2-5.png
A19: IC0183_CatNNF_AnoNNF_T90_rho1287_AUX1Cat_AUX2Ano_3-4 | B19: Balázs | E19: 168 | F19: QC_IC_168h | G19: Both | H19: 45424 | I19: 1 of the 5 NNF samples from the same piece of anode and cathode | J19: Production #2 | K19: IC0183_CatNNF_AnoNNF_T90_rho1287_AUX1Cat_AUX2Ano_3-4.png
A20: IC0184_CatNNF_AnoNNF_T90_rho1287_AUX1Cat_AUX2Ano_2-7 | B20: Balázs | E20: 168 | F20: QC_IC_168h | G20: Both | H20: 45424 | I20: 1 of the 5 NNF samples from the same piece of anode and cathode | J20: Production #2 | K20: IC0184_CatNNF_AnoNNF_T90_rho1287_AUX1Cat_AUX2Ano_2-7.png
A21: IC0136_CatNNF_AnoNNF_rho1287_AUX1Cat_AUX2Ano_1-5 | B21: Balázs | E21: 1024 | F21: 0_ImmersionCellStandardProcedure_DN | G21: Both | H21: 45577 | I21: old protocol baseline | J21: Production #2 | K21: IC0136_CatNNF_AnoNNF_rho1287_AUX1Cat_AUX2Ano_1-5.png
A22: IC0135_CatNNF_AnoNNF_rho1287_AUX1Cat_AUX2Ano_1-7 | B22: Balázs | E22: 1024 | F22: 0_ImmersionCellStandardProcedure_DN | G22: Both | H22: 45577 | I22: old protocol baseline | J22: Production #2 | K22: IC0135_CatNNF_AnoNNF_rho1287_AUX1Cat_AUX2Ano_1-7.png
A23: IC0205_CatNNF_AnoNNF_rho1287_AUX1Cat_AUX2Ano_2-4 | B23: Mario | E23: 168 | F23: QC_IC_168h | G23: Both | H23: 18/12/24 | I23: new protocol baseline (same piece) | J23: Production #2 | K23: IC0205_CatNNF_AnoNNF_rho1287_AUX1Cat_AUX2Ano_2-4.png
A24: IC0204_CatNNF_AnoNNF_rho1287_AUX1Cat_AUX2Ano_2-3 | B24: Mario | E24: 168 | F24: QC_IC_168h | G24: Both | H24: 18/12/24 | I24: new protocol baseline (same piece) | J24: Production #2 | K24: IC0204_CatNNF_AnoNNF_rho1287_AUX1Cat_AUX2Ano_2-3.png
A25: IC0206_CatNNF_AnoNNF_rho1287_AUX1Cat_AUX2Ano_2-1 | B25: Mario | E25: 168 | F25: QC_IC_168h | G25: Both | H25: 18/12/24 | I25: new protocol baseline, running at 2,5 V - do not use for baseline | J25: Production #2 | K25: IC0206_CatNNF_AnoNNF_rho1287_AUX1Cat_AUX2Ano_2-1.png
A26: IC0207_CatNNF_AnoNNF_rho1287_AUX1Cat_AUX2Ano_1-6 | B26: Balázs | E26: 168 | F26: QC_IC_168h | G26: Both | H26: 20/12/24 | I26: new protocol baseline (same piece) | J26: Production #2 | K26: IC0207_CatNNF_AnoNNF_rho1287_AUX1Cat_AUX2Ano_1-6.png
A27: IC0227_CatNNF_AnoNNF_rho1287_AUX1Cat_AUX2Ano_1-5 | B27: Balázs | E27: 168 | F27: QC_IC_168h | G27: Both | H27: 45664 | I27: new protocol baseline (same piece) | J27: Production #2 | K27: IC0227_CatNNF_AnoNNF_rho1287_AUX1Cat_AUX2Ano_1-5.png
A28: IC0225_CatNNF_AnoNNF_rho1287_AUX1Cat_AUX2Ano_2-1 | B28: Balázs | E28: 168 | F28: QC_IC_168h | G28: Both | H28: 45664 | I28: new protocol baseline (same piece) - battery tester problems at around 100 h - don't use | J28: Production #2
A29: IC0226_CatNNF_AnoNNF_rho1287_AUX1Cat_AUX2Ano_2-3 | B29: Balázs | E29: 168 | F29: QC_IC_168h | G29: Both | H29: 45664 | I29: new protocol baseline (same piece) - battery tester problems at around 100 h - don't use | J29: Production #2
A30: IC0242_CatNNF_AnoNNF_rho1287_AUX1Cat_AUX2Ano_2-1 | B30: Balázs | E30: 168 | F30: QC_IC_168h | G30: Both | H30: 16/1/2025 | I30: new protocol baseline (same piece) | J30: Production #2 | K30: IC0242_CatNNF_AnoNNF_rho1287_AUX1Cat_AUX2Ano_2-1.png
A31: IC0243_CatNNF_AnoNNF_rho1287_AUX1Cat_AUX2Ano_1-5 | B31: Balázs | E31: 168 | F31: QC_IC_168h | G31: Both | H31: 16/1/2025 | I31: new protocol baseline (same piece) | J31: Production #2 | K31: IC0243_CatNNF_AnoNNF_rho1287_AUX1Cat_AUX2Ano_1-5.png
A32: IC0253_CatNNF_AnoNNF_rho1287_AUX1Cat_AUX2Ano_new_58,5hours_protocol_tempconditioning_3-2 | B32: Balázs | E32: 58 | F32: QC_IC_58.5h_temp_cond_v1_TEST_PHASE | G32: Both | H32: 20/1/2025 | I32: new protocol baseline (same piece). New "Step file" | J32: Production #2 | K32: IC0253_CatNNF_AnoNNF_rho1287_AUX1Cat_AUX2Ano_new_58,5hours_protocol_tempconditioning_3-2.png
A33: IC0254_CatNNF_AnoNNF_rho1287_AUX1Cat_AUX2Ano_new_58,5hours_protocol_tempconditioning_3-4 | B33: Balázs | E33: 58 | F33: QC_IC_58.5h_temp_cond_v1_TEST_PHASE | G33: Both | H33: 20/1/2025 | I33: new protocol baseline (same piece). New "Step file" | J33: Production #2 | K33: IC0254_CatNNF_AnoNNF_rho1287_AUX1Cat_AUX2Ano_new_58,5hours_protocol_tempconditioning_3-4.png
A34: IC0258_CatNNF_AnoNNF_rho1287_AUX1Cat_AUX2Ano_new_58,5hours_protocol_tempconditioning_1-1 | B34: Balázs | E34: 58 | F34: QC_IC_58.5h_temp_cond_v1_TEST_PHASE | G34: Both | H34: 20/1/2025 | I34: SAME piece - 58.5-hour-measurement | J34: Production #2 | K34: IC0258_CatNNF_AnoNNF_rho1287_AUX1Cat_AUX2Ano_new_58,5hours_protocol_tempconditioning_1-1.png
A35: IC0259_CatNNF_AnoNNF_rho1287_AUX1Cat_AUX2Ano_new_58,5hours_protocol_tempconditioning_1-5 | B35: Balázs | E35: 58 | F35: QC_IC_58.5h_temp_cond_v1_TEST_PHASE | G35: Both | H35: 20/1/2025 | I35: SAME piece - 58.5-hour-measurement | J35: Production #2 | K35: IC0259_CatNNF_AnoNNF_rho1287_AUX1Cat_AUX2Ano_new_58,5hours_protocol_tempconditioning_1-5.png
A36: IC0260_CatNNF_AnoNNF_rho1287_AUX1Cat_AUX2Ano_new_58,5hours_protocol_tempconditioning_2-1 | B36: Balázs | E36: 58 | F36: QC_IC_58.5h_temp_cond_v1_TEST_PHASE | G36: Both | H36: 20/1/2025 | I36: SAME piece - 58.5-hour-measurement | J36: Production #2 | K36: IC0260_CatNNF_AnoNNF_rho1287_AUX1Cat_AUX2Ano_new_58,5hours_protocol_tempconditioning_2-1.png
A37: IC0208_CatNNF_AnoNNF_rho1287_AUX1Cat_AUX2Ano_1-7 | B37: Balázs | E37: 1091 | F37: 0_ImmersionCellStandardProcedure_DN | G37: Both | H37: 27/1/2025 | I37: SAME piece 2 (old procedure) | J37: Production #2 | K37: IC0208_CatNNF_AnoNNF_rho1287_AUX1Cat_AUX2Ano_1-7.png
A38: IC0209_CatNNF_AnoNNF_rho1287_AUX1Cat_AUX2Ano_1-8 | B38: Balázs | E38: 1091 | F38: 0_ImmersionCellStandardProcedure_DN | G38: Both | H38: 45684 | I38: SAME piece 2 (old procedure) | J38: Production #2 | K38: IC0209_CatNNF_AnoNNF_rho1287_AUX1Cat_AUX2Ano_1-8.png
A39: IC0273_CatNNF_AnoNNF_rho1287_AUX1Cat_AUX2Ano_58,5hours_tempconditioning_12hours_3-5 | B39: Balázs | E39: 70 | F39: QC_IC_58.5h_temp_cond_v1_TEST_PHASE_12_hours | G39: Both | H39: 45691 | I39: SAME piece - 58.5-hour-measurement | J39: Production #2 | K39: IC0273_CatNNF_AnoNNF_rho1287_AUX1Cat_AUX2Ano_58,5hours_tempconditioning_12hours_3-5.png
A40: IC0274_CatNNF_AnoNNF_rho1287_AUX1Cat_AUX2Ano_58,5hours_tempconditioning_12hours_3-6 | B40: Balázs | E40: 70 | F40: QC_IC_58.5h_temp_cond_v1_TEST_PHASE_12_hours | G40: Both | H40: 45691 | I40: SAME piece - 58.5-hour-measurement | J40: Production #2 | K40: IC0274_CatNNF_AnoNNF_rho1287_AUX1Cat_AUX2Ano_58,5hours_tempconditioning_12hours_3-6.png
...

Sheet Gen3-Gen3 
A1: IC_ID | B1: Owner | C1: Assembled by | D1: Disassembled by | E1: Test length [h] | F1: Protocol | G1: Format | H1: Experiment finished on | I1: Notes | J1: Archived in | K1: Plot
A2: IC0057_CatPNF_AnoPNF_T90_rho1287_AUX1Cat_AUX2Ano_3-6 | B2: Balázs | E2: 2605 | F2: 0_ImmersionCellStandardProcedure_DN | G2: Both | H2: 24/08/2024 | J2: Production #1 | K2: IC0057_CatPNF_AnoPNF_T90_rho1287_AUX1Cat_AUX2Ano_3-6.png
A3: IC0057_CatPNF_AnoPNF_T90_rho1287_AUX1Cat_AUX2Ano_restart_3-6 | B3: Balázs | E3: 180 | F3: 0_ImmersionCellStandardProcedure_DN | G3: Both | H3: 12/09/2024 | K3: IC0057_CatPNF_AnoPNF_T90_rho1287_AUX1Cat_AUX2Ano_restart_3-6.png
A4: IC0058_CatPNF_AnoPNF_T90_rho1287_AUX1Cat_AUX2Ano_3-7 | B4: Balázs | E4: 2605 | F4: 0_ImmersionCellStandardProcedure_DN | G4: Both | H4: 24/08/2024 | J4: Production #1 | K4: IC0058_CatPNF_AnoPNF_T90_rho1287_AUX1Cat_AUX2Ano_3-7.png
A5: IC0058_CatPNF_AnoPNF_T90_rho1287_AUX1Cat_AUX2Ano_restart_3-7 | B5: Balázs | E5: 189 | F5: 0_ImmersionCellStandardProcedure_DN | G5: Both | H5: 12/09/2024 | K5: IC0058_CatPNF_AnoPNF_T90_rho1287_AUX1Cat_AUX2Ano_restart_3-7.png
A6: IC0059_CatPNF_AnoPNF_T90_rho1287_AUX1Cat_AUX2Ano_3-8 | B6: Balázs | E6: 2605 | F6: 0_ImmersionCellStandardProcedure_DN | G6: Both | H6: 24/08/2024 | J6: Production #1 | K6: IC0059_CatPNF_AnoPNF_T90_rho1287_AUX1Cat_AUX2Ano_3-8.png
A7: IC0059_CatPNF_AnoPNF_T90_rho1287_AUX1Cat_AUX2Ano_restart_3-8 | B7: Balázs | E7: 189 | F7: 0_ImmersionCellStandardProcedure_DN | G7: Both | H7: 45635 | K7: IC0059_CatPNF_AnoPNF_T90_rho1287_AUX1Cat_AUX2Ano_restart_3-8.png
A8: IC0060_CatA001385_AnoA001385_T90_rho1287_AUX1Cat_AUX2Ano_3-5 | B8: Balázs | E8: 1002 | F8: QC_IC_1000h | G8: Both | H8: 23/08/2024 | J8: Production #1 | K8: IC0060_CatA001385_AnoA001385_T90_rho1287_AUX1Cat_AUX2Ano_3-5.png
A9: IC0061_CatA001385_AnoA001385_T90_rho1287_AUX1Cat_AUX2Ano_2-8 | B9: Balázs | E9: 524 | F9: QC_IC_1000h | G9: Both | H9: 29/08/2024 | J9: Production #1 | K9: IC0061_CatA001385_AnoA001385_T90_rho1287_AUX1Cat_AUX2Ano_2-8.png
A10: IC0062_CatPNF_AnoPNF_T90_rho1287_AUX1Cat_AUX2Ano_1-3 | B10: Balázs | E10: 403 | F10: 0_ImmersionCellStandardProcedure_DN | G10: Regular | H10: 45479 | J10: Production #1 | K10: IC0062_CatPNF_AnoPNF_T90_rho1287_AUX1Cat_AUX2Ano_1-3.png
A11: IC0063_CatPNF_AnoPNF_T90_rho1287_AUX1Cat_AUX2Ano_1-5 | B11: Balázs | E11: 403 | F11: 0_ImmersionCellStandardProcedure_DN | G11: Regular | H11: 45479 | J11: Production #1 | K11: IC0063_CatPNF_AnoPNF_T90_rho1287_AUX1Cat_AUX2Ano_1-5.png
A12: IC0064_CatPNF_AnoPNF_T90_AUX1Ano_AUX2Cat_1-1 | B12: Balázs | E12: 646 | F12: QC_IC_1000h | G12: Regular | H12: 45481 | J12: Production #1 | K12: IC0064_CatPNF_AnoPNF_T90_AUX1Ano_AUX2Cat_1-1.png
A13: IC0065_CatPNF_AnoPNF_T90_rho1287_AUX1Cat_AUX2Ano_1-8 | B13: Balázs | E13: 381 | F13: Constant 0,8A? | G13: Regular | H13: 45479 | I13: Stored in two files, IC0065_..._1-8_1 continues just after IC0065_..._1-8 is finished (total time is the time of the two files) | J13: Production #1
A14: IC0066_CatPNF_AnoPNF_T90_rho1287_AUX1Cat_AUX2Ano_3-3 | B14: Balázs | E14: 382 | F14: 0_ImmersionCellStandardProcedure_DN | G14: Regular | H14: 13/06/2024 | I14: Stored also in two files, confusion in time, data loss in the middle (141 hours in the beginning can be used) | J14: Production #1 | K14: IC0066_CatPNF_AnoPNF_T90_rho1287_AUX1Cat_AUX2Ano_3-3.png
A15: IC0069_CatA1427_AnoA1950_T90_rho1287_AUX1Ano_AUX2Cat_2-7 | B15: Balázs | E15: 218 | F15: QC_IC_1000h | G15: Regular | H15: 45481 | J15: Production #1 | K15: IC0069_CatA1427_AnoA1950_T90_rho1287_AUX1Ano_AUX2Cat_2-7.png
A16: IC0074_Cat2243_Ano2454_T90_rho1287_AUX1Ano_AUX2Cat_1-5 | B16: Mario | E16: 1002 | F16: QC_IC_1000h | G16: Both | H16: 19/9/2024 | J16: Production #1 | K16: IC0074_Cat2243_Ano2454_T90_rho1287_AUX1Ano_AUX2Cat_1-5.png
A17: IC0078_Cat2516_Ano2516_T90_rho1287_AUX1Ano_AUX2Cat_1-2 | B17: Balázs | E17: 884 | F17: QC_IC_1000h | G17: Both | H17: 19/9/2024 | I17: Bad batch/patches on the electrode | J17: Production #1 | K17: IC0078_Cat2516_Ano2516_T90_rho1287_AUX1Ano_AUX2Cat_1-2.png
A18: IC0084_CatA001022_AnoA002575_T90_rho1287_AUX1Cat_AUX2Ano_3-1 | B18: Filippo | E18: 131 | F18: QC_IC_1000h | G18: Both | H18: 11/09/2024 | J18: Production #1 | K18: IC0084_CatA001022_AnoA002575_T90_rho1287_AUX1Cat_AUX2Ano_3-1.png
A19: IC0087_Cat2875_Ano_2797_T90_rho1287_AUX1Ano_AUX2_Cat_2-3 - BAD | B19: Balázs | E19: 168 | F19: QC_IC_168h | G19: Both | H19: 17/09/2024 | J19: Production #1 | K19: IC0087_Cat2875_Ano_2797_T90_rho1287_AUX1Ano_AUX2_Cat_2-3 - BAD.png
A20: IC0088_Cat2800_Ano2500_T90_rho1287_AUX1Ano_AUX2_Cat_2-4 | B20: Balázs | E20: 168 | F20: QC_IC_168h | G20: Both | H20: 17/09/2024 | J20: Production #1 | K20: IC0088_Cat2800_Ano2500_T90_rho1287_AUX1Ano_AUX2_Cat_2-4.png
A21: IC0089_Cat2218_Ano_2403_T90_rho1287_AUX1Ano_AUX2_Cat_2-8 | B21: Balázs | E21: 168 | F21: QC_IC_168h | G21: Both | H21: 17/09/2024 | I21: Stopped by voltage peak | J21: Production #1 | K21: IC0089_Cat2218_Ano_2403_T90_rho1287_AUX1Ano_AUX2_Cat_2-8.png
A22: IC0095_Cat2850_Ano_2550_T90_rho1287_AUX1Ano_AUX2_Cat_3-6 | B22: Balázs | E22: 168 | F22: QC_IC_168h | G22: Both | H22: 22/09/2024 | I22: do not use | J22: Production #1 | K22: IC0095_Cat2850_Ano_2550_T90_rho1287_AUX1Ano_AUX2_Cat_3-6.png
A23: IC0096_Cat2835_Ano_2525_T90_rho1287_AUX1Ano_AUX2_Cat_3-5 | B23: Balázs | E23: 168 | F23: QC_IC_168h | G23: Both | H23: 24/09/2024 | J23: Production #1 | K23: IC0096_Cat2835_Ano_2525_T90_rho1287_AUX1Ano_AUX2_Cat_3-5.png
A24: IC0097_Cat2904_Ano_2525_T90_rho1287_AUX1Ano_AUX2_Cat_3-3 | B24: Mario | E24: 168 | F24: QC_IC_168h | G24: Both | H24: 23/09/2024 | J24: Production #1 | K24: IC0097_Cat2904_Ano_2525_T90_rho1287_AUX1Ano_AUX2_Cat_3-3.png
A25: IC0098_Cat2903_Ano_2525_T90_rho1287_AUX1Ano_AUX2_Cat_3-1 | B25: Mario | E25: 168 | F25: QC_IC_168h | G25: Both | H25: 23/09/2024 | I25: sylgard | J25: Production #1 | K25: IC0098_Cat2903_Ano_2525_T90_rho1287_AUX1Ano_AUX2_Cat_3-1.png
A26: IC0169_CatA2830_AnoA1577_rho1287_AUX1Cat_AUX2Ano_3-8 | B26: Mario | E26: 168 | F26: QC_IC_168h | G26: Both | H26: 28/11/2024 | I26: sylgard | J26: Production #2 | K26: IC0169_CatA2830_AnoA1577_rho1287_AUX1Cat_AUX2Ano_3-8.png
A27: IC0302_CatA3296_Ano_A2797_rho1276_AUX1Cat_AUX2Ano_PRECONDITIONED_PART1_70degKOH_2-3 | B27: Balázs | C27: Gergo | D27: Gergo | E27: 72 | F27: Preconditioning_1st_part | G27: Both | H27: 45705 | I27: Preconditioned sample (15% KOH), made with preheated KOH (70deg). Thermoreg. first adjusted to 80, then to 90deg! | K27: IC0302_CatA3296_Ano_A2797_rho1276_AUX1Cat_AUX2Ano_PRECONDITIONED_PART1_70degKOH_2-3.png
A28: IC0304_CatA3306_AnoA3125_rho1276_AUX1Cat_AUX2Ano_PRECONDITIONED_PART1_3-5 | B28: Balázs | C28: Gergo | D28: Gergo | E28: 72 | F28: Preconditioning_1st_part | G28: Both | H28: 45705 | I28: Preconditioned sample (15% KOH), made with preheated KOH (70deg). Thermoreg. first adjusted to 80, then to 90deg! | K28: IC0304_CatA3306_AnoA3125_rho1276_AUX1Cat_AUX2Ano_PRECONDITIONED_PART1_3-5.png
A29: IC0306_CatA3298_AnoA3200_rho1276_AUX1Cat_AUX2Ano_PRECONDITIONED_PART1_3-7 | B29: Balázs | C29: Gergo | D29: Gergo | E29: 72 | F29: Preconditioning_1st_part | G29: Both | H29: 45705 | I29: Preconditioned sample (15% KOH), made with preheated KOH (70deg). Thermoreg. first adjusted to 80, then to 90deg! | K29: IC0306_CatA3298_AnoA3200_rho1276_AUX1Cat_AUX2Ano_PRECONDITIONED_PART1_3-7.png
A30: IC0316_CatA3306_AnoA3125_rho1276_AUX1Cat_AUX2Ano_PRECONDITIONED_PART2_3-5 | B30: Balázs | C30: Gergo | D30: Julie | E30: 13.5 | F30: Preconditioning_2nd_part | G30: Both | H30: 45706 | I30: Preconditioned sample (15% KOH), made with preheated KOH (70deg). Thermoreg. first adjusted to 80, then to 90deg! | K30: IC0316_CatA3306_AnoA3125_rho1276_AUX1Cat_AUX2Ano_PRECONDITIONED_PART2_3-5.png
A31: IC0305_CatA3298_AnoA3200_rho1276_AUX1Cat_AUX2Ano_3-6 | B31: Balázs | C31: Gergo | D31: Julie | E31: 79.5 | F31: No Preconditioning_72h+polcurve | G31: Both | H31: 45706 | I31: NO preconditioning! Made with preheated KOH (70deg). Thermoreg. first adjusted to 80, then to 90deg! | K31: IC0305_CatA3298_AnoA3200_rho1276_AUX1Cat_AUX2Ano_3-6.png
A32: IC0317_CatA3298_AnoA3200_rho1276_AUX1Cat_AUX2Ano_PRECONDITIONED_PART2_3-7 | B32: Balázs | C32: Gergo | D32: Julie | E32: 13.5 | F32: Preconditioning_2nd_part | G32: Both | H32: 45706 | I32: Preconditioned sample (15% KOH), made with preheated KOH (70deg). Thermoreg. first adjusted to 80, then to 90deg! | K32: IC0317_CatA3298_AnoA3200_rho1276_AUX1Cat_AUX2Ano_PRECONDITIONED_PART2_3-7.png
A33: IC0301_CatA3296_AnoA2797_rho1276_AUX1Cat_AUX2Ano_3-8 | B33: Balázs | C33: Gergo | D33: Julie | E33: 79.5 | F33: No Preconditioning_72h+polcurve | G33: Both | H33: 45706 | I33: NO preconditioning! Made with preheated KOH (70deg). Thermoreg. first adjusted to 80, then to 90deg! | K33: IC0301_CatA3296_AnoA2797_rho1276_AUX1Cat_AUX2Ano_3-8.png
A34: IC0315_CatA3296_Ano_A2797_rho1276_AUX1Cat_AUX2Ano_PRECONDITIONED_PART2_70degKOH_2-3 | B34: Balázs | C34: Gergo | D34: Julie | E34: 13.5 | F34: Preconditioning_2nd_part | G34: Both | H34: 45706 | I34: Preconditioned sample (15% KOH), made with preheated KOH (70deg). Thermoreg. first adjusted to 80, then to 90deg! | K34: IC0315_CatA3296_Ano_A2797_rho1276_AUX1Cat_AUX2Ano_PRECONDITIONED_PART2_70degKOH_2-3.png
A35: IC0303_CatA3306_AnoA3125_rho1276_AUX1Cat_AUX2Ano_2-4 | B35: Balázs | C35: Gergo | D35: Julie | E35: 79.5 | F35: No Preconditioning_72h+polcurve | G35: Both | H35: 45706 | I35: NO preconditioning! Made with preheated KOH (70deg). Thermoreg. first adjusted to 80, then to 90deg! | K35: IC0303_CatA3306_AnoA3125_rho1276_AUX1Cat_AUX2Ano_2-4.png
A36: IC0323_CatA3298_AnoA3200_rho1276_AUX1Cat_AUX2Ano_PRECOND-v2-Part1_3-5 | B36: Balázs | C36: Gergo | D36: Gergo | E36: 72 | F36: Preconditioning_1st_part_v2 | G36: Both | H36: 45712 | I36: Preconditioned (v2 - Part 1) sample with preheated (80deg) 15% KOH. | K36: IC0323_CatA3298_AnoA3200_rho1276_AUX1Cat_AUX2Ano_PRECOND-v2-Part1_3-5.png
A37: IC0324_CatA3306_AnoA3125_rho1276_AUX1Cat_AUX2Ano_PRECOND-v2-Part1_3-6 | B37: Balázs | C37: Gergo | D37: Gergo | E37: 72 | F37: Preconditioning_1st_part_v2 | G37: Both | H37: 45712 | I37: Preconditioned (v2 - Part 1) sample with preheated (80deg) 15% KOH. | K37: IC0324_CatA3306_AnoA3125_rho1276_AUX1Cat_AUX2Ano_PRECOND-v2-Part1_3-6.png
A38: IC0325_CatA3296_AnoA2797_rho1276_AUX1Cat_AUX2Ano_PRECOND-v2-Part1_3-7 | B38: Balázs | C38: Gergo | D38: Gergo | E38: 72 | F38: Preconditioning_1st_part_v2 | G38: Both | H38: 45712 | I38: Preconditioned (v2 - Part 1) sample with preheated (80deg) 15% KOH. | K38: IC0325_CatA3296_AnoA2797_rho1276_AUX1Cat_AUX2Ano_PRECOND-v2-Part1_3-7.png
A39: IC0340_CatA3298_AnoA3200_rho1276_AUX1Cat_AUX2Ano_PRECOND-v2-Part2_3-5 | B39: Balázs | C39: Gergo | D39: Gergo | E39: 79.5 | F39: Preconditioning_2nd_part_v2 | G39: Both | H39: 45716 | I39: Preconditioned (v2 - Part 2) sample with preheated (70deg) 30% KOH. | J39: Production #2 | K39: IC0340_CatA3298_AnoA3200_rho1276_AUX1Cat_AUX2Ano_PRECOND-v2-Part2_3-5.png
A40: IC0341_CatA3306_AnoA3125_rho1276_AUX1Cat_AUX2Ano_PRECOND-v2-Part2_3-6 | B40: Balázs | C40: Gergo | D40: Gergo | E40: 79.5 | F40: Preconditioning_2nd_part_v2 | G40: Both | H40: 45716 | I40: Preconditioned (v2 - Part 2) sample with preheated (70deg) 30% KOH. | J40: Production #2 | K40: IC0341_CatA3306_AnoA3125_rho1276_AUX1Cat_AUX2Ano_PRECOND-v2-Part2_3-6.png
...

Sheet Gen2-Gen3Ano
A1: IC_ID | B1: Owner | C1: Assembled by | D1: Disassembled by | E1: Test length [h] | F1: Protocol | G1: Format | H1: Experiment finished on | I1: Notes | J1: Archived in | K1: Plot
A2: IC0100_CatNNF_Ano_A2797_T90_rho1287_AUX1Ano_AUX2_Cat_3-8 | B2: Balázs | E2: 168 | F2: QC_IC_168h | G2: Both | H2: 29/09/2024 | I2: Sample is taken from the dark spot. | J2: Production #1 | K2: IC0100_CatNNF_Ano_A2797_T90_rho1287_AUX1Ano_AUX2_Cat_3-8.png
A3: IC0101_CatNNF_Ano_2378_T90_rho1287_AUX1Ano_AUX2_Cat_2-8 | B3: Balázs | E3: 168 | F3: QC_IC_168h | G3: Both | I3: Sample is taken from the dark spot. Temperature is not measured after app. 50 hours. | J3: Production #1 | K3: IC0101_CatNNF_Ano_2378_T90_rho1287_AUX1Ano_AUX2_Cat_2-8.png
A4: IC0102_CatNNF_Ano2797_T90_rho1287_AUX1Ano_AUX2_Cat_2-4 | B4: Balázs | E4: 168 | F4: QC_IC_168h | G4: Both | I4: Sample is taken from the bright spot. | J4: Production #1 | K4: IC0102_CatNNF_Ano2797_T90_rho1287_AUX1Ano_AUX2_Cat_2-4.png
A5: IC0104_CatNNF_Ano2378_T90_rho1287_AUX1Ano_AUX2_Cat_3-6 | B5: Balázs | E5: 168 | F5: QC_IC_168h | G5: Both | I5: Sample is taken from the bright spot. | J5: Production #1 | K5: IC0104_CatNNF_Ano2378_T90_rho1287_AUX1Ano_AUX2_Cat_3-6.png
A6: IC0140_CatNNF_AnoA003050_T90_rho1287_AUX1NaN_AUX2NaN_3-7 | B6: Balázs | E6: 168 | F6: QC_IC_168h | G6: Both | I6: Sudden voltage drop between 20 and 48 hours. - do not use | J6: Production #2 | K6: IC0140_CatNNF_AnoA003050_T90_rho1287_AUX1NaN_AUX2NaN_3-7.png
A7: IC0141_CatNNF_AnoA003025_rho1287_AUX1Cat_AUX2Ano_3-6 | B7: Balázs | E7: 168 | F7: QC_IC_168h | G7: Both | I7: Fluctuating temperature - do not use | J7: Production #2 | K7: IC0141_CatNNF_AnoA003025_rho1287_AUX1Cat_AUX2Ano_3-6.png
A8: IC0142_CatNNF_AnoA003000_T90_rho1287_AUX1NaN_AUX2NaN_3-8 | B8: Balázs | E8: 168 | F8: QC_IC_168h | G8: Both | I8: Fluctuating temperature - do not use | J8: Production #2 | K8: IC0142_CatNNF_AnoA003000_T90_rho1287_AUX1NaN_AUX2NaN_3-8.png
A9: IC0161_CatNNF_Ano1577_T90_rho1287_AUX1Cat_AUX2Ano_2-4 | B9: Balázs | E9: 168 | F9: QC_IC_168h | G9: Both | H9: 45617 | J9: Production #2 | K9: IC0161_CatNNF_Ano1577_T90_rho1287_AUX1Cat_AUX2Ano_2-4.png
A10: IC0175_CatNNF_Ano3200_T90_rho1287_AUX1Cat_AUX2Ano_2-1 | B10: Mario | E10: 168 | F10: QC_IC_168h | G10: Both | H10: 45625 | J10: Production #2 | K10: IC0175_CatNNF_Ano3200_T90_rho1287_AUX1Cat_AUX2Ano_2-1.png
A11: IC0173_CatNNF_AnoA3125_T90_rho1287_AUX1Cat_AUX2Ano_3-6 | B11: Mario | E11: 168 | F11: QC_IC_168h | G11: Both | H11: 45625 | J11: Production #2 | K11: IC0173_CatNNF_AnoA3125_T90_rho1287_AUX1Cat_AUX2Ano_3-6.png
A12: IC0186_CatNNF_Ano2279_T90_rho1287_AUX1Cat_AUX2Ano_3-8 | B12: Mario | E12: 168 | F12: QC_IC_168h | G12: Both | H12: 45455 | J12: Production #2 | K12: IC0186_CatNNF_Ano2279_T90_rho1287_AUX1Cat_AUX2Ano_3-8.png
A13: IC0185_CatNNF_Ano3100_T90_rho1287_AUX1Cat_AUX2Ano_3-7 | B13: Mario | E13: 168 | F13: QC_IC_168h | G13: Both | H13: 45455 | J13: Production #2 | K13: IC0185_CatNNF_Ano3100_T90_rho1287_AUX1Cat_AUX2Ano_3-7.png
A14: IC0188_CatNNF_AnoA2423_T90_rho1287_AUX1Cat_AUX2Ano_3-6 | B14: Mario | E14: 168 | F14: QC_IC_168h | G14: Both | H14: 45547 | I14: Temperature is around 80 °C for 50 hours.-use it cautiously | J14: Production #2 | K14: IC0188_CatNNF_AnoA2423_T90_rho1287_AUX1Cat_AUX2Ano_3-6.png
A15: IC0234_CatNNF_AnoA001950_rho1287_AUX1Cat_AUX2Ano_3-6 | B15: Mario | E15: 168 | F15: QC_IC_168h | G15: Both | H15: 45670 | J15: Production #2 | K15: IC0234_CatNNF_AnoA001950_rho1287_AUX1Cat_AUX2Ano_3-6.png
A16: IC0233_CatNNF_AnoA002422_rho1287_AUX1Cat_AUX2Ano_3-5 | B16: Mario | E16: 168 | F16: QC_IC_168h | G16: Both | H16: 45670 | J16: Production #2 | K16: IC0233_CatNNF_AnoA002422_rho1287_AUX1Cat_AUX2Ano_3-5.png
A17: IC0468_CatNNF_AnoA3320_1of3_rho1276_AUX1Cat_AUX2Ano_5-1 | B17: Balázs | C17: Nerea | D17: Jesper | E17: 1000 | F17: _QC_IC_1000h_v1.xml | G17: Custom | H17: 45792 | I17: 1/3 EUROFIN | J17: Production #3 | K17: IC0468_CatNNF_AnoA3320_1of3_rho1276_AUX1Cat_AUX2Ano_5-1.png
A18: IC0470_CatNNF_AnoA3320_3of3_rho1276_AUX1Cat_AUX2Ano_5-2 | B18: Balázs | C18: Akos | D18: Jesper | E18: 1000 | F18: _QC_IC_1000h_v1.xml | G18: Custom | H18: 45792 | I18: 3/3 EUROFIN | J18: Production #3 | K18: IC0470_CatNNF_AnoA3320_3of3_rho1276_AUX1Cat_AUX2Ano_5-2.png
A19: IC0469_CatNNF_AnoA3320_2of3_rho1276_AUX1Cat_AUX2Ano_5-5 | B19: Balázs | C19: Akos | D19: Jesper | E19: 1000 | F19: _QC_IC_1000h_v1.xml | G19: Custom | H19: 45792 | I19: 2/EUROFIN | J19: Production #3 | K19: IC0469_CatNNF_AnoA3320_2of3_rho1276_AUX1Cat_AUX2Ano_5-5.png
A20: IC0675_CatNNF_AnoA003320-1_rho1279_AUX1NaN_AUX2NaN_4-1 | B20: Balázs | C20: Aleksandra | D20: Peter Hilt | E20: 168 | F20: QC_IC_168h | G20: Custom format | H20: 45825 | I20: Gen3 Anode A003320 (from bag 1), pretreated cathode, preheated KOH and beaker | J20: Production #3 | K20: IC0675_CatNNF_AnoA003320-1_rho1279_AUX1NaN_AUX2NaN_4-1.png
A21: IC0676_CatNNF_AnoA003320-2_rho1279_AUX1NaN_AUX2NaN_4-2 | B21: Balázs | C21: Aleksandra | D21: Peter Hilt | E21: 168 | F21: QC_IC_168h | G21: Custom format | H21: 45825 | I21: Gen3 Anode A003320 (from bag 2), pretreated cathode, preheated KOH and beaker | J21: Production #3 | K21: IC0676_CatNNF_AnoA003320-2_rho1279_AUX1NaN_AUX2NaN_4-2.png
A22: IC0677_CatNNF_AnoA003320-3_rho1279_AUX1NaN_AUX2NaN_4-6 | B22: Balázs | C22: Aleksandra | D22: Peter Hilt | E22: 168 | F22: QC_IC_168h | G22: Custom format | H22: 45825 | I22: Gen3 Anode A003320 (from bag 3), pretreated cathode, preheated KOH and beaker | J22: Production #3 | K22: IC0677_CatNNF_AnoA003320-3_rho1279_AUX1NaN_AUX2NaN_4-6.png
A23: IC0710_CatNNF_AnoB394-BL_rho1297_AUX1NaN_AUX2NaN_4-1 | B23: Balázs | C23: Gergo | D23: Akos/Daniel | E23: 168 | F23: QC_IC_168h | G23: Custom format | H23: 45841 | J23: Production #3
A24: IC0711_CatNNF_AnoB394-TL_rho1297_AUX1NaN_AUX2NaN_4-2 | B24: Balázs | C24: Gergo | D24: Akos/Daniel | E24: 168 | F24: QC_IC_168h | G24: Custom format | H24: 45841 | J24: Production #3
A25: IC0712_CatNNF_AnoB394-M_rho1297_AUX1NaN_AUX2NaN_4-3 | B25: Balázs | C25: Gergo | D25: Akos/Daniel | E25: 168 | F25: QC_IC_168h | G25: Custom format | H25: 45841 | J25: Production #3
A26: IC0713_CatNNF_AnoB394-BR_rho1297_AUX1NaN_AUX2NaN_4-4 | B26: Balázs | C26: Gergo | D26: Akos/Daniel | E26: 168 | F26: QC_IC_168h | G26: Custom format | H26: 45841 | J26: Production #3
A27: IC0714_CatNNF_AnoB394-TR_rho1297_AUX1NaN_AUX2NaN_4-5 | B27: Balázs | C27: Gergo | D27: Akos/Daniel | E27: 168 | F27: QC_IC_168h | G27: Custom format | H27: 45841 | J27: Production #3
A28: IC0719_CatNNF_AnoB456-BR_rho1297_AUX1NaN_AUX2NaN_4-6 | B28: Balázs | C28: Ola | D28: Oniel/Bardia | E28: 168 | F28: QC_IC_168h | G28: Custom format | H28: 45845 | I28: Low Right B456 anode | J28: Production #3
A29: IC0721_CatNNF_AnoB468-TR_rho1297_AUX1NaN_AUX2NaN_5-1 | B29: Balázs | C29: Peter | D29: Oniel/Bardia | E29: 168 | F29: QC_IC_168h | G29: Custom format | H29: 45845 | I29: Anode_Production_B468 | J29: Production #3
A30: IC0720_CatNNF_AnoB456-TR_rho1297_AUX1NaN_AUX2NaN_5-2 | B30: Balázs | C30: Carmine | D30: Oniel/Mohammadreza(Bardia) | E30: 168 | F30: QC_IC_168h | G30: Custom | H30: 45845 | I30: Anode_Production_QC_upper right, other one is lower right | J30: Production #3
A31: IC0722_CatNNF_AnoB463-TR_rho1297_AUX1NaN_AUX2NaN_5-5 | B31: Balázs | C31: Peter | D31: Oniel/Mohammadreza(Bardia) | E31: 168 | F31: QC_IC_168h | G31: Custom | H31: 45845 | I31: Anode_Production_QC_upper right, other one is lower right BUT taken from wrong position | J31: Production #3
A32: IC0724_CatNNF_AnoB463-TR_2_rho1279_AUX1NaN_AUX2NaN_5-7 | B32: Balázs | C32: Carmine | D32: Oniel/Mohammadreza(Bardia) | E32: 168 | F32: QC_IC_168h | G32: Custom format | H32: 45845 | I32: Position 2 (technically position 1 since the first cut was out the diagonal) | J32: Production #3
A33: IC0725_CatNNF_AnoB572-TR_rho1279_AUX1NaN_AUX2NaN_5-8 | B33: Balázs | C33: Carmine | D33: Oniel/Mohammadreza(Bardia) | E33: 168 | F33: QC_IC_168h | G33: Custom | H33: 45845 | I33: It was used as aged sample for degradation study in half cells | J33: Production #3
A34: IC0736_CatNNF_AnoB578-TL_rho1297_AUX1NaN_AUX2NaN_4-1 | B34: Balázs | C34: Akos | D34: Aleksandra/Oniel | E34: 168 | F34: QC_IC_168h | G34: Custom | H34: 45848 | I34: Abbreviations for "Production - Line 2" samples (depending on where they were cut from): BL - Bottom Left TL - Top Left BR - Bottom Right TR - Top Right M - Middle | J34: Production #3
A35: IC0741_CatNNF_AnoB394-BR_rho1279_AUX1NaN_AUX2NaN_5-6 | B35: Balázs | C35: Daniel | D35: Aleksandra/Oniel | E35: 168 | F35: QC_IC_168h | G35: Custom | H35: 45848 | I35: Mismatched brackets - Anode Side "1.8mm" | J35: Production #3
A36: IC0740_CatNNF_AnoB578-TR_rho1297_AUX1NaN_AUX2NaN_4-5 | B36: Balázs | C36: Akos | D36: Aleksandra/Oniel | E36: 168 | F36: QC_IC_168h | G36: Custom | H36: 45848 | I36: Sample consumed by coating thickness measurement. Mismatched brackets - Anode Side "1.8mm" | J36: Production #4
A37: IC0737_CatNNF_AnoB578-BL_rho1297_AUX1NaN_AUX2NaN_4-2 | B37: Balázs | C37: Daniel | D37: Aleksandra/Oniel | E37: 168 | F37: QC_IC_168h | G37: Custom | H37: 45848 | I37: Mismatched brackets - Anode Side "1.8mm" | J37: Production #3
A38: IC0738_CatNNF_AnoB578-M_rho1297_AUX1NaN_AUX2NaN_4-3 | B38: Balázs | C38: Daniel | D38: Aleksandra/Oniel | E38: 168 | F38: QC_IC_168h | G38: Custom | H38: 45848 | I38: Abbreviations for "Production - Line 2" samples (depending on where they were cut from): BL - Bottom Left TL - Top Left BR - Bottom Right TR - Top Right M - Middle | J38: Production #3
A39: IC0739_CatNNF_AnoB578-BR_rho1297_AUX1NaN_AUX2NaN_4-4 | B39: Balázs | C39: Akos | D39: Aleksandra/Oniel | E39: 168 | F39: QC_IC_168h | G39: Custom | H39: 45848 | I39: Abbreviations for "Production - Line 2" samples (depending on where they were cut from): BL - Bottom Left TL - Top Left BR - Bottom Right TR - Top Right M - Middle | J39: Production #4
A40: IC0757_CatNNF_AnoB572-TR_rho1279_AUX1NaN_AUX2NaN_4-1 | B40: Balázs | C40: Carmine | D40: Daniel | E40: 64 | F40: QC_IC_anode_64h_v1 | G40: Custom | H40: 45852 | J40: Production #3
...

Sheet Gen3Cat-Gen2
A1: IC_ID | B1: Owner | C1: Assembled by | D1: Disassembled by | E1: Test length [h] | F1: Protocol | G1: Format | H1: Experiment finished on | I1: Notes | J1: Arhived in | K1: Plot
A2: IC0079_Cat2125_AnoNF_T90_rho1287_AUX1Ano_AUX2_Cat_1-6 - GOOD | B2: Balázs | E2: 1000 | F2: QC_IC_1000h | G2: Format | H2: 45570 | I2: Irregular temp - do not use | J2: Production #1 | K2: IC0079_Cat2125_AnoNF_T90_rho1287_AUX1Ano_AUX2_Cat_1-6 - GOOD.png
A3: IC0080_Cat2243_AnoNF_T90_rho1287_AUX1Ano_AUX2_Cat_1-7 - GOOD | B3: Balázs | E3: 1000 | F3: QC_IC_1000h | G3: Both | H3: 45570 | I3: Irregular temp - do not use | J3: Production #1 | K3: IC0080_Cat2243_AnoNF_T90_rho1287_AUX1Ano_AUX2_Cat_1-7 - GOOD.png
A4: IC0081_Cat856_AnoNF_T90_rho1287_AUX1Ano_AUX2_Cat_1-8 - BAD | B4: Balázs | E4: 1000 | F4: QC_IC_1000h | G4: Both | H4: 45570 | I4: High temp - do not use Sample was taken from a BRIGHT spot,Another IC0081 exists in the sulfidized sheet | J4: Production #1 | K4: IC0081_Cat856_AnoNF_T90_rho1287_AUX1Ano_AUX2_Cat_1-8 - BAD.png
A5: IC0091_CatA002835_AnoNNF_T90_rho1287_AUX1Cat_AUX2Ano_2-1 | B5: Balázs | E5: 168 | F5: QC_IC_168h | G5: Both | H5: 19/09/2024 | J5: Production #1 | K5: IC0091_CatA002835_AnoNNF_T90_rho1287_AUX1Cat_AUX2Ano_2-1.png
A6: IC0093_Cat2901_AnoNNF_T90_rho1287_AUX1Ano_AUX2_Cat_3-8 | B6: Balázs | E6: 168 | F6: QC_IC_168h | G6: Both | H6: 21/09/2024 | I6: Sample was taken from a DARK spot | J6: Production #1 | K6: IC0093_Cat2901_AnoNNF_T90_rho1287_AUX1Ano_AUX2_Cat_3-8.png | R6: 0 voltage between 26.28 and 26.43 hours
A7: IC0094_Cat2902_AnoNNF_T90_rho1287_AUX1Ano_AUX2Cat_3-7 | B7: Balázs | E7: 168 | F7: QC_IC_168h | G7: Both | H7: 21/09/2024 | I7: Irregular temp - do not use Sample was considered to be GOOD. | J7: Production #1 | K7: IC0094_Cat2902_AnoNNF_T90_rho1287_AUX1Ano_AUX2Cat_3-7.png
A8: IC0099_Cat2904_Ano_NNF_T90_rho1287_AUX1Ano_AUX2_Cat_3-4 | B8: Mario | E8: 168 | F8: QC_IC_168h | G8: Both | I8: No data. Sample was considered to be GOOD. | J8: Production #1 | K8: NaN
A9: IC0103_Cat2904_AnoNNF_T90_rho1287_AUX1Ano_AUX2_Cat_2-3 | B9: Balázs | E9: 168 | F9: QC_IC_168h | G9: Both | I9: Sample was considered to be BAD. | J9: Production #1 | K9: IC0103_Cat2904_AnoNNF_T90_rho1287_AUX1Ano_AUX2_Cat_2-3.png
A10: IC0139_CatA002904_AnoNNF_T90_rho1287_AUX1NaN_AUX2NaN_3-4 | B10: Mario | E10: 168 | F10: QC_IC_168h | G10: Both | H10: 31/10/2024 | I10: Equals with IC0099 | J10: Production #1 | K10: IC0139_CatA002904_AnoNNF_T90_rho1287_AUX1NaN_AUX2NaN_3-4.png
A11: IC0153_CatA002741EDGE_AnoNNF_T90_rho1287_AUX1Cat_AUX2Ano_3-7 | B11: Mario | E11: 168 | F11: QC_IC_168h | G11: Both | H11: 19/11/2024 | I11: Sample was taken from the edge. | J11: Production #2 | K11: IC0153_CatA002741EDGE_AnoNNF_T90_rho1287_AUX1Cat_AUX2Ano_3-7.png
A12: IC0152_CatA002925_AnoNNF_T90_rho1287_AUX1Cat_AUX2Ano_3-8 | B12: Mario | E12: 168 | F12: QC_IC_168h | G12: Both | H12: 19/11/2024 | J12: Production #2 | K12: IC0152_CatA002925_AnoNNF_T90_rho1287_AUX1Cat_AUX2Ano_3-8.png
A13: IC0157_CatA002741CENTER_AnoNNF_T90_rho1287_AUX1Cat_AUX2Ano_3-6 | B13: Mario | E13: 168 | F13: QC_IC_168h | G13: Both | H13: 21/11/2024 | I13: Irregular temp - do not use + battery tester fail | J13: Production #2 | K13: IC0157_CatA002741CENTER_AnoNNF_T90_rho1287_AUX1Cat_AUX2Ano_3-6.png
A14: IC0156_Cat1427_AnoNNF_T90_rho1287_AUX1Cat_AUX2Ano_2-3 | B14: Mario | E14: 168 | F14: QC_IC_168h | G14: Both | H14: 21/11/2024 | J14: Production #2 | K14: IC0156_Cat1427_AnoNNF_T90_rho1287_AUX1Cat_AUX2Ano_2-3.png
A15: IC0158_CatA002975_AnoNNF_T90_rho1287_AUX1Cat_AUX2Ano_2-1 | B15: Mario | E15: 168 | F15: QC_IC_168h | G15: Both | H15: 21/11/2024 | I15: Small temperature fluctuations | J15: Production #2 | K15: IC0158_CatA002975_AnoNNF_T90_rho1287_AUX1Cat_AUX2Ano_2-1.png
A16: IC0160_Cat987_AnoNNF_T90_rho1287_AUX1Cat_AUX2Ano_3-5 | B16: Mario | E16: 171 | F16: QC_IC_168h_v1 | G16: Both | H16: 21/11/2024 | I16: Battery tester malfunction at the end of experiment | J16: Production #2 | K16: IC0160_Cat987_AnoNNF_T90_rho1287_AUX1Cat_AUX2Ano_3-5.png
A17: IC0174_CatA2800_AnoNNF_T90_rho1287_AUX1Cat_AUX2Ano_2-3 | B17: Mario | E17: 168 | F17: QC_IC_168h | G17: Both | H17: 29/11/2024 | J17: Production #2 | K17: IC0174_CatA2800_AnoNNF_T90_rho1287_AUX1Cat_AUX2Ano_2-3.png
A18: IC0177_CatA2105_AnoNNF_T90_rho1287_AUX1Cat_AUX2Ano_2-4 | B18: Mario | E18: 168 | F18: QC_IC_168h | G18: Both | H18: 29/11/2024 | J18: Production #2 | K18: IC0177_CatA2105_AnoNNF_T90_rho1287_AUX1Cat_AUX2Ano_2-4.png
A19: IC0178_CatA2021_AnoNNF_T90_rho1287_AUX1Cat_AUX2Ano_3-5 | B19: Mario | E19: 168 | F19: QC_IC_168h | G19: Both | H19: 45324 | I19: Low voltage for appr. 10 hours - do not use | J19: Production #2 | K19: IC0178_CatA2021_AnoNNF_T90_rho1287_AUX1Cat_AUX2Ano_3-5.png
A20: IC0187_CatA2950_AnoNNF_T90_rho1287_AUX1Cat_AUX2Ano_3-3 | B20: Mario | E20: 168 | F20: QC_IC_168h | G20: Both | J20: Production #2 | K20: IC0187_CatA2950_AnoNNF_T90_rho1287_AUX1Cat_AUX2Ano_3-3.png
A21: IC0189_CatA183_AnoNNF_T90_rho1287_AUX1Cat_AUX2Ano_2-1 | B21: Mario | E21: 168 | F21: QC_IC_168h | G21: Both | H21: 45635 | J21: Production #2 | K21: IC0189_CatA183_AnoNNF_T90_rho1287_AUX1Cat_AUX2Ano_2-1.png
A22: IC0190_CatA186_AnoNNF_T90_rho1287_AUX1Cat_AUX2Ano_2-4 | B22: Mario | E22: 168 | F22: QC_IC_168h | G22: Both | H22: 45635 | J22: Production #2 | K22: IC0190_CatA186_AnoNNF_T90_rho1287_AUX1Cat_AUX2Ano_2-4.png
A23: IC0191_CatA167_AnoNNF_T90_rho1287_AUX1Cat_AUX2Ano_2-3 | B23: Mario | E23: 168 | F23: QC_IC_168h | G23: Both | H23: 45635 | J23: Production #2 | K23: IC0191_CatA167_AnoNNF_T90_rho1287_AUX1Cat_AUX2Ano_2-3.png
A24: IC0192_CatA1364_AnoNNF_T90_rho1287_AUX1Cat_AUX2Ano_3-5 | B24: Mario | E24: 168 | F24: QC_IC_168h | G24: Both | H24: 45635 | J24: Production #2 | K24: IC0192_CatA1364_AnoNNF_T90_rho1287_AUX1Cat_AUX2Ano_3-5.png
A25: IC0221_CatA003270_AnoNNF_rho1287_AUX1Cat_AUX2Ano_1-3 | B25: Julie | E25: 146 | F25: 0_ImmersionCellStandardProcedure_DN | G25: Both | H25: 45660 | I25: Wrong protocol, do not use | J25: Plating line 1 sensitivity study Flemming 2024
A26: IC0285_CatA3298_AnoNNF_rho1287_AUX1Cat_AUX2Ano-2-7 | B26: Balázs | D26: Akos | E26: 70 | F26: QC_IC_58.5h...12_hours | G26: Both | H26: 45694 | I26: Eurofin batch | J26: Production #2 | K26: IC0285_CatA3298_AnoNNF_rho1287_AUX1Cat_AUX2Ano-2-7.png
A27: IC0283_CatA003300_AnoNNF_rho1276_AUX1Cat_AUX2Ano_2-1 | B27: Balázs | D27: Akos | E27: 70 | F27: QC_IC_58.5h...12_hours | G27: Both | H27: 45694 | I27: Eurofin batch | J27: Production #2 | K27: IC0283_CatA003300_AnoNNF_rho1276_AUX1Cat_AUX2Ano_2-1.png
A28: IC0286_CatA3296_AnoNNF_rho1287_AUX1Cat_AUX2Ano-2-3 | B28: Balázs | D28: Gergo | E28: 70 | F28: QC_IC_58.5h...12_hours | G28: Both | H28: 45695 | I28: Eurofin batch. With preheated KOH(60 deg) and pretreated NNF anode. QC_IC_58.5h...12h | J28: Production #2 | K28: IC0286_CatA3296_AnoNNF_rho1287_AUX1Cat_AUX2Ano-2-3.png
A29: IC0290_CatA3306_AnoNNF_rho1287_AUX1Cat_AUX2Ano_2-8 | B29: Balázs | D29: Gergo | E29: 70 | F29: QC_IC_58.5h...12_hours | G29: Both | H29: 45695 | I29: Eurofin batch. With preheated KOH(60 deg) and pretreated NNF anode. QC_IC_58.5h...12h | J29: Production #2 | K29: IC0290_CatA3306_AnoNNF_rho1287_AUX1Cat_AUX2Ano_2-8.png
A30: IC0278_Cat3306_AnoNNF_rho1276_AUX1Cat_AUX2Ano_3-7 | B30: Balázs | D30: Gergo | E30: 168 | F30: QC_IC_168h_v1 | G30: Both | H30: 45695 | I30: Preheated KOH to 50 degrees used Preheated container to 50 degrees used Eurofin production | J30: Production #2 | K30: IC0278_Cat3306_AnoNNF_rho1276_AUX1Cat_AUX2Ano_3-7.png
A31: IC0279_Cat3308_AnoNNF_rho1276_AUX1Cat_AUX2Ano_3-8 | B31: Balázs | D31: Gergo | E31: 168 | F31: QC_IC_168h_v1 | G31: Both | H31: 45695 | I31: Preheated KOH to 50 degrees used Preheated container to 50 degrees used Eurofin production | J31: Production #2 | K31: IC0279_Cat3308_AnoNNF_rho1276_AUX1Cat_AUX2Ano_3-8.png
A32: IC0291_CatA3308_AnoNNF_rho1287_AUX1Cat_AUX2Ano_3-3 | B32: Balázs | D32: Gergo | E32: 70 | F32: QC_IC_58.5h...12_hours | G32: Both | H32: 45695 | I32: With preheated KOH(60 deg) and pretreated NNF anode. QCIC58.5h...12h | J32: Production #2 | K32: IC0291_CatA3308_AnoNNF_rho1287_AUX1Cat_AUX2Ano_3-3.png
A33: IC0280_Cat3300_AnoNNF_rho1276_AUX1Cat_AUX2Ano_1-5 | B33: Balázs | D33: Gergo | E33: 168 | F33: QC_IC_168h_v1 | G33: Both | H33: 45695 | I33: Preheated container to 50 degrees used Eurofin production - battery tester problems, unstable potential | J33: Production #2 | K33: IC0280_Cat3300_AnoNNF_rho1276_AUX1Cat_AUX2Ano_1-5.png
A34: IC0281_CatA003298_AnoNNF_rho1276_AUX1Cat_AUX2Ano_3-6 | B34: Balázs | C34: Akos | D34: Akos | E34: 168 | F34: QC_IC_168h_v1 | G34: Both | H34: 45698 | I34: QC_IC_168h_v1 | J34: Production #2 | K34: IC0281_CatA003298_AnoNNF_rho1276_AUX1Cat_AUX2Ano_3-6.png
A35: IC0282_CatA003296_AnoNNF_rho1276_AUX1Cat_AUX2Ano_3-5 | B35: Balázs | C35: Akos | D35: Akos | E35: 168 | F35: QC_IC_168h_v1 | G35: Both | H35: 45698 | I35: QCIC168h_v1. black flakes in the electrolyte during testing :( | J35: Production #2 | K35: IC0282_CatA003296_AnoNNF_rho1276_AUX1Cat_AUX2Ano_3-5.png
A36: IC0334_CatA3296_AnoNNF_rho1279_AUX1Cat_AUXAno_48h_2-1 | B36: Balázs | C36: Gergo | D36: Nerea | E36: 48 | F36: QC_IC_48h...3_hours | G36: Both | H36: 45714 | I36: No pretreatment for the NNF. | J36: Production #2 | K36: IC0334_CatA3296_AnoNNF_rho1279_AUX1Cat_AUXAno_48h_2-1.png
A37: IC0339_CatA3308_AnoNNF_rho1276_AUX1Cat_AUX2Ano_48h_1-5 | B37: Balázs | C37: Gergo | D37: Nerea | E37: 48 | F37: QC_IC_48h...3_hours | G37: Both | H37: 45714 | I37: No pretreatment for the NNF. | J37: Production #2 | K37: IC0339_CatA3308_AnoNNF_rho1276_AUX1Cat_AUX2Ano_48h_1-5.png
A38: IC0335_CatA3298_AnoNNF_rho1276_AUX1Cat_AUXAno_48h_2-3 | B38: Balázs | C38: Gergo | D38: Nerea | E38: 48 | F38: QC_IC_48h...3_hours | G38: Both | H38: 45714 | I38: No pretreatment for the NNF. | J38: Production #2 | K38: IC0335_CatA3298_AnoNNF_rho1276_AUX1Cat_AUXAno_48h_2-3.png
A39: IC0338_CatA3306_AnoNNF_rho1276_AUX1Cat_AUX2Ano_48h_3-8 | B39: Balázs | C39: Gergo | D39: Nerea | E39: 48 | F39: QC_IC_48h...3_hours | G39: Both | H39: 45714 | I39: No pretreatment for the NNF. | J39: Production #2 | K39: IC0338_CatA3306_AnoNNF_rho1276_AUX1Cat_AUX2Ano_48h_3-8.png
A40: IC0336_CatA3300_AnoNNF_rho1276_AUX1Cat_AUXAno_48h_2-4 | B40: Balázs | I40: Balázs fucked up the saving - rookie mistake | J40: Production #2
...

Sheet Gen4Cat-Gen2
A1: IC_ID | B1: Owner | C1: Assembled by | D1: Disassembled by | E1: Test length [h] | F1: Protocol | G1: Format | H1: Experiment finished on | I1: Notes | J1: Arhived in | K1: Plot
A2: IC1884_CatB13881-TR_AnoNNF_rho1282_1.3ppm_Fe_5-3 | B2: Balazs | C2: Frederik | D2: Marcus | E2: 42 | F2: _QC_IC_168h_v1.xml | G2: Custom | H2: 46219 | I2: 168hr test stopped early because no iron was added | J2: Production #11
A3: IC1880_CatB13862-TR_AnoNNF_rho1282_1.3ppm_Fe_4-5 | B3: Balazs | C3: Oniel | D3: Oniel | E3: 168 | G3: Custom | H3: 46223 | I3: 168hr test | J3: Production #11 | K3: IC0080_Cat2243_AnoNF_T90_rho1287_AUX1Ano_AUX2_Cat_1-7 - GOOD.png
A4: IC1898_CatB13902-TR_AnoNNF_rho1282_1.3ppm_Fe_2-6 | B4: Balázs | C4: Aleksandra | D4: Aleksandra | E4: 48 | F4: QC_IC_48h_v1 | G4: Custom | H4: 46223 | J4: Production #11
A5: IC1881_CatB13863-TR_AnoNNF_rho1282_1.3ppm_Fe_4-6 | B5: Balazs | C5: Oniel | D5: Oniel | E5: 168 | G5: Custom | H5: 46223 | I5: 168hr test | J5: Production #11 | K5: IC0091_CatA002835_AnoNNF_T90_rho1287_AUX1Cat_AUX2Ano_2-1.png
A6: IC1882_CatB13866-TR_AnoNNF_rho1282_1.3ppm_Fe_5-1 | B6: Balazs | C6: Oniel | D6: Oniel | E6: 168 | G6: Custom | H6: 46223 | I6: 168hr test | J6: Production #11 | K6: IC0093_Cat2901_AnoNNF_T90_rho1287_AUX1Ano_AUX2_Cat_3-8.png
A7: IC1892_CatB13892-TR_AnoNNF_rho1282_1.3ppm_Fe_6-4 | B7: Balazs | C7: Marcus | D7: Frederik | E7: 48 | F7: QC_IC_48h_v1 | G7: Custom | H7: 46223 | I7: 48h test | J7: Production #11 | K7: IC0094_Cat2902_AnoNNF_T90_rho1287_AUX1Ano_AUX2Cat_3-7.png
A8: IC1893_CatB13893-TR_AnoNNF_rho1282_1.3ppm_Fe_6-5 | B8: Balazs | C8: Marcus | D8: Frederik | E8: 48 | F8: QC_IC_48h_v1 | G8: Custom | H8: 46223 | I8: 48h test | J8: Production #11 | K8: NaN
A9: IC1894_CatB13894-TR_AnoNNF_rho1282_1.3ppm_Fe_6-6 | B9: Balazs | C9: Marcus | D9: Frederik | E9: 48 | F9: QC_IC_48h_v1 | G9: Custom | H9: 46223 | I9: SEM shows unknown lumps of potentially carbon, 48h test | J9: Production #11 | K9: IC0103_Cat2904_AnoNNF_T90_rho1287_AUX1Ano_AUX2_Cat_2-3.png
A10: IC1895_CatB13895-TR_AnoNNF_rho1282_1.3ppm_Fe_6-7 | B10: Balazs | C10: Emil | D10: Frederik | E10: 48 | F10: QC_IC_48h_v1 | G10: Custom | H10: 46223 | I10: 48h test | J10: Production #11 | K10: IC0139_CatA002904_AnoNNF_T90_rho1287_AUX1NaN_AUX2NaN_3-4.png
A11: IC1896_CatB13896-TR_AnoNNF_rho1282_1.3ppm_Fe_6-8 | B11: Balazs | C11: Emil | D11: Frederik | E11: 48 | F11: QC_IC_48h_v1 | G11: Custom | H11: 46223 | I11: 48h test | J11: Production #11 | K11: IC0153_CatA002741EDGE_AnoNNF_T90_rho1287_AUX1Cat_AUX2Ano_3-7.png
A12: IC1897_CatB13900-TR_AnoNNF_rho1282_1.3ppm_Fe_7-1 | B12: Balazs | C12: Emil | D12: Frederik | E12: 48 | F12: QC_IC_48h_v1 | G12: Custom | H12: 46223 | I12: Cracks. Needs post mortem, 48h test | J12: Production #11 | K12: IC0152_CatA002925_AnoNNF_T90_rho1287_AUX1Cat_AUX2Ano_3-8.png
A13: IC1886_CatB13882-TR_AnoNNF_rho1282_1.3ppm_Fe_4-1 | B13: Balázs | C13: Aleksandra | D13: Tamas | E13: 168 | F13: _QC_IC_168h_v1.xml | G13: Custom | H13: 46225 | I13: 168h | J13: Production #11 | K13: IC0157_CatA002741CENTER_AnoNNF_T90_rho1287_AUX1Cat_AUX2Ano_3-6.png
A14: IC1887_CatB13883-TR_AnoNNF_rho1282_1.3ppm_Fe_4-2 | B14: Balázs | C14: Aleksandra | D14: Tamas | E14: 168 | F14: _QC_IC_168h_v1.xml | G14: Custom | H14: 46225 | I14: 168h | J14: Production #11 | K14: IC0156_Cat1427_AnoNNF_T90_rho1287_AUX1Cat_AUX2Ano_2-3.png
A15: IC1888_CatB13887-TR_AnoNNF_rho1282_1.3ppm_Fe_4-3 | B15: Balázs | C15: Aleksandra | D15: Tamas | E15: 168 | F15: _QC_IC_168h_v1.xml | G15: Custom | H15: 46225 | I15: 168h | J15: Production #11 | K15: IC0158_CatA002975_AnoNNF_T90_rho1287_AUX1Cat_AUX2Ano_2-1.png
A16: IC1889_CatB13888-TR_AnoNNF_rho1282_1.3ppm_Fe_4-4 | B16: Balázs | C16: Aleksandra | D16: Tamas | E16: 168 | F16: _QC_IC_168h_v1.xml | G16: Custom | H16: 46225 | I16: 168h | J16: Production #11 | K16: IC0160_Cat987_AnoNNF_T90_rho1287_AUX1Cat_AUX2Ano_3-5.png
A17: IC1890_CatB13891-TR_AnoNNF_rho1282_1.3ppm_Fe_2-5 | B17: Balázs | C17: Aleksandra | D17: Tamas | E17: 168 | F17: _QC_IC_168h_v1.xml | G17: Custom | H17: 46225 | I17: 168h | J17: Production #11 | K17: IC0174_CatA2800_AnoNNF_T90_rho1287_AUX1Cat_AUX2Ano_2-3.png
A18: IC1808_CatGen4.1.45B3_AnoNNF_rho1282_1.3ppm_Fe_2-8 | B18: Balázs | C18: Frederik | D18: Tamas | E18: 1350 | F18: QC_IC_3000h_v3 | G18: Custom | H18: 46225 | I18: QC_IC_3000h_v3, Cathode: Gen4.1.45B3, Anode: NNF | J18: Gen 4 Co | K18: IC0177_CatA2105_AnoNNF_T90_rho1287_AUX1Cat_AUX2Ano_2-4.png
... A24: IC1903_CatB13917-TR_AnoNNF_rho1282_1.3ppm_Fe_6-8 | B24: Balazs | C24: Oniel | D24: Emil | E24: 48 | F24: QC_IC_48h_v1 | G24: Custom | H24: 46226 | I24: 48 h test | J24: Production #11 | K24: IC0192_CatA1364_AnoNNF_T90_rho1287_AUX1Cat_AUX2Ano_3-5.png
A25: IC1904_CatB13913-TR_AnoNNF_rho1282_1.3ppm_Fe_7-1 | B25: Balazs | C25: Frederik | D25: Emil | E25: 48 | F25: QC_IC_48h_v1 | G25: Custom | H25: 46226 | I25: 48h test - The electrode is an anode run as a cathode. | J25: Production #11
A26: IC1905_CatB13925-TR_AnoNNF_rho1282_1.3ppm_Fe_4-5 | B26: Balazs | C26: Marcus | D26: Antonina | E26: 48 | F26: QC_IC_48h_v1 | G26: Custom | H26: 46226 | J26: Production #11 | K26: IC0285_CatA3298_AnoNNF_rho1287_AUX1Cat_AUX2Ano-2-7.png
A27: IC1906_CatB13926-TR_AnoNNF_rho1282_1.3ppm_Fe_4-6 | B27: Balazs | C27: Marcus | D27: Antonina | E27: 48 | F27: QC_IC_48h_v1 | G27: Custom | H27: 46226 | J27: Production #11 | K27: IC0283_CatA003300_AnoNNF_rho1276_AUX1Cat_AUX2Ano_2-1.png
A28: IC1907_CatB13945-TR_AnoNNF_rho1282_1.3ppm_Fe_5-1 | B28: Balazs | C28: Marcus | D28: Antonina | E28: 48 | F28: QC_IC_48h_v1 | G28: Custom | H28: 46226 | J28: Production #11 | K28: IC0286_CatA3296_AnoNNF_rho1287_AUX1Cat_AUX2Ano-2-3.png
A29: IC1908_CatB13951-TR_AnoNNF_rho1282_1.3ppm_Fe_7-2 | B29: Balazs | C29: Marcus | D29: Antonina | E29: 48 | F29: QC_IC_48h_v1 | G29: Custom | H29: 46226 | J29: Production #11 | K29: IC0290_CatA3306_AnoNNF_rho1287_AUX1Cat_AUX2Ano_2-8.png
A30: IC1891_CatB13881-TR_AnoNNF_rho1282_1.3ppm_Fe_5-3 | B30: Balazs | C30: Marcus | D30: Antonina | E30: 168 | F30: _QC_IC_168h_v1.xml | G30: Custom | H30: 46226 | I30: 168hr test, restart of IC1884 | J30: Production #11 | K30: IC0278_Cat3306_AnoNNF_rho1276_AUX1Cat_AUX2Ano_3-7.png
A31: IC1912_CatB13953-TR_AnoNNF_rho1282_1.3ppm_Fe_7-7 | B31: Balazs | C31: Daniel | D31: Aleksandra | E31: 48 | F31: QC_IC_48h_v1 | G31: Custom | H31: 46227 | J31: Production #11 | K31: IC0279_Cat3308_AnoNNF_rho1276_AUX1Cat_AUX2Ano_3-8.png
A32: IC1911_CatB13967-TR_AnoNNF_rho1282_1.3ppm_Fe_7-8 | B32: Balazs | C32: Daniel | D32: Aleksandra | E32: 48 | F32: QC_IC_48h_v1 | G32: Custom | H32: 46227 | J32: Production #11 | K32: IC0291_CatA3308_AnoNNF_rho1287_AUX1Cat_AUX2Ano_3-3.png
A33: IC1915_CatB13977-TR_AnoNNF_rho1282_1.3ppm_Fe_4-1 | B33: Balazs | C33: Antonina | E33: 48 | F33: QC_IC_48h_v1 | G33: Custom | H33: 46228 | J33: Production #11 | K33: IC0280_Cat3300_AnoNNF_rho1276_AUX1Cat_AUX2Ano_1-5.png
A34: IC1916_CatB13980-TR_AnoNNF_rho1282_1.3ppm_Fe_4-2 | B34: Balazs | C34: Antonina | E34: 48 | F34: QC_IC_48h_v1 | G34: Custom | H34: 46228 | J34: Production #11 | K34: IC0281_CatA003298_AnoNNF_rho1276_AUX1Cat_AUX2Ano_3-6.png
A35: IC1917_CatB13994-TR_AnoNNF_rho1282_1.3ppm_Fe_4-3 | B35: Balazs | C35: Antonina | E35: 48 | F35: QC_IC_48h_v1 | G35: Custom | H35: 46228 | J35: Production #11 | K35: IC0282_CatA003296_AnoNNF_rho1276_AUX1Cat_AUX2Ano_3-5.png
A36: IC1924_CatB13951-BL_AnoNNF_rho1282_1.3ppm_Fe_4-4 | B36: Balazs | C36: Aleksandra | E36: 48 | F36: QC_IC_48h_v1 | G36: Custom | H36: 46228 | I36: 48 h, duplicate of IC1925 | J36: Production #11 | K36: IC0334_CatA3296_AnoNNF_rho1279_AUX1Cat_AUXAno_48h_2-1.png
A37: IC1925_CatB13951-BL_AnoNNF_rho1282_1.3ppm_Fe_4-5 | B37: Balazs | C37: Aleksandra | E37: 48 | F37: QC_IC_48h_v1 | G37: Custom | H37: 46228 | I37: 48 h, duplicate of IC1924 | J37: Production #11 | K37: IC0339_CatA3308_AnoNNF_rho1276_AUX1Cat_AUX2Ano_48h_1-5.png
A38: IC1926_CatB13951-TR_AnoNNF_rho1282_1.3ppm_Fe_4-6 | B38: Balazs | C38: Aleksandra | E38: 48 | F38: QC_IC_48h_v1 | G38: Custom | H38: 46228 | I38: 48 h, duplicate of IC1927; reassembled because Ni backplate broke before starting the test | J38: Production #11 | K38: IC0335_CatA3298_AnoNNF_rho1276_AUX1Cat_AUXAno_48h_2-3.png
A39: IC1927_CatB13951-TR_AnoNNF_rho1282_1.3ppm_Fe_5-1 | B39: Balazs | C39: Aleksandra | E39: 48 | F39: QC_IC_48h_v1 | G39: Custom | H39: 46228 | I39: 48h, duplicate of IC1926 | J39: Production #11 | K39: IC0338_CatA3306_AnoNNF_rho1276_AUX1Cat_AUX2Ano_48h_3-8.png
A40: IC1918_CatB13951-C_AnoNNF_rho1282_1.3ppm_Fe_6-4 | B40: Balazs | C40: Aleksandra | E40: 48 | F40: QC_IC_48h_v1 | G40: Custom | H40: 46228 | I40: duplicate of IC1919 | J40: Production #11
A41: IC1919_CatB13951-C_AnoNNF_rho1282_1.3ppm_Fe_6-5 | B41: Balazs | C41: Aleksandra | E41: 48 | F41: QC_IC_48h_v1 | G41: Custom | H41: 46228 | I41: Duplicate of IC1918 | J41: Production #11 | K41: IC0337_CatA3300_AnoNNF_rho1276_AUX1Cat_AUX2Ano_168h_3-2.png
A42: IC1920_CatB13951-TL_AnoNNF_rho1282_1.3ppm_Fe_6-6 | B42: Balazs | C42: Aleksandra | E42: 48 | F42: QC_IC_48h_v1 | G42: Custom | H42: 46228 | I42: Duplicate of IC1921 | J42: Production #11
A43: IC1921_CatB13951-TL_AnoNNF_rho1282_1.3ppm_Fe_6-7 | B43: Balazs | C43: Aleksandra | E43: 48 | F43: QC_IC_48h_v1 | G43: Custom | H43: 46228 | I43: duplicate of IC1920 | J43: Production #11 | K43: IC0366_CatA03306_AnoNNF_rho1276_AUX1Cat_AUX2Ano-2-7.png
A44: IC1922_CatB13951-BR_AnoNNF_rho1282_1.3ppm_Fe_6-8 | B44: Balazs | C44: Aleksandra | E44: 48 | F44: QC_IC_48h_v1 | G44: Custom | H44: 46228 | I44: Duplicate of IC1923 | J44: Production #11 | K44: IC0365_CatA03298_AnoNNF_rho1276_AUX1Cat_AUX2Ano-3-2.png
A45: IC1923_CatB13951-BR_AnoNNF_rho1282_1.3ppm_Fe_7-1 | B45: Balazs | C45: Aleksandra | E45: 48 | F45: QC_IC_48h_v1 | G45: Custom | H45: 46228 | I45: Duplicate of IC1922 | J45: Production #11 | K45: IC0373_CatA3296_AnoNNF_rho1276_AUX1Cat_AUX2Ano_3-5.png
...

Sheet Accelerated
A1: IC_ID | B1: Owner | C1: Assembled by | D1: Disassembled by | E1: Test length [h] | F1: Protocol | G1: Format | H1: Experiment finished on | I1: Notes | J1: Archived in | K1: Plot
A2: IC0639_CatNNF_AnoNNF_rho1279_AUX1NaN_AUX2NaN_4-4_accelerated | B2: Balázs | C2: Akos | D2: Aleksandra | E2: 168 | F2: HPro_AST_1 | G2: Custom format | H2: 45812
A3: IC0640_CatC19_AnoNNF_rho1279_AUX1NaN_AUX2NaN_5-1_accelerated | B3: Balázs | C3: Akos | D3: Aleksandra | E3: 168 | F3: HPro_AST_1 | G3: Custom format | H3: 45812
A4: IC0656_CatNNF_AnoNNF_rho1279_AUX1NaN_AUX2NaN_4-4_accelerated | B4: Balázs | C4: Akos | D4: Akos | E4: 42.5 | F4: HPro_AST_2 | G4: Custom format | H4: 45814 | I4: LOST DATA, The file is stopped after 42,5 hours and was probably saved over with a new filename | J4: Production #3
A5: IC0657_CatC19_AnoNNF_rho1279_AUX1NaN_AUX2NaN_5-1_accelerated | B5: Balázs | C5: Akos | D5: Akos | E5: 42.5 | F5: HPro_AST_2 | G5: Custom format | H5: 45814 | I5: LOST DATA, The file is stopped after 42,5 hours and was probably saved over with a new filename
A6: IC0656_CatNNF_AnoNNF_rho1279_AUX1NaN_AUX2NaN_4-4_accelerated_v2 | B6: Balázs | C6: Akos | D6: Akos | E6: 168 | F6: HPro_AST_3 | G6: Custom format | H6: 45827
A7: IC0657_CatC19_AnoNNF_rho1279_AUX1NaN_AUX2NaN_5-1_accelerated_v2 | B7: Balázs | C7: Akos | D7: Akos | E7: 168 | F7: HPro_AST_3 | G7: Custom format | H7: 45827
A8: IC1538_CatNNF_AnoNNF_rho1282_6-6 | B8: Peter | C8: Peter | E8: 236 | F8: HPro_AST_v4.xml | G8: Custom | H8: 46116
A9: IC1577_CatB10889-TR_AnoB10882-TR_rho1282_3-7 | B9: Peter | C9: Oniel | D9: Oniel | E9: 245 | F9: HPro_AST_v4.xml | G9: Custom | H9: 46122 | I9: Initial accelerated stress test | J9: Production #10
A10: IC1804_CatGen4.1.60_AnoGen2.3_rho1282_1.3ppm_Fe_RC_7-1 | B10: Balázs | C10: Markus | D10: Emil | E10: 142 | F10: _START_STOP_IC_168h_v2_RC.xml | G10: Custom | H10: 46177 | I10: Reverse current. B1 for 4.1.60 | J10: Gen 4 Co
A11: IC1805_CatGen4.1.60_AnoGen2.3_rho1282_1.3ppm_Fe_RC_7-2 | B11: Balázs | C11: Markus | D11: Emil | E11: 142 | F11: _START_STOP_IC_168h_v2_RC.xml | G11: Custom | H11: 46177 | I11: Reverse current. B1 for 4.1.60 | J11: Gen 4 Co
A12: IC1825_CatDNC_AnoDNA_rho1279_CRoperation_after5000hoursCC_6-5_part2 | B12: Morten | C12: Antonina | D12: Frederik | E12: 845 | F12: Start test CR_onoff | G12: Custom | H12: 46216 | I12: Reverse current

Sheet H2-FOAM
A1: IC_ID | B1: Owner | C1: Assembled by | D1: Disassembled by | E1: Test length [h] | F1: Protocol | G1: Format | H1: Experiment finished on | I1: Notes | J1: Archived in | K1: Plot
A2: IC0350_CatNNF-AnoNNF-rho1276_AUX1Cat_AUX2Ano-1-5 | B2: Paolo | C2: Mathias | D2: Mathias | E2: 6 | F2: QnD_RT_6h_v1 | G2: Both | H2: 45716 | I2: Heating plate was hot when experiment began despite KOH being replaced by cooler KOH. Heating was turned off, initial temperature of cell was 38 degC. | J2: H2 foam (white binder) | K2: IC0350_CatNNF-AnoNNF-rho1276_AUX1Cat_AUX2Ano-1-5.png
A3: IC0351_CatNNF-AnoNNF-rho1276_AUX1Cat_AUX2Ano-2-1 | B3: Paolo | C3: Mathias | D3: Mathias | E3: 6 | F3: QnD_RT_6h_v1 | G3: Both | H3: 45716 | J3: H2 foam (white binder)
A4: IC0352_CatNNF-AnoNNF-rho1276_AUX1Cat_AUX2Ano-3-8 | B4: Paolo | C4: Mathias | D4: Mathias | E4: 6 | F4: QnD_RT_6h_v1 | G4: Both | H4: 45716 | J4: H2 foam (white binder)
A5: IC0359_CatNNF_AnoANF_rho1276_AUX1Cat_AUX2Ano-3-6 | B5: Paolo | C5: Mathias | D5: Andrea | E5: 6 | F5: QnD_RT_6h_v2 | G5: Both | H5: 45720 | I5: 0,5 mm PTFE | J5: H2 foam (white binder)
A6: IC0358_CatNNF_AnoANF_rho1276_AUX1Cat_AUX2Ano-3-7 | B6: Paolo | C6: Mathias | D6: Mathias | E6: 6 | F6: QnD_RT_6h_v2 | G6: Both | H6: 45720 | J6: H2 foam (white binder)
A7: IC0357_CatNNF_AnoANF_rho1276_AUX1Cat_AUX2Ano-3-8 | B7: Paolo | C7: Mathias | D7: Mathias | E7: 6 | F7: QnD_RT_6h_v2 | G7: Both | H7: 45720 | J7: H2 foam (white binder)
A8: IC0364_CatNNF_AnoANF_rho1276_AUX1NaN_AUX2NaN-3-6 | B8: Paolo | C8: Mathias | D8: Andrea | E8: 3 | F8: QnD_RT_3h_v2 | G8: Both | H8: 45720 | I8: 0,5 mm PTFE. | J8: H2 foam (white binder)
A9: IC0363_CatNNF_AnoANF_rho1276_AUX1NaN_AUX2NaN-3-7 | B9: Paolo | C9: Mathias | D9: Nerea | E9: 3 | F9: QnD_RT_3h_v2 | G9: Both | H9: 45721 | I9: 0,5 mm PTFE. | J9: H2 foam (white binder)
A10: IC0362_CatNNF_AnoANF_rho1276_AUX1NaN_AUX2NaN-3-8 | B10: Paolo | C10: Mathias | D10: Nerea | E10: 3 | F10: QnD_RT_3h_v2 | G10: Both | H10: 45721 | I10: 0,5 mm PTFE. | J10: H2 foam (white binder)
A11: IC0377_CatNNF_AnoNNF_rho1276_AUX1Lol_AUX2Lol-2-1 | B11: Paolo | C11: Mathias | D11: Mathias | E11: 3 | F11: QnD_RT_3h_v2 | G11: Both | H11: 45722 | I11: 0,5 mm PTFE | J11: H2 foam (white binder)
A12: IC0378_CatNNF_AnoNNF_rho1276_AUX1Lol_AUX2Lol-2-7 | B12: Paolo | C12: Mathias | D12: Mathias | E12: 3 | F12: QnD_RT_3h_v2 | G12: Both | H12: 45722 | I12: 0,5 mm PTFE | J12: H2 foam (white binder)
